Workbook

Sheet 本版更新
A1: R23.00 更新重點
A3: 1 | B3: 篩選條件按你嘅四點更新：① 有熱錢及消息驅動（高位前 60 日內有一日 ≥+8% 或跳空 ≥+5%、成交量 ≥3× 50 日均量；升浪期成交額 ≥ 前 60 日 2 倍）② 曾有 10MA 上升（近 30 日內通過 R1–R20 嘅 10MA 測試：10 日升 ≥5%、最後三值遞升、10 步升 ≥7 步）③ 回落到 20MA（MA20 向上、高位 2–25 日前、回調 3–30%、高位時高過 MA20 ≥8%、收市喺 MA20 ±3% 兼近 3 日觸及）④ 波幅減低（ATR5 ≤ 0.9× ATR20 兼 ≤ 0.7× 升浪期 ATR）。細節見「篩選規則」頁。
A4: 2 | B4: 數據更新至 2026-09-30 收市（254 個交易日，2025-09-26 起）。
A5: 3 | B5: 合資格 2,762 隻 → 第一梯隊 3 隻（RLGT、CSR、BSVN）；每個門檻放寬一級嘅第二梯隊 19 隻。分頁改為 大型／中型／小型。
A6: 4 | B6: 評分改為 熱錢分數 0.25 + 10MA分數 0.20 + 回調質素 0.30 + 波幅收窄 0.25（每項 0–100，公式喺總表）。
A7: 5 | B7: R22 向前測試（2 日）：中位數 +0.69%，大市 -1.02%；2 隻 R22 股喺新條件下仍上榜。
A8: 6 | B8: 逐隻查咗事件日當日嘅新聞（催化劑頁有來源）：CSR 係全換股併購目標；3 隻係加密貨幣庫存股；UMAC 係傳聞；AMBA 係分析員推介。
A9: 7 | B9: 容器重設令 Nasdaq 序列檔消失：上市日期改由保存嘅審計檔提供，加 SPAC 空殼期偵測；兩源核對只剩收市後快照。
A10: 8 | B10: 獨立重寫嘅篩選程式對兩個梯隊共 22 隻 0 差異。所有代號連 TradingView；可推導欄位全部係公式。

Sheet 總表
A1: 梯隊 | B1: 排名 | C1: 代號 | D1: 公司 | E1: 交易所 | F1: 板塊 | G1: 行業 | H1: 市值(十億美元) | I1: 市值組 | J1: 收市價 | K1: 前收 | L1: 當日% | M1: 當日高 | N1: 當日低 | O1: MA10 | P1: MA20 | Q1: 距MA20% | R1: MA50 | S1: MA20（5日前） | T1: MA20 5日斜率% | U1: 63日最高收市 | V1: 高位日期 | W1: 高位至今（交易日） | X1: 距高位% | Y1: 升浪起點 | Z1: 升浪日數 | AA1: 升浪幅度% | AB1: 高位時高過MA20% | AC1: 近3日最低價距MA20% | AD1: 事件日 | AE1: 事件日升幅 | AF1: 事件日跳空 | AG1: 事件日量比（×50日均量） | AH1: 事件日數目 | AI1: 升浪成交額（日均） | AJ1: 升浪前60日成交額（日均） | AK1: 升浪成交額比 | AL1: 10MA上升日期 | AM1: MA10 10日升幅 | AN1: MA10上升步比例 | AO1: 回調量比 | AP1: ATR5% | AQ1: ATR20% | AR1: 升浪期ATR% | AS1: ATR5/ATR20 | AT1: ATR5/升浪ATR | AU1: 成交額分 | AV1: 事件量分 | AW1: 升浪分 | AX1: 10MA升幅分 | AY1: 10MA步分 | AZ1: 量縮 | BA1: 貼近MA20 | BB1: MA20斜率分 | BC1: 回調深度分 | BD1: 企穩 | BE1: 短期收窄 | BF1: 對升浪收窄 | BG1: 熱錢分數 | BH1: 10MA分數 | BI1: 回調質素 | BJ1: 波幅收窄 | BK1: 綜合分數 | BL1: 唔過嘅條件（梯隊2） | BM1: R22 排名 | BN1: 門檻測試留低 | BO1: 審視標記 | BP1: 兩源最大差%
A2: 1 | B2: =COUNTIFS($A$2:$A$23,A2,$BK$2:$BK$23,">"&BK2)+1 | C2: RLGT | D2: Radiant Logistics Inc. | E2: AMEX | F2: 工業 | G2: Integrated Freight & Logistics | H2: 0.412 | I2: 小型 | J2: 8.69 | K2: 8.78 | L2: =J2/K2-1 | M2: 8.85 | N2: 8.65 | O2: 8.689 | P2: 8.5995 | Q2: =J2/P2-1 | R2: 8.585 | S2: 8.5715 | T2: =P2/S2-1 | U2: 9.81 | V2: 2026-09-15 | W2: 11 | X2: =J2/U2-1 | Y2: 2026-09-11 | Z2: 2 | AA2: 0.20664207 | AB2: 0.1517464 | AC2: -0.0090458127 | AD2: 2026-09-15 | AE2: 0.19488429 | AF2: 0.15103532 | AG2: 23.125345 | AH2: 1 | AI2: 8238108.6 | AJ2: 1211309.5 | AK2: =AI2/AJ2 | AL2: 2026-09-28 | AM2: 0.063960491 | AN2: 1 | AO2: 0.88073845 | AP2: 0.022174627 | AQ2: 0.041543891 | AR2: 0.068952324 | AS2: =AP2/AQ2 | AT2: =AP2/AR2 | AU2: =MAX(0,MIN(1,(AK2-2)/4)) | AV2: =MAX(0,MIN(1,(AG2-3)/7)) | AW2: =MAX(0,MIN(1,(AA2-0.25)/0.75)) | AX2: =MAX(0,MIN(1,(AM2-0.05)/0.2)) | AY2: =MAX(0,MIN(1,(AN2-0.7)/0.3)) | AZ2: =MAX(0,MIN(1,(AO2-1.2)/(0.6-1.2))) | BA2: =MAX(0,MIN(1,(ABS(Q2)-0.03)/(0-0.03))) | BB2: =MAX(0,MIN(1,T2/0.03)) | BC2: =MAX(0,MIN(1,(-X2-0.3)/(0.15-0.3))) | BD2: =0.5*IF(M2>N2,(J2-N2)/(M2-N2),0.5)+0.5*(J2>=P2) | BE2: =MAX(0,MIN(1,(AS2-0.9)/(0.5-0.9))) | BF2: =MAX(0,MIN(1,(AT2-0.7)/(0.3-0.7))) | BG2: =100*(0.4*AU2+0.3*AV2+0.3*AW2) | BH2: =100*(0.5*AX2+0.5*AY2) | BI2: =100*(0.3*AZ2+0.25*BA2+0.2*BB2+0.1*BC2+0.15*BD2) | BJ2: =100*(0.5*BE2+0.5*BF2) | BK2: =0.25*BG2+0.2*BH2+0.3*BI2+0.25*BJ2 | BN2: 25/26 | BO2: 20 日成交額中位數只有 $1.7M（股票池下限 $1M），入市出市都會有滑價 | BP2: 0
A3: 1 | B3: =COUNTIFS($A$2:$A$23,A3,$BK$2:$BK$23,">"&BK3)+1 | C3: CSR | D3: D/B/A Centerspace | E3: NYSE | F3: 房地產 | G3: Real Estate Investment Trusts | H3: 0.926 | I3: 小型 | J3: 54.4 | K3: 55.13 | L3: =J3/K3-1 | M3: 55.06 | N3: 54.36 | O3: 55.489 | P3: 55.6165 | Q3: =J3/P3-1 | R3: 55.1482 | S3: 55 | T3: =P3/S3-1 | U3: 58.62 | V3: 2026-09-14 | W3: 12 | X3: =J3/U3-1 | Y3: 2026-09-01 | Z3: 8 | AA3: 0.11891582 | AB3: 0.080821956 | AC3: -0.022592216 | AD3: 2026-09-09 | AE3: 0.088218554 | AF3: 0.097324986 | AG3: 15.218839 | AH3: 1 | AI3: 27747487 | AJ3: 9206314.8 | AK3: =AI3/AJ3 | AL3: 2026-09-22 | AM3: 0.081059071 | AN3: 1 | AO3: 1.1978387 | AP3: 0.017599746 | AQ3: 0.024789947 | AR3: 0.03485565 | AS3: =AP3/AQ3 | AT3: =AP3/AR3 | AU3: =MAX(0,MIN(1,(AK3-2)/4)) | AV3: =MAX(0,MIN(1,(AG3-3)/7)) | AW3: =MAX(0,MIN(1,(AA3-0.25)/0.75)) | AX3: =MAX(0,MIN(1,(AM3-0.05)/0.2)) | AY3: =MAX(0,MIN(1,(AN3-0.7)/0.3)) | AZ3: =MAX(0,MIN(1,(AO3-1.2)/(0.6-1.2))) | BA3: =MAX(0,MIN(1,(ABS(Q3)-0.03)/(0-0.03))) | BB3: =MAX(0,MIN(1,T3/0.03)) | BC3: =MAX(0,MIN(1,(-X3-0.3)/(0.15-0.3))) | BD3: =0.5*IF(M3>N3,(J3-N3)/(M3-N3),0.5)+0.5*(J3>=P3) | BE3: =MAX(0,MIN(1,(AS3-0.9)/(0.5-0.9))) | BF3: =MAX(0,MIN(1,(AT3-0.7)/(0.3-0.7))) | BG3: =100*(0.4*AU3+0.3*AV3+0.3*AW3) | BH3: =100*(0.5*AX3+0.5*AY3) | BI3: =100*(0.3*AZ3+0.25*BA3+0.2*BB3+0.1*BC3+0.15*BD3) | BJ3: =100*(0.5*BE3+0.5*BF3) | BK3: =0.25*BG3+0.2*BH3+0.3*BI3+0.25*BJ3 | BN3: 24/26 | BO3: 全換股併購目標：09-09 起每股 CSR = 3.800 股 IRT，股價跟收購方 IRT 走。升浪係併購溢價、回調係 IRT 跌，唔係資金追入後嘅回調；交割前基本上冇自己嘅走勢 | BP3: 0
A4: 1 | B4: =COUNTIFS($A$2:$A$23,A4,$BK$2:$BK$23,">"&BK4)+1 | C4: BSVN | D4: Bank7 Corp. Common stock | E4: NASDAQ | F4: 金融 | G4: Major Banks | H4: 0.527 | I4: 小型 | J4: 54.53 | K4: 55.28 | L4: =J4/K4-1 | M4: 55.62 | N4: 54.53 | O4: 54.926 | P4: 54.7495 | Q4: =J4/P4-1 | R4: 52.5268 | S4: 53.857 | T4: =P4/S4-1 | U4: 57.43 | V4: 2026-09-04 | W4: 17 | X4: =J4/U4-1 | Y4: 2026-06-08 | Z4: 62 | AA4: 0.27735765 | AB4: 0.10155268 | AC4: -0.004009169 | AD4: 2026-09-04 | AE4: 0.094947569 | AF4: 0.034318398 | AG4: 3.0870712 | AH4: 1 | AI4: 1750458.5 | AJ4: 510658.97 | AK4: =AI4/AJ4 | AL4: 2026-09-18 | AM4: 0.057781113 | AN4: 1 | AO4: 1.2845178 | AP4: 0.018636584 | AQ4: 0.028818827 | AR4: 0.029795929 | AS4: =AP4/AQ4 | AT4: =AP4/AR4 | AU4: =MAX(0,MIN(1,(AK4-2)/4)) | AV4: =MAX(0,MIN(1,(AG4-3)/7)) | AW4: =MAX(0,MIN(1,(AA4-0.25)/0.75)) | AX4: =MAX(0,MIN(1,(AM4-0.05)/0.2)) | AY4: =MAX(0,MIN(1,(AN4-0.7)/0.3)) | AZ4: =MAX(0,MIN(1,(AO4-1.2)/(0.6-1.2))) | BA4: =MAX(0,MIN(1,(ABS(Q4)-0.03)/(0-0.03))) | BB4: =MAX(0,MIN(1,T4/0.03)) | BC4: =MAX(0,MIN(1,(-X4-0.3)/(0.15-0.3))) | BD4: =0.5*IF(M4>N4,(J4-N4)/(M4-N4),0.5)+0.5*(J4>=P4) | BE4: =MAX(0,MIN(1,(AS4-0.9)/(0.5-0.9))) | BF4: =MAX(0,MIN(1,(AT4-0.7)/(0.3-0.7))) | BG4: =100*(0.4*AU4+0.3*AV4+0.3*AW4) | BH4: =100*(0.5*AX4+0.5*AY4) | BI4: =100*(0.3*AZ4+0.25*BA4+0.2*BB4+0.1*BC4+0.15*BD4) | BJ4: =100*(0.5*BE4+0.5*BF4) | BK4: =0.25*BG4+0.2*BH4+0.3*BI4+0.25*BJ4 | BN4: 22/26 | BO4: 今日放量（2.1× 50日均量）收喺 20MA 下面；20 日成交額中位數只有 $2.6M（股票池下限 $1M），入市出市都會有滑價 | BP4: 0
A5: 2 | B5: =COUNTIFS($A$2:$A$23,A5,$BK$2:$BK$23,">"&BK5)+1 | C5: CRSR | D5: Corsair Gaming Inc. | E5: NASDAQ | F5: 科技 | G5: Computer peripheral equipment | H5: 1.456 | I5: 小型 | J5: 13.5 | K5: 13.46 | L5: =J5/K5-1 | M5: 13.72 | N5: 13.38 | O5: 13.518 | P5: 13.151 | Q5: =J5/P5-1 | R5: 12.2053 | S5: 12.747 | T5: =P5/S5-1 | U5: 14.35 | V5: 2026-08-07 | W5: 37 | X5: =J5/U5-1 | Y5: 2026-05-19 | Z5: 55 | AA5: 1.1385991 | AB5: 0.37527853 | AC5: 0.017203556 | AD5: 2026-05-28 | AE5: 0.21690428 | AF5: 0.1293279 | AG5: 18.561187 | AH5: 3 | AI5: 30175268 | AJ5: 8025177.2 | AK5: =AI5/AJ5 | AL5: 2026-08-18 | AM5: 0.19666303 | AN5: 1 | AO5: 0.69396612 | AP5: 0.033655251 | AQ5: 0.043985022 | AR5: 0.084280151 | AS5: =AP5/AQ5 | AT5: =AP5/AR5 | AU5: =MAX(0,MIN(1,(AK5-2)/4)) | AV5: =MAX(0,MIN(1,(AG5-3)/7)) | AW5: =MAX(0,MIN(1,(AA5-0.25)/0.75)) | AX5: =MAX(0,MIN(1,(AM5-0.05)/0.2)) | AY5: =MAX(0,MIN(1,(AN5-0.7)/0.3)) | AZ5: =MAX(0,MIN(1,(AO5-1.2)/(0.6-1.2))) | BA5: =MAX(0,MIN(1,(ABS(Q5)-0.03)/(0-0.03))) | BB5: =MAX(0,MIN(1,T5/0.03)) | BC5: =MAX(0,MIN(1,(-X5-0.3)/(0.15-0.3))) | BD5: =0.5*IF(M5>N5,(J5-N5)/(M5-N5),0.5)+0.5*(J5>=P5) | BE5: =MAX(0,MIN(1,(AS5-0.9)/(0.5-0.9))) | BF5: =MAX(0,MIN(1,(AT5-0.7)/(0.3-0.7))) | BG5: =100*(0.4*AU5+0.3*AV5+0.3*AW5) | BH5: =100*(0.5*AX5+0.5*AY5) | BI5: =100*(0.3*AZ5+0.25*BA5+0.2*BB5+0.1*BC5+0.15*BD5) | BJ5: =100*(0.5*BE5+0.5*BF5) | BK5: =0.25*BG5+0.2*BH5+0.3*BI5+0.25*BJ5 | BL5: C3 回落20MA：高位喺 37 日前；近 3 日最低價距 MA20 +1.7% | BO5: 疑似釘價：10 日收市區間只有 2.1%，之前有單日 +35% | BP5: 0
A6: 2 | B6: =COUNTIFS($A$2:$A$23,A6,$BK$2:$BK$23,">"&BK6)+1 | C6: CMRC | D6: Commerce.com Inc. Series 1 | E6: NASDAQ | F6: 科技 | G6: Computer Software: Prepackaged Software | H6: 0.258 | I6: 小型 | J6: 3.16 | K6: 3.11 | L6: =J6/K6-1 | M6: 3.235 | N6: 3.08 | O6: 3.2525 | P6: 3.124 | Q6: =J6/P6-1 | R6: 2.7733 | S6: 2.92575 | T6: =P6/S6-1 | U6: 3.64 | V6: 2026-09-14 | W6: 12 | X6: =J6/U6-1 | Y6: 2026-08-17 | Z6: 19 | AA6: 0.76699029 | AB6: 0.45150035 | AC6: -0.014084507 | AD6: 2026-09-10 | AE6: 0.18461538 | AF6: 0.11538462 | AG6: 4.4040514 | AH6: 3 | AI6: 3783023.1 | AJ6: 2192366.5 | AK6: =AI6/AJ6 | AL6: 2026-09-23 | AM6: 0.37865854 | AN6: 1 | AO6: 0.48346396 | AP6: 0.044198188 | AQ6: 0.068979782 | AR6: 0.085745533 | AS6: =AP6/AQ6 | AT6: =AP6/AR6 | AU6: =MAX(0,MIN(1,(AK6-2)/4)) | AV6: =MAX(0,MIN(1,(AG6-3)/7)) | AW6: =MAX(0,MIN(1,(AA6-0.25)/0.75)) | AX6: =MAX(0,MIN(1,(AM6-0.05)/0.2)) | AY6: =MAX(0,MIN(1,(AN6-0.7)/0.3)) | AZ6: =MAX(0,MIN(1,(AO6-1.2)/(0.6-1.2))) | BA6: =MAX(0,MIN(1,(ABS(Q6)-0.03)/(0-0.03))) | BB6: =MAX(0,MIN(1,T6/0.03)) | BC6: =MAX(0,MIN(1,(-X6-0.3)/(0.15-0.3))) | BD6: =0.5*IF(M6>N6,(J6-N6)/(M6-N6),0.5)+0.5*(J6>=P6) | BE6: =MAX(0,MIN(1,(AS6-0.9)/(0.5-0.9))) | BF6: =MAX(0,MIN(1,(AT6-0.7)/(0.3-0.7))) | BG6: =100*(0.4*AU6+0.3*AV6+0.3*AW6) | BH6: =100*(0.5*AX6+0.5*AY6) | BI6: =100*(0.3*AZ6+0.25*BA6+0.2*BB6+0.1*BC6+0.15*BD6) | BJ6: =100*(0.5*BE6+0.5*BF6) | BK6: =0.25*BG6+0.2*BH6+0.3*BI6+0.25*BJ6 | BL6: C1b 熱錢：升浪成交額係之前 60 日嘅 1.73×（要 ≥2.0×） | BO6: 20 日成交額中位數只有 $2.2M（股票池下限 $1M），入市出市都會有滑價 | BP6: 0
A7: 2 | B7: =COUNTIFS($A$2:$A$23,A7,$BK$2:$BK$23,">"&BK7)+1 | C7: OMER | D7: Omeros Corporation | E7: NASDAQ | F7: 醫療保健 | G7: Biotechnology: Pharmaceutical Preparations | H7: 1.393 | I7: 小型 | J7: 19.04 | K7: 19.25 | L7: =J7/K7-1 | M7: 19.4 | N7: 19.02 | O7: 19.453 | P7: 18.94 | Q7: =J7/P7-1 | R7: 16.597 | S7: 18.7245 | T7: =P7/S7-1 | U7: 21.05 | V7: 2026-09-22 | W7: 6 | X7: =J7/U7-1 | Y7: 2026-06-26 | Z7: 60 | AA7: 1.4279123 | AB7: 0.12859556 | AC7: 0.0039364878 | AD7: 2026-08-13 | AE7: 0.26549964 | AF7: 0.21444201 | AG7: 7.0710505 | AH7: 2 | AI7: 29218304 | AJ7: 18980138 | AK7: =AI7/AJ7 | AL7: 2026-08-26 | AM7: 0.40967118 | AN7: 1 | AO7: 0.66260258 | AP7: 0.035289293 | AQ7: 0.046988346 | AR7: 0.063079394 | AS7: =AP7/AQ7 | AT7: =AP7/AR7 | AU7: =MAX(0,MIN(1,(AK7-2)/4)) | AV7: =MAX(0,MIN(1,(AG7-3)/7)) | AW7: =MAX(0,MIN(1,(AA7-0.25)/0.75)) | AX7: =MAX(0,MIN(1,(AM7-0.05)/0.2)) | AY7: =MAX(0,MIN(1,(AN7-0.7)/0.3)) | AZ7: =MAX(0,MIN(1,(AO7-1.2)/(0.6-1.2))) | BA7: =MAX(0,MIN(1,(ABS(Q7)-0.03)/(0-0.03))) | BB7: =MAX(0,MIN(1,T7/0.03)) | BC7: =MAX(0,MIN(1,(-X7-0.3)/(0.15-0.3))) | BD7: =0.5*IF(M7>N7,(J7-N7)/(M7-N7),0.5)+0.5*(J7>=P7) | BE7: =MAX(0,MIN(1,(AS7-0.9)/(0.5-0.9))) | BF7: =MAX(0,MIN(1,(AT7-0.7)/(0.3-0.7))) | BG7: =100*(0.4*AU7+0.3*AV7+0.3*AW7) | BH7: =100*(0.5*AX7+0.5*AY7) | BI7: =100*(0.3*AZ7+0.25*BA7+0.2*BB7+0.1*BC7+0.15*BD7) | BJ7: =100*(0.5*BE7+0.5*BF7) | BK7: =0.25*BG7+0.2*BH7+0.3*BI7+0.25*BJ7 | BL7: C1b 熱錢：升浪成交額係之前 60 日嘅 1.54×（要 ≥2.0×） | BP7: 0
A8: 2 | B8: =COUNTIFS($A$2:$A$23,A8,$BK$2:$BK$23,">"&BK8)+1 | C8: HAE | D8: Haemonetics Corporation | E8: NYSE | F8: 醫療保健 | G8: Medical/Dental Instruments | H8: 4.814 | I8: 中型 | J8: 105.3 | K8: 105.8 | L8: =J8/K8-1 | M8: 105.78 | N8: 103.54 | O8: 106.826 | P8: 105.2725 | Q8: =J8/P8-1 | R8: 97.8104 | S8: 104.892 | T8: =P8/S8-1 | U8: 108.8 | V8: 2026-08-21 | W8: 27 | X8: =J8/U8-1 | Y8: 2026-05-21 | Z8: 63 | AA8: 0.75653859 | AB8: 0.19985002 | AC8: -0.016457289 | AD8: 2026-08-18 | AE8: 0.15929988 | AF8: 0.13548244 | AG8: 2.7825999 | AH8: 1 | AI8: 70451532 | AJ8: 45639027 | AK8: =AI8/AJ8 | AL8: 2026-08-31 | AM8: 0.21283838 | AN8: 1 | AO8: 0.63608504 | AP8: 0.019117473 | AQ8: 0.024422688 | AR8: 0.039705023 | AS8: =AP8/AQ8 | AT8: =AP8/AR8 | AU8: =MAX(0,MIN(1,(AK8-2)/4)) | AV8: =MAX(0,MIN(1,(AG8-3)/7)) | AW8: =MAX(0,MIN(1,(AA8-0.25)/0.75)) | AX8: =MAX(0,MIN(1,(AM8-0.05)/0.2)) | AY8: =MAX(0,MIN(1,(AN8-0.7)/0.3)) | AZ8: =MAX(0,MIN(1,(AO8-1.2)/(0.6-1.2))) | BA8: =MAX(0,MIN(1,(ABS(Q8)-0.03)/(0-0.03))) | BB8: =MAX(0,MIN(1,T8/0.03)) | BC8: =MAX(0,MIN(1,(-X8-0.3)/(0.15-0.3))) | BD8: =0.5*IF(M8>N8,(J8-N8)/(M8-N8),0.5)+0.5*(J8>=P8) | BE8: =MAX(0,MIN(1,(AS8-0.9)/(0.5-0.9))) | BF8: =MAX(0,MIN(1,(AT8-0.7)/(0.3-0.7))) | BG8: =100*(0.4*AU8+0.3*AV8+0.3*AW8) | BH8: =100*(0.5*AX8+0.5*AY8) | BI8: =100*(0.3*AZ8+0.25*BA8+0.2*BB8+0.1*BC8+0.15*BD8) | BJ8: =100*(0.5*BE8+0.5*BF8) | BK8: =0.25*BG8+0.2*BH8+0.3*BI8+0.25*BJ8 | BL8: C1a 事件日：高位前 60 日最大量日只有 2.8× 50日均量（當日 +15.9%）；要 ≥3× 兼當日 ≥+8% 或開市跳空 ≥+5%；C1b 熱錢：升浪成交額係之前 60 日嘅 1.54×（要 ≥2.0×）；C3 回落20MA：高位喺 27 日前 | BP8: 0
A9: 2 | B9: =COUNTIFS($A$2:$A$23,A9,$BK$2:$BK$23,">"&BK9)+1 | C9: ASST | D9: Strive Inc. Class A | E9: NASDAQ | F9: 金融 | G9: Finance: Consumer Services | H9: 2.843 | I9: 中型 | J9: 29.41 | K9: 29.31 | L9: =J9/K9-1 | M9: 30.54 | N9: 28.96 | O9: 29.414 | P9: 28.24 | Q9: =J9/P9-1 | R9: 20.2783 | S9: 26.614 | T9: =P9/S9-1 | U9: 30.33 | V9: 2026-09-21 | W9: 7 | X9: =J9/U9-1 | Y9: 2026-06-30 | Z9: 57 | AA9: 1.7800183 | AB9: 0.17772687 | AC9: 0.024687606 | AD9: 2026-08-21 | AE9: 0.12957223 | AF9: 0.094854309 | AG9: 3.9426733 | AH9: 10 | AI9: 1.3364698e+08 | AJ9: 67550215 | AK9: =AI9/AJ9 | AL9: 2026-09-03 | AM9: 0.70907848 | AN9: 1 | AO9: 0.52413831 | AP9: 0.052990963 | AQ9: 0.072203471 | AR9: 0.081775654 | AS9: =AP9/AQ9 | AT9: =AP9/AR9 | AU9: =MAX(0,MIN(1,(AK9-2)/4)) | AV9: =MAX(0,MIN(1,(AG9-3)/7)) | AW9: =MAX(0,MIN(1,(AA9-0.25)/0.75)) | AX9: =MAX(0,MIN(1,(AM9-0.05)/0.2)) | AY9: =MAX(0,MIN(1,(AN9-0.7)/0.3)) | AZ9: =MAX(0,MIN(1,(AO9-1.2)/(0.6-1.2))) | BA9: =MAX(0,MIN(1,(ABS(Q9)-0.03)/(0-0.03))) | BB9: =MAX(0,MIN(1,T9/0.03)) | BC9: =MAX(0,MIN(1,(-X9-0.3)/(0.15-0.3))) | BD9: =0.5*IF(M9>N9,(J9-N9)/(M9-N9),0.5)+0.5*(J9>=P9) | BE9: =MAX(0,MIN(1,(AS9-0.9)/(0.5-0.9))) | BF9: =MAX(0,MIN(1,(AT9-0.7)/(0.3-0.7))) | BG9: =100*(0.4*AU9+0.3*AV9+0.3*AW9) | BH9: =100*(0.5*AX9+0.5*AY9) | BI9: =100*(0.3*AZ9+0.25*BA9+0.2*BB9+0.1*BC9+0.15*BD9) | BJ9: =100*(0.5*BE9+0.5*BF9) | BK9: =0.25*BG9+0.2*BH9+0.3*BI9+0.25*BJ9 | BL9: C1b 熱錢：升浪成交額係之前 60 日嘅 1.98×（要 ≥2.0×）；C3 回落20MA：收市距 MA20 +4.1%；近 3 日最低價距 MA20 +2.5% | BO9: 比特幣庫存公司，股價跟比特幣走；同名單入面 GEMI、PURR 同向（21 日相關系數中位數 +0.66，名單其餘 +0.08）：當一個交易睇 | BP9: 0
A10: 2 | B10: =COUNTIFS($A$2:$A$23,A10,$BK$2:$BK$23,">"&BK10)+1 | C10: GEMI | D10: Gemini Space Station Inc. Class A | E10: NASDAQ | F10: 金融 | G10: Finance: Consumer Services | H10: 0.686 | I10: 小型 | J10: 5.16 | K10: 5.29 | L10: =J10/K10-1 | M10: 5.548 | N10: 5.12 | O10: 5.465 | P10: 4.98925 | Q10: =J10/P10-1 | R10: 4.507 | S10: 4.75775 | T10: =P10/S10-1 | U10: 5.99 | V10: 2026-09-21 | W10: 7 | X10: =J10/U10-1 | Y10: 2026-08-18 | Z10: 23 | AA10: 0.6920904 | AB10: 0.2961861 | AC10: 0.026206344 | AD10: 2026-09-18 | AE10: 0.31151242 | AF10: 0.031602709 | AG10: 7.8094921 | AH10: 5 | AI10: 16181145 | AJ10: 7145468.7 | AK10: =AI10/AJ10 | AL10: 2026-09-29 | AM10: 0.18962651 | AN10: 1 | AO10: 0.74148828 | AP10: 0.067280114 | AQ10: 0.093967091 | AR10: 0.1098988 | AS10: =AP10/AQ10 | AT10: =AP10/AR10 | AU10: =MAX(0,MIN(1,(AK10-2)/4)) | AV10: =MAX(0,MIN(1,(AG10-3)/7)) | AW10: =MAX(0,MIN(1,(AA10-0.25)/0.75)) | AX10: =MAX(0,MIN(1,(AM10-0.05)/0.2)) | AY10: =MAX(0,MIN(1,(AN10-0.7)/0.3)) | AZ10: =MAX(0,MIN(1,(AO10-1.2)/(0.6-1.2))) | BA10: =MAX(0,MIN(1,(ABS(Q10)-0.03)/(0-0.03))) | BB10: =MAX(0,MIN(1,T10/0.03)) | BC10: =MAX(0,MIN(1,(-X10-0.3)/(0.15-0.3))) | BD10: =0.5*IF(M10>N10,(J10-N10)/(M10-N10),0.5)+0.5*(J10>=P10) | BE10: =MAX(0,MIN(1,(AS10-0.9)/(0.5-0.9))) | BF10: =MAX(0,MIN(1,(AT10-0.7)/(0.3-0.7))) | BG10: =100*(0.4*AU10+0.3*AV10+0.3*AW10) | BH10: =100*(0.5*AX10+0.5*AY10) | BI10: =100*(0.3*AZ10+0.25*BA10+0.2*BB10+0.1*BC10+0.15*BD10) | BJ10: =100*(0.5*BE10+0.5*BF10) | BK10: =0.25*BG10+0.2*BH10+0.3*BI10+0.25*BJ10 | BL10: C3 回落20MA：收市距 MA20 +3.4%；近 3 日最低價距 MA20 +2.6% | BO10: 09-18 +31% 係加密板塊因 SEC 代幣化豁免同升；一年跌 76%，升浪係低位反彈而非趨勢；同名單入面 ASST、PURR 同向（21 日相關系數中位數 +0.66，名單其餘 +0.08）：當一個交易睇 | BP10: 0
A11: 2 | B11: =COUNTIFS($A$2:$A$23,A11,$BK$2:$BK$23,">"&BK11)+1 | C11: UMAC | D11: Unusual Machines Inc. | E11: AMEX | F11: 科技 | G11: Radio And Television Broadcasting And Communications Equipment | H11: 1.246 | I11: 小型 | J11: 24.48 | K11: 24.94 | L11: =J11/K11-1 | M11: 25.78 | N11: 24.471 | O11: 23.939 | P11: 23.7845 | Q11: =J11/P11-1 | R11: 24.296 | S11: 23.741 | T11: =P11/S11-1 | U11: 34.06 | V11: 2026-08-14 | W11: 32 | X11: =J11/U11-1 | Y11: 2026-05-19 | Z11: 60 | AA11: 1.4934114 | AB11: 0.46756576 | AC11: -0.012251635 | AD11: 2026-05-28 | AE11: 0.57195964 | AF11: 0.32766861 | AG11: 10.641854 | AH11: 4 | AI11: 1.5304486e+08 | AJ11: 71336482 | AK11: =AI11/AJ11 | AL11: 2026-08-18 | AM11: 0.32653159 | AN11: 1 | AO11: 0.73606859 | AP11: 0.06221733 | AQ11: 0.068766105 | AR11: 0.13462935 | AS11: =AP11/AQ11 | AT11: =AP11/AR11 | AU11: =MAX(0,MIN(1,(AK11-2)/4)) | AV11: =MAX(0,MIN(1,(AG11-3)/7)) | AW11: =MAX(0,MIN(1,(AA11-0.25)/0.75)) | AX11: =MAX(0,MIN(1,(AM11-0.05)/0.2)) | AY11: =MAX(0,MIN(1,(AN11-0.7)/0.3)) | AZ11: =MAX(0,MIN(1,(AO11-1.2)/(0.6-1.2))) | BA11: =MAX(0,MIN(1,(ABS(Q11)-0.03)/(0-0.03))) | BB11: =MAX(0,MIN(1,T11/0.03)) | BC11: =MAX(0,MIN(1,(-X11-0.3)/(0.15-0.3))) | BD11: =0.5*IF(M11>N11,(J11-N11)/(M11-N11),0.5)+0.5*(J11>=P11) | BE11: =MAX(0,MIN(1,(AS11-0.9)/(0.5-0.9))) | BF11: =MAX(0,MIN(1,(AT11-0.7)/(0.3-0.7))) | BG11: =100*(0.4*AU11+0.3*AV11+0.3*AW11) | BH11: =100*(0.5*AX11+0.5*AY11) | BI11: =100*(0.3*AZ11+0.25*BA11+0.2*BB11+0.1*BC11+0.15*BD11) | BJ11: =100*(0.5*BE11+0.5*BF11) | BK11: =0.25*BG11+0.2*BH11+0.3*BI11+0.25*BJ11 | BL11: C3 回落20MA：高位喺 32 日前；C4 波幅減低：ATR5/ATR20 0.90（要 ≤0.9）；ATR5 係升浪期 ATR 嘅 0.46×（要 ≤0.7） | BO11: 回調唔係有序回落：期內有一日跌 -11.5%；05-28 +57% 係 WSJ 傳聞（政府資助無人機公司）帶動；距高位 −28% | BP11: 0
A12: 2 | B12: =COUNTIFS($A$2:$A$23,A12,$BK$2:$BK$23,">"&BK12)+1 | C12: PURR | D12: Hyperliquid Strategies Inc | E12: NASDAQ | F12: 金融 | G12: Finance: Consumer Services | H12: 2.836 | I12: 中型 | J12: 12.27 | K12: 11.92 | L12: =J12/K12-1 | M12: 12.545 | N12: 11.983 | O12: 13.157 | P12: 12.4455 | Q12: =J12/P12-1 | R12: 9.8613 | S12: 12.26525 | T12: =P12/S12-1 | U12: 14.09 | V12: 2026-09-24 | W12: 4 | X12: =J12/U12-1 | Y12: 2026-07-29 | Z12: 40 | AA12: 1.360134 | AB12: 0.13704683 | AC12: -0.045948507 | AD12: 2026-08-19 | AE12: 0.30416667 | AF12: 0.0083333333 | AG12: 5.6583757 | AH12: 6 | AI12: 2.4268078e+08 | AJ12: 1.2103013e+08 | AK12: =AI12/AJ12 | AL12: 2026-09-01 | AM12: 0.64778904 | AN12: 1 | AO12: 0.72400243 | AP12: 0.073102523 | AQ12: 0.091242095 | AR12: 0.096628737 | AS12: =AP12/AQ12 | AT12: =AP12/AR12 | AU12: =MAX(0,MIN(1,(AK12-2)/4)) | AV12: =MAX(0,MIN(1,(AG12-3)/7)) | AW12: =MAX(0,MIN(1,(AA12-0.25)/0.75)) | AX12: =MAX(0,MIN(1,(AM12-0.05)/0.2)) | AY12: =MAX(0,MIN(1,(AN12-0.7)/0.3)) | AZ12: =MAX(0,MIN(1,(AO12-1.2)/(0.6-1.2))) | BA12: =MAX(0,MIN(1,(ABS(Q12)-0.03)/(0-0.03))) | BB12: =MAX(0,MIN(1,T12/0.03)) | BC12: =MAX(0,MIN(1,(-X12-0.3)/(0.15-0.3))) | BD12: =0.5*IF(M12>N12,(J12-N12)/(M12-N12),0.5)+0.5*(J12>=P12) | BE12: =MAX(0,MIN(1,(AS12-0.9)/(0.5-0.9))) | BF12: =MAX(0,MIN(1,(AT12-0.7)/(0.3-0.7))) | BG12: =100*(0.4*AU12+0.3*AV12+0.3*AW12) | BH12: =100*(0.5*AX12+0.5*AY12) | BI12: =100*(0.3*AZ12+0.25*BA12+0.2*BB12+0.1*BC12+0.15*BD12) | BJ12: =100*(0.5*BE12+0.5*BF12) | BK12: =0.25*BG12+0.2*BH12+0.3*BI12+0.25*BJ12 | BL12: C4 波幅減低：ATR5/ATR20 0.80（要 ≤0.9）；ATR5 係升浪期 ATR 嘅 0.76×（要 ≤0.7） | BM12: 10 | BO12: 回調唔係有序回落：期內有一日跌 -8.8%；加密貨幣（HYPE 代幣）庫存公司，股價跟代幣走；09-25 監管負面消息；同名單入面 ASST、GEMI 同向（21 日相關系數中位數 +0.66，名單其餘 +0.08）：當一個交易睇 | BP12: 0
A13: 2 | B13: =COUNTIFS($A$2:$A$23,A13,$BK$2:$BK$23,">"&BK13)+1 | C13: UTMD | D13: Utah Medical Products Inc. | E13: NASDAQ | F13: 醫療保健 | G13: Medical/Dental Instruments | H13: 0.239 | I13: 小型 | J13: 74.05 | K13: 74.95 | L13: =J13/K13-1 | M13: 74.95 | N13: 74.04 | O13: 74.672 | P13: 72.888 | Q13: =J13/P13-1 | R13: 71.663 | S13: 72.1845 | T13: =P13/S13-1 | U13: 76.66 | V13: 2026-09-22 | W13: 6 | X13: =J13/U13-1 | Y13: 2026-07-23 | Z13: 42 | AA13: 0.1944531 | AB13: 0.064988469 | AC13: 0.015805071 | AD13: 2026-06-26 | AE13: 0.10617616 | AF13: 0.035890534 | AG13: 7.8402367 | AH13: 1 | AI13: 2595278 | AJ13: 988995.47 | AK13: =AI13/AJ13 | AL13: 2026-09-28 | AM13: 0.05837729 | AN13: 1 | AO13: 0.86861949 | AP13: 0.011456194 | AQ13: 0.01917648 | AR13: 0.027771946 | AS13: =AP13/AQ13 | AT13: =AP13/AR13 | AU13: =MAX(0,MIN(1,(AK13-2)/4)) | AV13: =MAX(0,MIN(1,(AG13-3)/7)) | AW13: =MAX(0,MIN(1,(AA13-0.25)/0.75)) | AX13: =MAX(0,MIN(1,(AM13-0.05)/0.2)) | AY13: =MAX(0,MIN(1,(AN13-0.7)/0.3)) | AZ13: =MAX(0,MIN(1,(AO13-1.2)/(0.6-1.2))) | BA13: =MAX(0,MIN(1,(ABS(Q13)-0.03)/(0-0.03))) | BB13: =MAX(0,MIN(1,T13/0.03)) | BC13: =MAX(0,MIN(1,(-X13-0.3)/(0.15-0.3))) | BD13: =0.5*IF(M13>N13,(J13-N13)/(M13-N13),0.5)+0.5*(J13>=P13) | BE13: =MAX(0,MIN(1,(AS13-0.9)/(0.5-0.9))) | BF13: =MAX(0,MIN(1,(AT13-0.7)/(0.3-0.7))) | BG13: =100*(0.4*AU13+0.3*AV13+0.3*AW13) | BH13: =100*(0.5*AX13+0.5*AY13) | BI13: =100*(0.3*AZ13+0.25*BA13+0.2*BB13+0.1*BC13+0.15*BD13) | BJ13: =100*(0.5*BE13+0.5*BF13) | BK13: =0.25*BG13+0.2*BH13+0.3*BI13+0.25*BJ13 | BL13: C3 回落20MA：高位時只高過 MA20 6.5%；近 3 日最低價距 MA20 +1.6% | BO13: 事件日升幅：媒體 +6.6% vs 我哋數據 +10.6%，未對得上；20 日成交額中位數只有 $2.2M（股票池下限 $1M），入市出市都會有滑價 | BP13: 0
A14: 2 | B14: =COUNTIFS($A$2:$A$23,A14,$BK$2:$BK$23,">"&BK14)+1 | C14: RNG | D14: RingCentral Inc. Class A | E14: NYSE | F14: 科技 | G14: EDP Services | H14: 6.215 | I14: 中型 | J14: 74.7 | K14: 74.43 | L14: =J14/K14-1 | M14: 76.35 | N14: 73.99 | O14: 76.414 | P14: 74.1275 | Q14: =J14/P14-1 | R14: 66.3254 | S14: 72.2835 | T14: =P14/S14-1 | U14: 79.82 | V14: 2026-09-24 | W14: 4 | X14: =J14/U14-1 | Y14: 2026-06-25 | Z14: 63 | AA14: 1.3036075 | AB14: 0.093851709 | AC14: -0.022196372 | AD14: 2026-07-24 | AE14: 0.25090627 | AF14: 0.048679441 | AG14: 5.3486415 | AH14: 2 | AI14: 1.0816547e+08 | AJ14: 68510316 | AK14: =AI14/AJ14 | AL14: 2026-08-18 | AM14: 0.22774925 | AN14: 1 | AO14: 0.92785216 | AP14: 0.040702046 | AQ14: 0.04710444 | AR14: 0.055257513 | AS14: =AP14/AQ14 | AT14: =AP14/AR14 | AU14: =MAX(0,MIN(1,(AK14-2)/4)) | AV14: =MAX(0,MIN(1,(AG14-3)/7)) | AW14: =MAX(0,MIN(1,(AA14-0.25)/0.75)) | AX14: =MAX(0,MIN(1,(AM14-0.05)/0.2)) | AY14: =MAX(0,MIN(1,(AN14-0.7)/0.3)) | AZ14: =MAX(0,MIN(1,(AO14-1.2)/(0.6-1.2))) | BA14: =MAX(0,MIN(1,(ABS(Q14)-0.03)/(0-0.03))) | BB14: =MAX(0,MIN(1,T14/0.03)) | BC14: =MAX(0,MIN(1,(-X14-0.3)/(0.15-0.3))) | BD14: =0.5*IF(M14>N14,(J14-N14)/(M14-N14),0.5)+0.5*(J14>=P14) | BE14: =MAX(0,MIN(1,(AS14-0.9)/(0.5-0.9))) | BF14: =MAX(0,MIN(1,(AT14-0.7)/(0.3-0.7))) | BG14: =100*(0.4*AU14+0.3*AV14+0.3*AW14) | BH14: =100*(0.5*AX14+0.5*AY14) | BI14: =100*(0.3*AZ14+0.25*BA14+0.2*BB14+0.1*BC14+0.15*BD14) | BJ14: =100*(0.5*BE14+0.5*BF14) | BK14: =0.25*BG14+0.2*BH14+0.3*BI14+0.25*BJ14 | BL14: C1b 熱錢：升浪成交額係之前 60 日嘅 1.58×（要 ≥2.0×）；C4 波幅減低：ATR5/ATR20 0.86（要 ≤0.9）；ATR5 係升浪期 ATR 嘅 0.74×（要 ≤0.7） | BP14: 0
A15: 2 | B15: =COUNTIFS($A$2:$A$23,A15,$BK$2:$BK$23,">"&BK15)+1 | C15: ASO | D15: Academy Sports and Outdoors Inc. | E15: NASDAQ | F15: 非必需消費 | G15: Other Specialty Stores | H15: 2.949 | I15: 中型 | J15: 48.09 | K15: 47.89 | L15: =J15/K15-1 | M15: 48.605 | N15: 47.5 | O15: 48.613 | P15: 48.94475 | Q15: =J15/P15-1 | R15: 47.7987 | S15: 47.62425 | T15: =P15/S15-1 | U15: 55.36 | V15: 2026-09-11 | W15: 13 | X15: =J15/U15-1 | Y15: 2026-08-27 | Z15: 10 | AA15: 0.298616 | AB15: 0.19987212 | AC15: -0.029517977 | AD15: 2026-09-09 | AE15: 0.14403936 | AF15: 0.067770074 | AG15: 3.9812206 | AH15: 1 | AI15: 1.2084484e+08 | AJ15: 76894564 | AK15: =AI15/AJ15 | AL15: 2026-09-22 | AM15: 0.17423226 | AN15: 1 | AO15: 0.74337214 | AP15: 0.028880294 | AQ15: 0.04395519 | AR15: 0.048994834 | AS15: =AP15/AQ15 | AT15: =AP15/AR15 | AU15: =MAX(0,MIN(1,(AK15-2)/4)) | AV15: =MAX(0,MIN(1,(AG15-3)/7)) | AW15: =MAX(0,MIN(1,(AA15-0.25)/0.75)) | AX15: =MAX(0,MIN(1,(AM15-0.05)/0.2)) | AY15: =MAX(0,MIN(1,(AN15-0.7)/0.3)) | AZ15: =MAX(0,MIN(1,(AO15-1.2)/(0.6-1.2))) | BA15: =MAX(0,MIN(1,(ABS(Q15)-0.03)/(0-0.03))) | BB15: =MAX(0,MIN(1,T15/0.03)) | BC15: =MAX(0,MIN(1,(-X15-0.3)/(0.15-0.3))) | BD15: =0.5*IF(M15>N15,(J15-N15)/(M15-N15),0.5)+0.5*(J15>=P15) | BE15: =MAX(0,MIN(1,(AS15-0.9)/(0.5-0.9))) | BF15: =MAX(0,MIN(1,(AT15-0.7)/(0.3-0.7))) | BG15: =100*(0.4*AU15+0.3*AV15+0.3*AW15) | BH15: =100*(0.5*AX15+0.5*AY15) | BI15: =100*(0.3*AZ15+0.25*BA15+0.2*BB15+0.1*BC15+0.15*BD15) | BJ15: =100*(0.5*BE15+0.5*BF15) | BK15: =0.25*BG15+0.2*BH15+0.3*BI15+0.25*BJ15 | BL15: C1b 熱錢：升浪成交額係之前 60 日嘅 1.57×（要 ≥2.0×） | BP15: 0
A16: 2 | B16: =COUNTIFS($A$2:$A$23,A16,$BK$2:$BK$23,">"&BK16)+1 | C16: BVS | D16: Bioventus Inc. Class A | E16: NASDAQ | F16: 醫療保健 | G16: Medical/Dental Instruments | H16: 1.177 | I16: 小型 | J16: 13.63 | K16: 14 | L16: =J16/K16-1 | M16: 14.01 | N16: 13.57 | O16: 13.509 | P16: 13.5375 | Q16: =J16/P16-1 | R16: 13.5902 | S16: 13.5345 | T16: =P16/S16-1 | U16: 15.26 | V16: 2026-08-05 | W16: 39 | X16: =J16/U16-1 | Y16: 2026-06-01 | Z16: 45 | AA16: 0.92433796 | AB16: 0.22158181 | AC16: 0.0024007387 | AD16: 2026-08-05 | AE16: 0.13710879 | AF16: -0.054396423 | AG16: 3.4796438 | AH16: 2 | AI16: 8406014.2 | AJ16: 5016077.1 | AK16: =AI16/AJ16 | AL16: 2026-08-18 | AM16: 0.11415741 | AN16: 1 | AO16: 0.74174578 | AP16: 0.030031572 | AQ16: 0.037102474 | AR16: 0.0549209 | AS16: =AP16/AQ16 | AT16: =AP16/AR16 | AU16: =MAX(0,MIN(1,(AK16-2)/4)) | AV16: =MAX(0,MIN(1,(AG16-3)/7)) | AW16: =MAX(0,MIN(1,(AA16-0.25)/0.75)) | AX16: =MAX(0,MIN(1,(AM16-0.05)/0.2)) | AY16: =MAX(0,MIN(1,(AN16-0.7)/0.3)) | AZ16: =MAX(0,MIN(1,(AO16-1.2)/(0.6-1.2))) | BA16: =MAX(0,MIN(1,(ABS(Q16)-0.03)/(0-0.03))) | BB16: =MAX(0,MIN(1,T16/0.03)) | BC16: =MAX(0,MIN(1,(-X16-0.3)/(0.15-0.3))) | BD16: =0.5*IF(M16>N16,(J16-N16)/(M16-N16),0.5)+0.5*(J16>=P16) | BE16: =MAX(0,MIN(1,(AS16-0.9)/(0.5-0.9))) | BF16: =MAX(0,MIN(1,(AT16-0.7)/(0.3-0.7))) | BG16: =100*(0.4*AU16+0.3*AV16+0.3*AW16) | BH16: =100*(0.5*AX16+0.5*AY16) | BI16: =100*(0.3*AZ16+0.25*BA16+0.2*BB16+0.1*BC16+0.15*BD16) | BJ16: =100*(0.5*BE16+0.5*BF16) | BK16: =0.25*BG16+0.2*BH16+0.3*BI16+0.25*BJ16 | BL16: C1b 熱錢：升浪成交額係之前 60 日嘅 1.68×（要 ≥2.0×）；C3 回落20MA：高位喺 39 日前 | BO16: 回調唔係有序回落：期內有一日跌 -8.4% | BP16: 0
A17: 2 | B17: =COUNTIFS($A$2:$A$23,A17,$BK$2:$BK$23,">"&BK17)+1 | C17: PLSE | D17: Pulse Biosciences Inc | E17: NASDAQ | F17: 醫療保健 | G17: Medical/Dental Instruments | H17: 3.63 | I17: 中型 | J17: 49.92 | K17: 50.89 | L17: =J17/K17-1 | M17: 51.27 | N17: 49.17 | O17: 51.905 | P17: 52.4 | Q17: =J17/P17-1 | R17: 46.2134 | S17: 51.903 | T17: =P17/S17-1 | U17: 55.2 | V17: 2026-09-15 | W17: 11 | X17: =J17/U17-1 | Y17: 2026-06-16 | Z17: 62 | AA17: 1.1983274 | AB17: 0.087245546 | AC17: -0.068341316 | AD17: 2026-09-09 | AE17: 0.085673294 | AF17: 0.019881123 | AG17: 3.6619308 | AH17: 3 | AI17: 18850486 | AJ17: 7163912.6 | AK17: =AI17/AJ17 | AL17: 2026-08-20 | AM17: 0.26429075 | AN17: 1 | AO17: 0.99970496 | AP17: 0.052551883 | AQ17: 0.077568449 | AR17: 0.073918521 | AS17: =AP17/AQ17 | AT17: =AP17/AR17 | AU17: =MAX(0,MIN(1,(AK17-2)/4)) | AV17: =MAX(0,MIN(1,(AG17-3)/7)) | AW17: =MAX(0,MIN(1,(AA17-0.25)/0.75)) | AX17: =MAX(0,MIN(1,(AM17-0.05)/0.2)) | AY17: =MAX(0,MIN(1,(AN17-0.7)/0.3)) | AZ17: =MAX(0,MIN(1,(AO17-1.2)/(0.6-1.2))) | BA17: =MAX(0,MIN(1,(ABS(Q17)-0.03)/(0-0.03))) | BB17: =MAX(0,MIN(1,T17/0.03)) | BC17: =MAX(0,MIN(1,(-X17-0.3)/(0.15-0.3))) | BD17: =0.5*IF(M17>N17,(J17-N17)/(M17-N17),0.5)+0.5*(J17>=P17) | BE17: =MAX(0,MIN(1,(AS17-0.9)/(0.5-0.9))) | BF17: =MAX(0,MIN(1,(AT17-0.7)/(0.3-0.7))) | BG17: =100*(0.4*AU17+0.3*AV17+0.3*AW17) | BH17: =100*(0.5*AX17+0.5*AY17) | BI17: =100*(0.3*AZ17+0.25*BA17+0.2*BB17+0.1*BC17+0.15*BD17) | BJ17: =100*(0.5*BE17+0.5*BF17) | BK17: =0.25*BG17+0.2*BH17+0.3*BI17+0.25*BJ17 | BL17: C3 回落20MA：收市距 MA20 -4.7%；C4 波幅減低：ATR5/ATR20 0.68（要 ≤0.9）；ATR5 係升浪期 ATR 嘅 0.71×（要 ≤0.7） | BM17: 4 | BO17: 回調唔係有序回落：期內有一日跌 -10.1% | BP17: 0
A18: 2 | B18: =COUNTIFS($A$2:$A$23,A18,$BK$2:$BK$23,">"&BK18)+1 | C18: BBNX | D18: Beta Bionics Inc. | E18: NASDAQ | F18: 醫療保健 | G18: Medical/Dental Instruments | H18: 1.022 | I18: 小型 | J18: 18.98 | K18: 19.41 | L18: =J18/K18-1 | M18: 19.52 | N18: 18.45 | O18: 21.254 | P18: 19.96725 | Q18: =J18/P18-1 | R18: 18.2469 | S18: 19.73925 | T18: =P18/S18-1 | U18: 22.81 | V18: 2026-09-22 | W18: 6 | X18: =J18/U18-1 | Y18: 2026-07-31 | Z18: 36 | AA18: 0.77786438 | AB18: 0.16396852 | AC18: -0.075986929 | AD18: 2026-09-16 | AE18: 0.15340614 | AF18: -0.03224129 | AG18: 6.0478432 | AH18: 3 | AI18: 26116253 | AJ18: 14011813 | AK18: =AI18/AJ18 | AL18: 2026-08-24 | AM18: 0.26751418 | AN18: 1 | AO18: 0.87600751 | AP18: 0.058865017 | AQ18: 0.078431614 | AR18: 0.075525058 | AS18: =AP18/AQ18 | AT18: =AP18/AR18 | AU18: =MAX(0,MIN(1,(AK18-2)/4)) | AV18: =MAX(0,MIN(1,(AG18-3)/7)) | AW18: =MAX(0,MIN(1,(AA18-0.25)/0.75)) | AX18: =MAX(0,MIN(1,(AM18-0.05)/0.2)) | AY18: =MAX(0,MIN(1,(AN18-0.7)/0.3)) | AZ18: =MAX(0,MIN(1,(AO18-1.2)/(0.6-1.2))) | BA18: =MAX(0,MIN(1,(ABS(Q18)-0.03)/(0-0.03))) | BB18: =MAX(0,MIN(1,T18/0.03)) | BC18: =MAX(0,MIN(1,(-X18-0.3)/(0.15-0.3))) | BD18: =0.5*IF(M18>N18,(J18-N18)/(M18-N18),0.5)+0.5*(J18>=P18) | BE18: =MAX(0,MIN(1,(AS18-0.9)/(0.5-0.9))) | BF18: =MAX(0,MIN(1,(AT18-0.7)/(0.3-0.7))) | BG18: =100*(0.4*AU18+0.3*AV18+0.3*AW18) | BH18: =100*(0.5*AX18+0.5*AY18) | BI18: =100*(0.3*AZ18+0.25*BA18+0.2*BB18+0.1*BC18+0.15*BD18) | BJ18: =100*(0.5*BE18+0.5*BF18) | BK18: =0.25*BG18+0.2*BH18+0.3*BI18+0.25*BJ18 | BL18: C1b 熱錢：升浪成交額係之前 60 日嘅 1.86×（要 ≥2.0×）；C3 回落20MA：收市距 MA20 -4.9%；C4 波幅減低：ATR5/ATR20 0.75（要 ≤0.9）；ATR5 係升浪期 ATR 嘅 0.78×（要 ≤0.7） | BO18: 事件日同時宣布 $1.25 億配售（後定價 $1.5 億）；配售價係下面嘅參考位 | BP18: 0
A19: 2 | B19: =COUNTIFS($A$2:$A$23,A19,$BK$2:$BK$23,">"&BK19)+1 | C19: PKOH | D19: Park-Ohio Holdings Corp. | E19: NASDAQ | F19: 工業 | G19: Industrial Specialties | H19: 0.683 | I19: 小型 | J19: 46.2 | K19: 47.16 | L19: =J19/K19-1 | M19: 47.3 | N19: 45.72 | O19: 46.831 | P19: 46.2535 | Q19: =J19/P19-1 | R19: 45.082 | S19: 45.8585 | T19: =P19/S19-1 | U19: 52.51 | V19: 2026-08-07 | W19: 37 | X19: =J19/U19-1 | Y19: 2026-05-19 | Z19: 55 | AA19: 0.82263103 | AB19: 0.31747645 | AC19: -0.011534262 | AD19: 2026-08-07 | AE19: 0.12900452 | AF19: 0.017845625 | AG19: 2.7757226 | AH19: 2 | AI19: 3185602.8 | AJ19: 1374158.6 | AK19: =AI19/AJ19 | AL19: 2026-08-19 | AM19: 0.22643655 | AN19: 1 | AO19: 1.0130994 | AP19: 0.033105128 | AQ19: 0.033677549 | AR19: 0.047528948 | AS19: =AP19/AQ19 | AT19: =AP19/AR19 | AU19: =MAX(0,MIN(1,(AK19-2)/4)) | AV19: =MAX(0,MIN(1,(AG19-3)/7)) | AW19: =MAX(0,MIN(1,(AA19-0.25)/0.75)) | AX19: =MAX(0,MIN(1,(AM19-0.05)/0.2)) | AY19: =MAX(0,MIN(1,(AN19-0.7)/0.3)) | AZ19: =MAX(0,MIN(1,(AO19-1.2)/(0.6-1.2))) | BA19: =MAX(0,MIN(1,(ABS(Q19)-0.03)/(0-0.03))) | BB19: =MAX(0,MIN(1,T19/0.03)) | BC19: =MAX(0,MIN(1,(-X19-0.3)/(0.15-0.3))) | BD19: =0.5*IF(M19>N19,(J19-N19)/(M19-N19),0.5)+0.5*(J19>=P19) | BE19: =MAX(0,MIN(1,(AS19-0.9)/(0.5-0.9))) | BF19: =MAX(0,MIN(1,(AT19-0.7)/(0.3-0.7))) | BG19: =100*(0.4*AU19+0.3*AV19+0.3*AW19) | BH19: =100*(0.5*AX19+0.5*AY19) | BI19: =100*(0.3*AZ19+0.25*BA19+0.2*BB19+0.1*BC19+0.15*BD19) | BJ19: =100*(0.5*BE19+0.5*BF19) | BK19: =0.25*BG19+0.2*BH19+0.3*BI19+0.25*BJ19 | BL19: C1a 事件日：高位前 60 日最大量日只有 4.6× 50日均量（當日 +2.0%）；要 ≥3× 兼當日 ≥+8% 或開市跳空 ≥+5%；C3 回落20MA：高位喺 37 日前；C4 波幅減低：ATR5/ATR20 0.98（要 ≤0.9）；ATR5 係升浪期 ATR 嘅 0.70×（要 ≤0.7） | BO19: 回調唔係有序回落：期內有一日跌 -8.9%；最大升日 08-07 同業績日 08-05 差兩日，當日消息未查到；20 日成交額中位數只有 $2.8M（股票池下限 $1M），入市出市都會有滑價 | BP19: 0
A20: 2 | B20: =COUNTIFS($A$2:$A$23,A20,$BK$2:$BK$23,">"&BK20)+1 | C20: KN | D20: Knowles Corporation | E20: NYSE | F20: 必需消費 | G20: Consumer Electronics/Appliances | H20: 3.188 | I20: 中型 | J20: 37.15 | K20: 37.32 | L20: =J20/K20-1 | M20: 37.48 | N20: 36.95 | O20: 36.663 | P20: 35.981 | Q20: =J20/P20-1 | R20: 36.3362 | S20: 35.293 | T20: =P20/S20-1 | U20: 40.4 | V20: 2026-08-04 | W20: 40 | X20: =J20/U20-1 | Y20: 2026-05-04 | Z20: 63 | AA20: 0.26526777 | AB20: 0.10286089 | AC20: 0.02693088 | AD20: 2026-07-23 | AE20: 0.060092871 | AF20: -0.0081944824 | AG20: 2.1378234 | AH20: 1 | AI20: 42168177 | AJ20: 19798827 | AK20: =AI20/AJ20 | AL20: 2026-09-18 | AM20: 0.040201742 | AN20: 1 | AO20: 0.68670023 | AP20: 0.025729154 | AQ20: 0.029914381 | AR20: 0.047997873 | AS20: =AP20/AQ20 | AT20: =AP20/AR20 | AU20: =MAX(0,MIN(1,(AK20-2)/4)) | AV20: =MAX(0,MIN(1,(AG20-3)/7)) | AW20: =MAX(0,MIN(1,(AA20-0.25)/0.75)) | AX20: =MAX(0,MIN(1,(AM20-0.05)/0.2)) | AY20: =MAX(0,MIN(1,(AN20-0.7)/0.3)) | AZ20: =MAX(0,MIN(1,(AO20-1.2)/(0.6-1.2))) | BA20: =MAX(0,MIN(1,(ABS(Q20)-0.03)/(0-0.03))) | BB20: =MAX(0,MIN(1,T20/0.03)) | BC20: =MAX(0,MIN(1,(-X20-0.3)/(0.15-0.3))) | BD20: =0.5*IF(M20>N20,(J20-N20)/(M20-N20),0.5)+0.5*(J20>=P20) | BE20: =MAX(0,MIN(1,(AS20-0.9)/(0.5-0.9))) | BF20: =MAX(0,MIN(1,(AT20-0.7)/(0.3-0.7))) | BG20: =100*(0.4*AU20+0.3*AV20+0.3*AW20) | BH20: =100*(0.5*AX20+0.5*AY20) | BI20: =100*(0.3*AZ20+0.25*BA20+0.2*BB20+0.1*BC20+0.15*BD20) | BJ20: =100*(0.5*BE20+0.5*BF20) | BK20: =0.25*BG20+0.2*BH20+0.3*BI20+0.25*BJ20 | BL20: C1a 事件日：高位前 60 日最大量日只有 5.0× 50日均量（當日 -1.8%）；要 ≥3× 兼當日 ≥+8% 或開市跳空 ≥+5%；C2 曾有10MA上升：近 30 日 MA10 最大 10 日升幅 +4.0%（2026-09-18；要 ≥5%），嗰時最後三值遞升、10 步升 100%（要 ≥70%）；C3 回落20MA：高位喺 40 日前；收市距 MA20 +3.2%；近 3 日最低價距 MA20 +2.7% | BP20: 0
A21: 2 | B21: =COUNTIFS($A$2:$A$23,A21,$BK$2:$BK$23,">"&BK21)+1 | C21: FLXS | D21: Flexsteel Industries Inc. | E21: NASDAQ | F21: 非必需消費 | G21: Home Furnishings | H21: 0.353 | I21: 小型 | J21: 84.65 | K21: 86.36 | L21: =J21/K21-1 | M21: 86.6 | N21: 84.5 | O21: 84.598 | P21: 83.34 | Q21: =J21/P21-1 | R21: 79.6296 | S21: 81.7495 | T21: =P21/S21-1 | U21: 89.37 | V21: 2026-09-25 | W21: 3 | X21: =J21/U21-1 | Y21: 2026-07-07 | Z21: 57 | AA21: 0.28497484 | AB21: 0.084047986 | AC21: 0.013918886 | AD21: 2026-08-18 | AE21: 0.088907705 | AF21: 0.14309907 | AG21: 5.2738492 | AH21: 1 | AI21: 5980855.7 | AJ21: 3352539.8 | AK21: =AI21/AJ21 | AL21: 2026-09-02 | AM21: 0.076556742 | AN21: 1 | AO21: 0.74775381 | AP21: 0.036381543 | AQ21: 0.038905576 | AR21: 0.044172744 | AS21: =AP21/AQ21 | AT21: =AP21/AR21 | AU21: =MAX(0,MIN(1,(AK21-2)/4)) | AV21: =MAX(0,MIN(1,(AG21-3)/7)) | AW21: =MAX(0,MIN(1,(AA21-0.25)/0.75)) | AX21: =MAX(0,MIN(1,(AM21-0.05)/0.2)) | AY21: =MAX(0,MIN(1,(AN21-0.7)/0.3)) | AZ21: =MAX(0,MIN(1,(AO21-1.2)/(0.6-1.2))) | BA21: =MAX(0,MIN(1,(ABS(Q21)-0.03)/(0-0.03))) | BB21: =MAX(0,MIN(1,T21/0.03)) | BC21: =MAX(0,MIN(1,(-X21-0.3)/(0.15-0.3))) | BD21: =0.5*IF(M21>N21,(J21-N21)/(M21-N21),0.5)+0.5*(J21>=P21) | BE21: =MAX(0,MIN(1,(AS21-0.9)/(0.5-0.9))) | BF21: =MAX(0,MIN(1,(AT21-0.7)/(0.3-0.7))) | BG21: =100*(0.4*AU21+0.3*AV21+0.3*AW21) | BH21: =100*(0.5*AX21+0.5*AY21) | BI21: =100*(0.3*AZ21+0.25*BA21+0.2*BB21+0.1*BC21+0.15*BD21) | BJ21: =100*(0.5*BE21+0.5*BF21) | BK21: =0.25*BG21+0.2*BH21+0.3*BI21+0.25*BJ21 | BL21: C1b 熱錢：升浪成交額係之前 60 日嘅 1.78×（要 ≥2.0×）；C4 波幅減低：ATR5/ATR20 0.94（要 ≤0.9）；ATR5 係升浪期 ATR 嘅 0.82×（要 ≤0.7） | BP21: 0
A22: 2 | B22: =COUNTIFS($A$2:$A$23,A22,$BK$2:$BK$23,">"&BK22)+1 | C22: AVTR | D22: Avantor Inc. | E22: NYSE | F22: 工業 | G22: Biotechnology: Laboratory Analytical Instruments | H22: 10.308 | I22: 大型 | J22: 15.05 | K22: 15.24 | L22: =J22/K22-1 | M22: 15.36 | N22: 15.05 | O22: 15.239 | P22: 15.1615 | Q22: =J22/P22-1 | R22: 14.204 | S22: 14.9725 | T22: =P22/S22-1 | U22: 15.86 | V22: 2026-09-17 | W22: 9 | X22: =J22/U22-1 | Y22: 2026-06-22 | Z22: 61 | AA22: 0.69625668 | AB22: 0.069742345 | AC22: -0.0073541536 | AD22: 2026-07-29 | AE22: 0.15780998 | AF22: 0.16666667 | AG22: 4.2504246 | AH22: 1 | AI22: 1.1899838e+08 | AJ22: 78786085 | AK22: =AI22/AJ22 | AL22: 2026-09-02 | AM22: 0.058388278 | AN22: 1 | AO22: 1.2404345 | AP22: 0.027500511 | AQ22: 0.030909582 | AR22: 0.040457191 | AS22: =AP22/AQ22 | AT22: =AP22/AR22 | AU22: =MAX(0,MIN(1,(AK22-2)/4)) | AV22: =MAX(0,MIN(1,(AG22-3)/7)) | AW22: =MAX(0,MIN(1,(AA22-0.25)/0.75)) | AX22: =MAX(0,MIN(1,(AM22-0.05)/0.2)) | AY22: =MAX(0,MIN(1,(AN22-0.7)/0.3)) | AZ22: =MAX(0,MIN(1,(AO22-1.2)/(0.6-1.2))) | BA22: =MAX(0,MIN(1,(ABS(Q22)-0.03)/(0-0.03))) | BB22: =MAX(0,MIN(1,T22/0.03)) | BC22: =MAX(0,MIN(1,(-X22-0.3)/(0.15-0.3))) | BD22: =0.5*IF(M22>N22,(J22-N22)/(M22-N22),0.5)+0.5*(J22>=P22) | BE22: =MAX(0,MIN(1,(AS22-0.9)/(0.5-0.9))) | BF22: =MAX(0,MIN(1,(AT22-0.7)/(0.3-0.7))) | BG22: =100*(0.4*AU22+0.3*AV22+0.3*AW22) | BH22: =100*(0.5*AX22+0.5*AY22) | BI22: =100*(0.3*AZ22+0.25*BA22+0.2*BB22+0.1*BC22+0.15*BD22) | BJ22: =100*(0.5*BE22+0.5*BF22) | BK22: =0.25*BG22+0.2*BH22+0.3*BI22+0.25*BJ22 | BL22: C1b 熱錢：升浪成交額係之前 60 日嘅 1.51×（要 ≥2.0×）；C3 回落20MA：高位時只高過 MA20 7.0% | BP22: 0
A23: 2 | B23: =COUNTIFS($A$2:$A$23,A23,$BK$2:$BK$23,">"&BK23)+1 | C23: AMBA | D23: Ambarella Inc. | E23: NASDAQ | F23: 科技 | G23: Semiconductors | H23: 3.034 | I23: 中型 | J23: 69.51 | K23: 68.73 | L23: =J23/K23-1 | M23: 70.71 | N23: 67.87 | O23: 68.605 | P23: 66.9275 | Q23: =J23/P23-1 | R23: 72.119 | S23: 66.8865 | T23: =P23/S23-1 | U23: 86.78 | V23: 2026-08-07 | W23: 37 | X23: =J23/U23-1 | Y23: 2026-07-17 | Z23: 15 | AA23: 0.40329884 | AB23: 0.18285286 | AC23: 0.013411925 | AD23: 2026-06-30 | AE23: 0.28040591 | AF23: 0.013132368 | AG23: 5.2538128 | AH23: 3 | AI23: 1.7281846e+08 | AJ23: 1.1405107e+08 | AK23: =AI23/AJ23 | AL23: 2026-09-29 | AM23: 0.033076829 | AN23: 0.7 | AO23: 0.7331641 | AP23: 0.057323956 | AQ23: 0.064835143 | AR23: 0.084159036 | AS23: =AP23/AQ23 | AT23: =AP23/AR23 | AU23: =MAX(0,MIN(1,(AK23-2)/4)) | AV23: =MAX(0,MIN(1,(AG23-3)/7)) | AW23: =MAX(0,MIN(1,(AA23-0.25)/0.75)) | AX23: =MAX(0,MIN(1,(AM23-0.05)/0.2)) | AY23: =MAX(0,MIN(1,(AN23-0.7)/0.3)) | AZ23: =MAX(0,MIN(1,(AO23-1.2)/(0.6-1.2))) | BA23: =MAX(0,MIN(1,(ABS(Q23)-0.03)/(0-0.03))) | BB23: =MAX(0,MIN(1,T23/0.03)) | BC23: =MAX(0,MIN(1,(-X23-0.3)/(0.15-0.3))) | BD23: =0.5*IF(M23>N23,(J23-N23)/(M23-N23),0.5)+0.5*(J23>=P23) | BE23: =MAX(0,MIN(1,(AS23-0.9)/(0.5-0.9))) | BF23: =MAX(0,MIN(1,(AT23-0.7)/(0.3-0.7))) | BG23: =100*(0.4*AU23+0.3*AV23+0.3*AW23) | BH23: =100*(0.5*AX23+0.5*AY23) | BI23: =100*(0.3*AZ23+0.25*BA23+0.2*BB23+0.1*BC23+0.15*BD23) | BJ23: =100*(0.5*BE23+0.5*BF23) | BK23: =0.25*BG23+0.2*BH23+0.3*BI23+0.25*BJ23 | BL23: C1b 熱錢：升浪成交額係之前 60 日嘅 1.52×（要 ≥2.0×）；C2 曾有10MA上升：近 30 日 MA10 最大 10 日升幅 +10.7%（2026-08-18；要 ≥5%），嗰時最後三值唔遞升、10 步升 70%（要 ≥70%）；C3 回落20MA：高位喺 37 日前；收市距 MA20 +3.9% | BO23: 升浪由分析員推介（Rosenblatt 首選）帶動，唔係業績 | BP23: 0

Sheet 大型股
A1: 大型股（市值 ≥ $100 億）· 兩個梯隊 · 以綜合分數排序 · 2026-09-30 收市
A3: 梯隊 | B3: 頁內排名 | C3: 總表排名 | D3: 代號 | E3: 公司 | F3: 板塊 | G3: 收市價 | H3: 距MA20% | I3: 距高位% | J3: 事件日 | K3: 事件日升幅 | L3: 事件日量比 | M3: 升浪成交額比 | N3: MA10 10日升幅 | O3: ATR5/ATR20 | P3: ATR5/升浪ATR | Q3: 熱錢分數 | R3: 10MA分數 | S3: 回調質素 | T3: 波幅收窄 | U3: 綜合分數 | V3: 唔過嘅條件（梯隊2） | W3: 審視標記
A4: ='總表'!A22 | B4: =COUNTIFS($A$4:$A$4,A4,$U$4:$U$4,">"&U4)+1 | C4: ='總表'!B22 | D4: AVTR | E4: ='總表'!D22 | F4: ='總表'!F22 | G4: ='總表'!J22 | H4: ='總表'!Q22 | I4: ='總表'!X22 | J4: ='總表'!AD22 | K4: ='總表'!AE22 | L4: ='總表'!AG22 | M4: ='總表'!AK22 | N4: ='總表'!AM22 | O4: ='總表'!AS22 | P4: ='總表'!AT22 | Q4: ='總表'!BG22 | R4: ='總表'!BH22 | S4: ='總表'!BI22 | T4: ='總表'!BJ22 | U4: ='總表'!BK22 | V4: ='總表'!BL22 | W4: ='總表'!BO22

Sheet 中型股
A1: 中型股（市值 $20–100 億）· 兩個梯隊 · 以綜合分數排序 · 2026-09-30 收市
A3: 梯隊 | B3: 頁內排名 | C3: 總表排名 | D3: 代號 | E3: 公司 | F3: 板塊 | G3: 收市價 | H3: 距MA20% | I3: 距高位% | J3: 事件日 | K3: 事件日升幅 | L3: 事件日量比 | M3: 升浪成交額比 | N3: MA10 10日升幅 | O3: ATR5/ATR20 | P3: ATR5/升浪ATR | Q3: 熱錢分數 | R3: 10MA分數 | S3: 回調質素 | T3: 波幅收窄 | U3: 綜合分數 | V3: 唔過嘅條件（梯隊2） | W3: 審視標記
A4: ='總表'!A8 | B4: =COUNTIFS($A$4:$A$11,A4,$U$4:$U$11,">"&U4)+1 | C4: ='總表'!B8 | D4: HAE | E4: ='總表'!D8 | F4: ='總表'!F8 | G4: ='總表'!J8 | H4: ='總表'!Q8 | I4: ='總表'!X8 | J4: ='總表'!AD8 | K4: ='總表'!AE8 | L4: ='總表'!AG8 | M4: ='總表'!AK8 | N4: ='總表'!AM8 | O4: ='總表'!AS8 | P4: ='總表'!AT8 | Q4: ='總表'!BG8 | R4: ='總表'!BH8 | S4: ='總表'!BI8 | T4: ='總表'!BJ8 | U4: ='總表'!BK8 | V4: ='總表'!BL8 | W4: ='總表'!BO8
A5: ='總表'!A9 | B5: =COUNTIFS($A$4:$A$11,A5,$U$4:$U$11,">"&U5)+1 | C5: ='總表'!B9 | D5: ASST | E5: ='總表'!D9 | F5: ='總表'!F9 | G5: ='總表'!J9 | H5: ='總表'!Q9 | I5: ='總表'!X9 | J5: ='總表'!AD9 | K5: ='總表'!AE9 | L5: ='總表'!AG9 | M5: ='總表'!AK9 | N5: ='總表'!AM9 | O5: ='總表'!AS9 | P5: ='總表'!AT9 | Q5: ='總表'!BG9 | R5: ='總表'!BH9 | S5: ='總表'!BI9 | T5: ='總表'!BJ9 | U5: ='總表'!BK9 | V5: ='總表'!BL9 | W5: ='總表'!BO9
A6: ='總表'!A12 | B6: =COUNTIFS($A$4:$A$11,A6,$U$4:$U$11,">"&U6)+1 | C6: ='總表'!B12 | D6: PURR | E6: ='總表'!D12 | F6: ='總表'!F12 | G6: ='總表'!J12 | H6: ='總表'!Q12 | I6: ='總表'!X12 | J6: ='總表'!AD12 | K6: ='總表'!AE12 | L6: ='總表'!AG12 | M6: ='總表'!AK12 | N6: ='總表'!AM12 | O6: ='總表'!AS12 | P6: ='總表'!AT12 | Q6: ='總表'!BG12 | R6: ='總表'!BH12 | S6: ='總表'!BI12 | T6: ='總表'!BJ12 | U6: ='總表'!BK12 | V6: ='總表'!BL12 | W6: ='總表'!BO12
A7: ='總表'!A14 | B7: =COUNTIFS($A$4:$A$11,A7,$U$4:$U$11,">"&U7)+1 | C7: ='總表'!B14 | D7: RNG | E7: ='總表'!D14 | F7: ='總表'!F14 | G7: ='總表'!J14 | H7: ='總表'!Q14 | I7: ='總表'!X14 | J7: ='總表'!AD14 | K7: ='總表'!AE14 | L7: ='總表'!AG14 | M7: ='總表'!AK14 | N7: ='總表'!AM14 | O7: ='總表'!AS14 | P7: ='總表'!AT14 | Q7: ='總表'!BG14 | R7: ='總表'!BH14 | S7: ='總表'!BI14 | T7: ='總表'!BJ14 | U7: ='總表'!BK14 | V7: ='總表'!BL14 | W7: ='總表'!BO14
A8: ='總表'!A15 | B8: =COUNTIFS($A$4:$A$11,A8,$U$4:$U$11,">"&U8)+1 | C8: ='總表'!B15 | D8: ASO | E8: ='總表'!D15 | F8: ='總表'!F15 | G8: ='總表'!J15 | H8: ='總表'!Q15 | I8: ='總表'!X15 | J8: ='總表'!AD15 | K8: ='總表'!AE15 | L8: ='總表'!AG15 | M8: ='總表'!AK15 | N8: ='總表'!AM15 | O8: ='總表'!AS15 | P8: ='總表'!AT15 | Q8: ='總表'!BG15 | R8: ='總表'!BH15 | S8: ='總表'!BI15 | T8: ='總表'!BJ15 | U8: ='總表'!BK15 | V8: ='總表'!BL15 | W8: ='總表'!BO15
A9: ='總表'!A17 | B9: =COUNTIFS($A$4:$A$11,A9,$U$4:$U$11,">"&U9)+1 | C9: ='總表'!B17 | D9: PLSE | E9: ='總表'!D17 | F9: ='總表'!F17 | G9: ='總表'!J17 | H9: ='總表'!Q17 | I9: ='總表'!X17 | J9: ='總表'!AD17 | K9: ='總表'!AE17 | L9: ='總表'!AG17 | M9: ='總表'!AK17 | N9: ='總表'!AM17 | O9: ='總表'!AS17 | P9: ='總表'!AT17 | Q9: ='總表'!BG17 | R9: ='總表'!BH17 | S9: ='總表'!BI17 | T9: ='總表'!BJ17 | U9: ='總表'!BK17 | V9: ='總表'!BL17 | W9: ='總表'!BO17
A10: ='總表'!A20 | B10: =COUNTIFS($A$4:$A$11,A10,$U$4:$U$11,">"&U10)+1 | C10: ='總表'!B20 | D10: KN | E10: ='總表'!D20 | F10: ='總表'!F20 | G10: ='總表'!J20 | H10: ='總表'!Q20 | I10: ='總表'!X20 | J10: ='總表'!AD20 | K10: ='總表'!AE20 | L10: ='總表'!AG20 | M10: ='總表'!AK20 | N10: ='總表'!AM20 | O10: ='總表'!AS20 | P10: ='總表'!AT20 | Q10: ='總表'!BG20 | R10: ='總表'!BH20 | S10: ='總表'!BI20 | T10: ='總表'!BJ20 | U10: ='總表'!BK20 | V10: ='總表'!BL20 | W10: ='總表'!BO20
A11: ='總表'!A23 | B11: =COUNTIFS($A$4:$A$11,A11,$U$4:$U$11,">"&U11)+1 | C11: ='總表'!B23 | D11: AMBA | E11: ='總表'!D23 | F11: ='總表'!F23 | G11: ='總表'!J23 | H11: ='總表'!Q23 | I11: ='總表'!X23 | J11: ='總表'!AD23 | K11: ='總表'!AE23 | L11: ='總表'!AG23 | M11: ='總表'!AK23 | N11: ='總表'!AM23 | O11: ='總表'!AS23 | P11: ='總表'!AT23 | Q11: ='總表'!BG23 | R11: ='總表'!BH23 | S11: ='總表'!BI23 | T11: ='總表'!BJ23 | U11: ='總表'!BK23 | V11: ='總表'!BL23 | W11: ='總表'!BO23

Sheet 小型股
A1: 小型股（市值 < $20 億）· 兩個梯隊 · 以綜合分數排序 · 2026-09-30 收市
A3: 梯隊 | B3: 頁內排名 | C3: 總表排名 | D3: 代號 | E3: 公司 | F3: 板塊 | G3: 收市價 | H3: 距MA20% | I3: 距高位% | J3: 事件日 | K3: 事件日升幅 | L3: 事件日量比 | M3: 升浪成交額比 | N3: MA10 10日升幅 | O3: ATR5/ATR20 | P3: ATR5/升浪ATR | Q3: 熱錢分數 | R3: 10MA分數 | S3: 回調質素 | T3: 波幅收窄 | U3: 綜合分數 | V3: 唔過嘅條件（梯隊2） | W3: 審視標記
A4: ='總表'!A2 | B4: =COUNTIFS($A$4:$A$16,A4,$U$4:$U$16,">"&U4)+1 | C4: ='總表'!B2 | D4: RLGT | E4: ='總表'!D2 | F4: ='總表'!F2 | G4: ='總表'!J2 | H4: ='總表'!Q2 | I4: ='總表'!X2 | J4: ='總表'!AD2 | K4: ='總表'!AE2 | L4: ='總表'!AG2 | M4: ='總表'!AK2 | N4: ='總表'!AM2 | O4: ='總表'!AS2 | P4: ='總表'!AT2 | Q4: ='總表'!BG2 | R4: ='總表'!BH2 | S4: ='總表'!BI2 | T4: ='總表'!BJ2 | U4: ='總表'!BK2 | V4: ='總表'!BL2 | W4: ='總表'!BO2
A5: ='總表'!A3 | B5: =COUNTIFS($A$4:$A$16,A5,$U$4:$U$16,">"&U5)+1 | C5: ='總表'!B3 | D5: CSR | E5: ='總表'!D3 | F5: ='總表'!F3 | G5: ='總表'!J3 | H5: ='總表'!Q3 | I5: ='總表'!X3 | J5: ='總表'!AD3 | K5: ='總表'!AE3 | L5: ='總表'!AG3 | M5: ='總表'!AK3 | N5: ='總表'!AM3 | O5: ='總表'!AS3 | P5: ='總表'!AT3 | Q5: ='總表'!BG3 | R5: ='總表'!BH3 | S5: ='總表'!BI3 | T5: ='總表'!BJ3 | U5: ='總表'!BK3 | V5: ='總表'!BL3 | W5: ='總表'!BO3
A6: ='總表'!A4 | B6: =COUNTIFS($A$4:$A$16,A6,$U$4:$U$16,">"&U6)+1 | C6: ='總表'!B4 | D6: BSVN | E6: ='總表'!D4 | F6: ='總表'!F4 | G6: ='總表'!J4 | H6: ='總表'!Q4 | I6: ='總表'!X4 | J6: ='總表'!AD4 | K6: ='總表'!AE4 | L6: ='總表'!AG4 | M6: ='總表'!AK4 | N6: ='總表'!AM4 | O6: ='總表'!AS4 | P6: ='總表'!AT4 | Q6: ='總表'!BG4 | R6: ='總表'!BH4 | S6: ='總表'!BI4 | T6: ='總表'!BJ4 | U6: ='總表'!BK4 | V6: ='總表'!BL4 | W6: ='總表'!BO4
A7: ='總表'!A5 | B7: =COUNTIFS($A$4:$A$16,A7,$U$4:$U$16,">"&U7)+1 | C7: ='總表'!B5 | D7: CRSR | E7: ='總表'!D5 | F7: ='總表'!F5 | G7: ='總表'!J5 | H7: ='總表'!Q5 | I7: ='總表'!X5 | J7: ='總表'!AD5 | K7: ='總表'!AE5 | L7: ='總表'!AG5 | M7: ='總表'!AK5 | N7: ='總表'!AM5 | O7: ='總表'!AS5 | P7: ='總表'!AT5 | Q7: ='總表'!BG5 | R7: ='總表'!BH5 | S7: ='總表'!BI5 | T7: ='總表'!BJ5 | U7: ='總表'!BK5 | V7: ='總表'!BL5 | W7: ='總表'!BO5
A8: ='總表'!A6 | B8: =COUNTIFS($A$4:$A$16,A8,$U$4:$U$16,">"&U8)+1 | C8: ='總表'!B6 | D8: CMRC | E8: ='總表'!D6 | F8: ='總表'!F6 | G8: ='總表'!J6 | H8: ='總表'!Q6 | I8: ='總表'!X6 | J8: ='總表'!AD6 | K8: ='總表'!AE6 | L8: ='總表'!AG6 | M8: ='總表'!AK6 | N8: ='總表'!AM6 | O8: ='總表'!AS6 | P8: ='總表'!AT6 | Q8: ='總表'!BG6 | R8: ='總表'!BH6 | S8: ='總表'!BI6 | T8: ='總表'!BJ6 | U8: ='總表'!BK6 | V8: ='總表'!BL6 | W8: ='總表'!BO6
A9: ='總表'!A7 | B9: =COUNTIFS($A$4:$A$16,A9,$U$4:$U$16,">"&U9)+1 | C9: ='總表'!B7 | D9: OMER | E9: ='總表'!D7 | F9: ='總表'!F7 | G9: ='總表'!J7 | H9: ='總表'!Q7 | I9: ='總表'!X7 | J9: ='總表'!AD7 | K9: ='總表'!AE7 | L9: ='總表'!AG7 | M9: ='總表'!AK7 | N9: ='總表'!AM7 | O9: ='總表'!AS7 | P9: ='總表'!AT7 | Q9: ='總表'!BG7 | R9: ='總表'!BH7 | S9: ='總表'!BI7 | T9: ='總表'!BJ7 | U9: ='總表'!BK7 | V9: ='總表'!BL7 | W9: ='總表'!BO7
A10: ='總表'!A10 | B10: =COUNTIFS($A$4:$A$16,A10,$U$4:$U$16,">"&U10)+1 | C10: ='總表'!B10 | D10: GEMI | E10: ='總表'!D10 | F10: ='總表'!F10 | G10: ='總表'!J10 | H10: ='總表'!Q10 | I10: ='總表'!X10 | J10: ='總表'!AD10 | K10: ='總表'!AE10 | L10: ='總表'!AG10 | M10: ='總表'!AK10 | N10: ='總表'!AM10 | O10: ='總表'!AS10 | P10: ='總表'!AT10 | Q10: ='總表'!BG10 | R10: ='總表'!BH10 | S10: ='總表'!BI10 | T10: ='總表'!BJ10 | U10: ='總表'!BK10 | V10: ='總表'!BL10 | W10: ='總表'!BO10
A11: ='總表'!A11 | B11: =COUNTIFS($A$4:$A$16,A11,$U$4:$U$16,">"&U11)+1 | C11: ='總表'!B11 | D11: UMAC | E11: ='總表'!D11 | F11: ='總表'!F11 | G11: ='總表'!J11 | H11: ='總表'!Q11 | I11: ='總表'!X11 | J11: ='總表'!AD11 | K11: ='總表'!AE11 | L11: ='總表'!AG11 | M11: ='總表'!AK11 | N11: ='總表'!AM11 | O11: ='總表'!AS11 | P11: ='總表'!AT11 | Q11: ='總表'!BG11 | R11: ='總表'!BH11 | S11: ='總表'!BI11 | T11: ='總表'!BJ11 | U11: ='總表'!BK11 | V11: ='總表'!BL11 | W11: ='總表'!BO11
A12: ='總表'!A13 | B12: =COUNTIFS($A$4:$A$16,A12,$U$4:$U$16,">"&U12)+1 | C12: ='總表'!B13 | D12: UTMD | E12: ='總表'!D13 | F12: ='總表'!F13 | G12: ='總表'!J13 | H12: ='總表'!Q13 | I12: ='總表'!X13 | J12: ='總表'!AD13 | K12: ='總表'!AE13 | L12: ='總表'!AG13 | M12: ='總表'!AK13 | N12: ='總表'!AM13 | O12: ='總表'!AS13 | P12: ='總表'!AT13 | Q12: ='總表'!BG13 | R12: ='總表'!BH13 | S12: ='總表'!BI13 | T12: ='總表'!BJ13 | U12: ='總表'!BK13 | V12: ='總表'!BL13 | W12: ='總表'!BO13
A13: ='總表'!A16 | B13: =COUNTIFS($A$4:$A$16,A13,$U$4:$U$16,">"&U13)+1 | C13: ='總表'!B16 | D13: BVS | E13: ='總表'!D16 | F13: ='總表'!F16 | G13: ='總表'!J16 | H13: ='總表'!Q16 | I13: ='總表'!X16 | J13: ='總表'!AD16 | K13: ='總表'!AE16 | L13: ='總表'!AG16 | M13: ='總表'!AK16 | N13: ='總表'!AM16 | O13: ='總表'!AS16 | P13: ='總表'!AT16 | Q13: ='總表'!BG16 | R13: ='總表'!BH16 | S13: ='總表'!BI16 | T13: ='總表'!BJ16 | U13: ='總表'!BK16 | V13: ='總表'!BL16 | W13: ='總表'!BO16
A14: ='總表'!A18 | B14: =COUNTIFS($A$4:$A$16,A14,$U$4:$U$16,">"&U14)+1 | C14: ='總表'!B18 | D14: BBNX | E14: ='總表'!D18 | F14: ='總表'!F18 | G14: ='總表'!J18 | H14: ='總表'!Q18 | I14: ='總表'!X18 | J14: ='總表'!AD18 | K14: ='總表'!AE18 | L14: ='總表'!AG18 | M14: ='總表'!AK18 | N14: ='總表'!AM18 | O14: ='總表'!AS18 | P14: ='總表'!AT18 | Q14: ='總表'!BG18 | R14: ='總表'!BH18 | S14: ='總表'!BI18 | T14: ='總表'!BJ18 | U14: ='總表'!BK18 | V14: ='總表'!BL18 | W14: ='總表'!BO18
A15: ='總表'!A19 | B15: =COUNTIFS($A$4:$A$16,A15,$U$4:$U$16,">"&U15)+1 | C15: ='總表'!B19 | D15: PKOH | E15: ='總表'!D19 | F15: ='總表'!F19 | G15: ='總表'!J19 | H15: ='總表'!Q19 | I15: ='總表'!X19 | J15: ='總表'!AD19 | K15: ='總表'!AE19 | L15: ='總表'!AG19 | M15: ='總表'!AK19 | N15: ='總表'!AM19 | O15: ='總表'!AS19 | P15: ='總表'!AT19 | Q15: ='總表'!BG19 | R15: ='總表'!BH19 | S15: ='總表'!BI19 | T15: ='總表'!BJ19 | U15: ='總表'!BK19 | V15: ='總表'!BL19 | W15: ='總表'!BO19
A16: ='總表'!A21 | B16: =COUNTIFS($A$4:$A$16,A16,$U$4:$U$16,">"&U16)+1 | C16: ='總表'!B21 | D16: FLXS | E16: ='總表'!D21 | F16: ='總表'!F21 | G16: ='總表'!J21 | H16: ='總表'!Q21 | I16: ='總表'!X21 | J16: ='總表'!AD21 | K16: ='總表'!AE21 | L16: ='總表'!AG21 | M16: ='總表'!AK21 | N16: ='總表'!AM21 | O16: ='總表'!AS21 | P16: ='總表'!AT21 | Q16: ='總表'!BG21 | R16: ='總表'!BH21 | S16: ='總表'!BI21 | T16: ='總表'!BJ21 | U16: ='總表'!BK21 | V16: ='總表'!BL21 | W16: ='總表'!BO21

Sheet 篩選規則
A1: R23.00 篩選條件：有熱錢及消息驅動 ＋ 曾有 10MA 上升 ＋ 回落到 20MA ＋ 波幅減低
A3: 說明 | B3: 由 R23.00 起取代 R21–R22 嘅「回報排頭 10% 動能」條件。股票池、價格來源（Yahoo 日線、Nasdaq 快照核對）不變；H = 近 63 日最高收市，升浪 = 由 H 前 63 日內最低收市升到 H。數據終點 2026-09-30，254 個交易日（2025-09-26 起）。 | C3: 門檻 | D3: 通過數目
A4: 股票池 | B4: 當日有成交、≥90 個交易日歷史（按 Nasdaq 上市日計，SPAC 空殼期唔計）、收市 ≥$2、普通股、20 日成交額中位數 ≥$1M | C4: 同 R1–R22 | D4: 2762
A5: C1a 事件日（消息驅動） | B5: 高位前 60 日內（唔計高位之後）有一日：收市對收市 ≥+8%，或開市比前收跳空 ≥+5%；而且當日成交量 ≥3× 之前 50 日平均。幾日都合格就取量比最大嗰日做「事件日」 | C5: 單獨 658 | D5: 658
A6: C1b 熱錢 | B6: 升浪期（至少高位前 5 日）日均成交額 ≥ 升浪開始前 60 日日均嘅 2 倍 | C6: 單獨 277 | D6: 203
A7: C2 曾有 10MA 上升 | B7: 近 30 日內（唔計今日）有一日通過 R1–R20 嘅 10MA 測試：MA10 比 10 日前高 ≥5%、最後三個 MA10 值遞升、10 步入面升 ≥70%。幾日都合格取升幅最大嗰日 | C7: 單獨 1,231 | D7: 140
A8: C3 回落到 20MA | B8: MA20 高過 5 日前；H 喺 2–25 日前；收市比 H 低 3%–30%；H 當日收市高過當日 MA20 ≥8%；收市喺 MA20 -3% 至 +3%；近 3 日有一日最低價 ≤ MA20×1.015 | C8: 單獨 54 | D8: 6
A9: C4 波幅減低 | B9: 近 5 日平均真實波幅（佔前收 %）≤ 0.9× 近 20 日平均，而且 ≤ 0.7× 升浪期平均。真實波幅只計有高低位嘅日子 | C9: 單獨 722 | D9: 3
A10: 第二梯隊 | B10: 每個門檻放寬一級（事件日 +6%／跳空 +5%／2× 量；熱錢 1.5×；MA10 升 3%、6 步；高位 40 日內；回調 ≤40%；高位時高過 MA20 6%；收市 ±5%、觸及 3%；ATR5/ATR20 ≤1.0、對升浪 ≤0.85）先合格嘅股票；總表「唔過嘅條件」欄列明每隻差邊項 | D10: 19
A12: 評分（每項 0–1，線性、兩頭封頂）
A13: 熱錢分數 | B13: 0.4 × 升浪成交額比（2×→0、6×→1）+ 0.3 × 事件日量比（3×→0、10×→1）+ 0.3 × 升浪幅度（25%→0、100%→1）
A14: 10MA分數 | B14: 0.5 × MA10 10 日升幅（5%→0、25%→1）+ 0.5 × MA10 上升步比例（70%→0、100%→1）
A15: 回調質素 | B15: 0.30 量縮（高位後日均量 ÷ 高位前 20 日：1.2→0、0.6→1）+ 0.25 貼近 MA20（|距 MA20|：3%→0、0%→1）+ 0.20 MA20 斜率（0→0、3%→1）+ 0.10 回調深度（30%→0、15%→1）+ 0.15 企穩（0.5 × 收市喺當日高低區間位置 + 0.5 × 收市 ≥ MA20）
A16: 波幅收窄 | B16: 0.5 × ATR5/ATR20（0.9→0、0.5→1）+ 0.5 × ATR5/升浪 ATR（0.7→0、0.3→1）
A17: 綜合分數 | B17: 0.25 × 熱錢 + 0.2 × 10MA + 0.3 × 回調質素 + 0.25 × 波幅收窄（每頁排名用；先分梯隊）
A18: 欄位顏色 | B18: 藍字 = 量度值（輸入）；黑字 = 公式；灰底 = 第二梯隊；橙底 = 有審視標記；黃底公司名 = 上版冇
A20: 同上一套條件嘅分別 | B20: R21–R22：1／2／3／6 個月回報排全體頭 10% ＋ 回到上升中嘅 20MA —— 捉慢慢升上去嘅強勢股。R23.00：先要有一日放量大升嘅消息日、升浪期成交額係之前兩倍（熱錢）、而且試過通過舊嘅 10MA 上升測試，再回落到 20MA 兼波幅收窄。兩套條件捉嘅股票本身唔同（見「同R22對照」頁）。

Sheet 敏感度
A1: 每次只郁一個門檻，睇第一梯隊點變（基準 = 本版門檻）；最後兩行係全部門檻同時放寬／收緊一級
A3: 門檻 | B3: 基準 | C3: 改為 | D3: 名單數目 | E3: 變動 | F3: 新增／剔走嘅代號 →
A4: 事件日升幅 | B4: 0.08 | C4: 0.06 | D4: 3 | E4: +0 / −0
A5: 事件日升幅 | B5: 0.08 | C5: 0.1 | D5: 2 | E5: +0 / −1 | F5: BSVN
A6: 事件日量比 | B6: 3 | C6: 2 | D6: 3 | E6: +0 / −0
A7: 事件日量比 | B7: 3 | C7: 4 | D7: 2 | E7: +0 / −1 | F7: BSVN
A8: 升浪成交額比 | B8: 2 | C8: 1.5 | D8: 6 | E8: +3 / −0 | F8: ASO | G8: CMRC | H8: OMER
A9: 升浪成交額比 | B9: 2 | C9: 3 | D9: 3 | E9: +0 / −0
A10: MA10 10日升幅 | B10: 0.05 | C10: 0.03 | D10: 3 | E10: +0 / −0
A11: MA10 10日升幅 | B11: 0.05 | C11: 0.08 | D11: 1 | E11: +0 / −2 | F11: BSVN | G11: RLGT
A12: MA10上升步比例 | B12: 0.7 | C12: 0.6 | D12: 3 | E12: +0 / −0
A13: MA10上升步比例 | B13: 0.7 | C13: 0.8 | D13: 3 | E13: +0 / −0
A14: 高位時高過MA20 | B14: 0.08 | C14: 0.06 | D14: 3 | E14: +0 / −0
A15: 高位時高過MA20 | B15: 0.08 | C15: 0.1 | D15: 2 | E15: +0 / −1 | F15: CSR
A16: 最深回調 | B16: 0.3 | C16: 0.25 | D16: 3 | E16: +0 / −0
A17: 最深回調 | B17: 0.3 | C17: 0.4 | D17: 3 | E17: +0 / −0
A18: 距MA20下限 | B18: -0.03 | C18: -0.02 | D18: 2 | E18: +0 / −1 | F18: CSR
A19: 距MA20下限 | B19: -0.03 | C19: -0.05 | D19: 3 | E19: +0 / −0
A20: 距MA20上限 | B20: 0.03 | C20: 0.02 | D20: 3 | E20: +0 / −0
A21: 距MA20上限 | B21: 0.03 | C21: 0.05 | D21: 3 | E21: +0 / −0
A22: 觸及容差 | B22: 0.015 | C22: 0 | D22: 3 | E22: +0 / −0
A23: 觸及容差 | B23: 0.015 | C23: 0.03 | D23: 3 | E23: +0 / −0
A24: ATR5/ATR20上限 | B24: 0.9 | C24: 0.8 | D24: 3 | E24: +0 / −0
A25: ATR5/ATR20上限 | B25: 0.9 | C25: 1 | D25: 3 | E25: +0 / −0
A26: ATR5/升浪ATR上限 | B26: 0.7 | C26: 0.6 | D26: 2 | E26: +0 / −1 | F26: BSVN
A27: ATR5/升浪ATR上限 | B27: 0.7 | C27: 0.85 | D27: 4 | E27: +1 / −0 | F27: PURR
A28: 高位最遠日數 | B28: 25 | C28: 20 | D28: 3 | E28: +0 / −0
A29: 高位最遠日數 | B29: 25 | C29: 40 | D29: 3 | E29: +0 / −0
A30: 全部放寬一級 | D30: 22 | E30: +19 / −0 | F30: AMBA | G30: ASO | H30: ASST | I30: AVTR | J30: BBNX | K30: BVS | L30: CMRC | M30: CRSR | N30: FLXS | O30: GEMI | P30: HAE | Q30: KN | R30: OMER | S30: PKOH | T30: PLSE | U30: PURR | V30: RNG | W30: UMAC | X30: UTMD
A31: 全部收緊一級 | D31: 0 | E31: +0 / −3 | F31: BSVN | G31: CSR | H31: RLGT
A33: 黃底 = 放寬後新增；橙底 = 收緊後剔走

Sheet 差一項
A1: 五項條件只差一項嘅股票（基準門檻）
A3: 代號 | B3: 唔通過嘅一項 | C3: 收市價 | D3: 距MA20% | E3: 距高位% | F3: 高位至今 | G3: 說明
A4: ASO | B4: C1b 熱錢 | C4: 48.09 | D4: -0.017463569 | E4: -0.13132225 | F4: 13 | G4: 升浪成交額係之前 60 日嘅 1.57×（要 ≥2.0×）
A5: CMRC | B5: C1b 熱錢 | C5: 3.16 | D5: 0.011523688 | E5: -0.13186813 | F5: 12 | G5: 升浪成交額係之前 60 日嘅 1.73×（要 ≥2.0×）
A6: DELL | B6: C1b 熱錢 | C6: 537.95 | D6: -0.0099611217 | E6: -0.085740993 | F6: 9 | G6: 升浪成交額係之前 60 日嘅 1.18×（要 ≥2.0×）
A7: GTLB | B7: C1b 熱錢 | C7: 47.25 | D7: -0.022118743 | E7: -0.060075592 | F7: 9 | G7: 升浪成交額係之前 60 日嘅 1.17×（要 ≥2.0×）
A8: OMER | B8: C1b 熱錢 | C8: 19.04 | D8: 0.005279831 | E8: -0.095486936 | F8: 6 | G8: 升浪成交額係之前 60 日嘅 1.54×（要 ≥2.0×）
A9: ACVA | B9: C3 回落20MA | C9: 10.43 | D9: 0.10774786 | E9: -0.0047709924 | F9: 7 | G9: 距高位 -0.5%；收市距 MA20 +10.8%；近 3 日最低價距 MA20 +10.8%
A10: AIP | B10: C3 回落20MA | C10: 23.64 | D10: 0.047942017 | E10: -0.3453337 | F10: 58 | G10: 高位喺 58 日前；距高位 -34.5%；高位時只高過 MA20 -10.7%；收市距 MA20 +4.8%
A11: ALAB | B11: C3 回落20MA | C11: 355.97 | D11: 0.13674503 | E11: -0.17740445 | F11: 61 | G11: 高位喺 61 日前；收市距 MA20 +13.7%；近 3 日最低價距 MA20 +9.7%
A12: AMLX | B12: C3 回落20MA | C12: 29.1 | D12: -0.093690874 | E12: -0.26626324 | F12: 28 | G12: MA20 唔係向上；高位喺 28 日前；收市距 MA20 -9.4%
A13: AMWL | B13: C3 回落20MA | C13: 13.58 | D13: 0.022397892 | E13: -0.020908435 | F13: 12 | G13: 距高位 -2.1%
A14: ANIX | B14: C3 回落20MA | C14: 2.93 | D14: 0.037535411 | E14: -0.21866667 | F14: 48 | G14: MA20 唔係向上；高位喺 48 日前；收市距 MA20 +3.8%
A15: AOUT | B15: C3 回落20MA | C15: 16.2 | D15: 0.051879748 | E15: -0.076923077 | F15: 3 | G15: 收市距 MA20 +5.2%；近 3 日最低價距 MA20 +3.5%
... A66: PURR | B66: C4 波幅減低 | C66: 12.27 | D66: -0.014101482 | E66: -0.12916962 | F66: 4 | G66: ATR5/ATR20 0.80（要 ≤0.9）；ATR5 係升浪期 ATR 嘅 0.76×（要 ≤0.7）

Sheet 20MA回調池
A1: 而家處於「上升中 20MA 回調位」（通過 C3）嘅全部股票，同佢哋差邊項
A3: 梯隊 | B3: 代號 | C3: 收市價 | D3: 距MA20% | E3: 距高位% | F3: 升浪成交額比 | G3: 事件日量比 | H3: ATR5/ATR20 | I3: ATR5/升浪ATR | J3: 唔過嘅條件 | K3: 說明
A4: 1 | B4: BSVN | C4: 54.53 | D4: -0.004 | E4: -0.0505 | F4: 3.43 | G4: 3.09 | H4: 0.647 | I4: 0.625 | J4: 全部通過
A5: 1 | B5: CSR | C5: 54.4 | D5: -0.0219 | E5: -0.072 | F5: 3.01 | G5: 15.22 | H5: 0.71 | I5: 0.505 | J5: 全部通過
A6: 1 | B6: RLGT | C6: 8.69 | D6: 0.0105 | E6: -0.1142 | F6: 6.8 | G6: 23.13 | H6: 0.534 | I6: 0.322 | J6: 全部通過
A7: 2 | B7: ASO | C7: 48.09 | D7: -0.0175 | E7: -0.1313 | F7: 1.57 | G7: 3.98 | H7: 0.657 | I7: 0.589 | J7: C1b 熱錢 | K7: C1b 熱錢：升浪成交額係之前 60 日嘅 1.57×（要 ≥2.0×）
A8: 2 | B8: CMRC | C8: 3.16 | D8: 0.0115 | E8: -0.1319 | F8: 1.73 | G8: 4.4 | H8: 0.641 | I8: 0.515 | J8: C1b 熱錢 | K8: C1b 熱錢：升浪成交額係之前 60 日嘅 1.73×（要 ≥2.0×）
A9: 2 | B9: OMER | C9: 19.04 | D9: 0.0053 | E9: -0.0955 | F9: 1.54 | G9: 7.07 | H9: 0.751 | I9: 0.559 | J9: C1b 熱錢 | K9: C1b 熱錢：升浪成交額係之前 60 日嘅 1.54×（要 ≥2.0×）
A10: 2 | B10: PURR | C10: 12.27 | D10: -0.0141 | E10: -0.1292 | F10: 2.01 | G10: 5.66 | H10: 0.801 | I10: 0.757 | J10: C4 波幅減低 | K10: C4 波幅減低：ATR5/ATR20 0.80（要 ≤0.9）；ATR5 係升浪期 ATR 嘅 0.76×（要 ≤0.7）
A11: 2 | B11: FLXS | C11: 84.65 | D11: 0.0157 | E11: -0.0528 | F11: 1.78 | G11: 5.27 | H11: 0.935 | I11: 0.824 | J11: C1b 熱錢、C4 波幅減低 | K11: C1b 熱錢：升浪成交額係之前 60 日嘅 1.78×（要 ≥2.0×）；C4 波幅減低：ATR5/ATR20 0.94（要 ≤0.9）；ATR5 係升浪期 ATR 嘅 0.82×（要 ≤0.7）
A12: 2 | B12: RNG | C12: 74.7 | D12: 0.0077 | E12: -0.0641 | F12: 1.58 | G12: 5.35 | H12: 0.864 | I12: 0.737 | J12: C1b 熱錢、C4 波幅減低 | K12: C1b 熱錢：升浪成交額係之前 60 日嘅 1.58×（要 ≥2.0×）；C4 波幅減低：ATR5/ATR20 0.86（要 ≤0.9）；ATR5 係升浪期 ATR 嘅 0.74×（要 ≤0.7）
B13: DELL | C13: 537.95 | D13: -0.01 | E13: -0.0857 | F13: 1.18 | G13: 5.62 | H13: 0.671 | I13: 0.607 | J13: C1b 熱錢 | K13: C1b 熱錢：升浪成交額係之前 60 日嘅 1.18×（要 ≥2.0×）
B14: GTLB | C14: 47.25 | D14: -0.0221 | E14: -0.0601 | F14: 1.17 | G14: 6.53 | H14: 0.764 | I14: 0.654 | J14: C1b 熱錢 | K14: C1b 熱錢：升浪成交額係之前 60 日嘅 1.17×（要 ≥2.0×）
B15: MTW | C15: 21.46 | D15: 0.0019 | E15: -0.0571 | F15: 2.05 | G15: 5.16 | H15: 1.077 | I15: 0.997 | J15: C4 波幅減低 | K15: C4 波幅減低：ATR5/ATR20 1.08（要 ≤0.9）；ATR5 係升浪期 ATR 嘅 1.00×（要 ≤0.7）
B16: NEO | C16: 18.36 | D16: -0.0086 | E16: -0.0779 | F16: 2.04 | G16: 3.07 | H16: 1.099 | I16: 0.971 | J16: C4 波幅減低 | K16: C4 波幅減低：ATR5/ATR20 1.10（要 ≤0.9）；ATR5 係升浪期 ATR 嘅 0.97×（要 ≤0.7）
B17: ACFN | C17: 20 | D17: -0.0203 | E17: -0.0995 | F17: 3.88 | H17: 0.95 | I17: 0.979 | J17: C1a 事件日、C4 波幅減低 | K17: C1a 事件日：高位前 60 日最大量日只有 33.8× 50日均量（當日 +5.2%）；要 ≥3× 兼當日 ≥+8% 或開市跳空 ≥+5%；C4 波幅減低：ATR5/ATR20 0.95（要 ≤0.9）；ATR5 係升浪期 ATR 嘅 0.98×（要 ≤0.7）
B18: AGPU | C18: 11.37 | D18: -0.0034 | E18: -0.12 | F18: 0.17 | G18: 8.79 | H18: 0.936 | I18: 0.789 | J18: C1b 熱錢、C4 波幅減低 | K18: C1b 熱錢：升浪成交額係之前 60 日嘅 0.17×（要 ≥2.0×）；C4 波幅減低：ATR5/ATR20 0.94（要 ≤0.9）；ATR5 係升浪期 ATR 嘅 0.79×（要 ≤0.7）
B19: BLTE | C19: 169.82 | D19: -0.0183 | E19: -0.1229 | F19: 1.14 | G19: 4.13 | H19: 0.756 | I19: 0.736 | J19: C1b 熱錢、C4 波幅減低 | K19: C1b 熱錢：升浪成交額係之前 60 日嘅 1.14×（要 ≥2.0×）；C4 波幅減低：ATR5/ATR20 0.76（要 ≤0.9）；ATR5 係升浪期 ATR 嘅 0.74×（要 ≤0.7）
B20: CORT | C20: 115.23 | D20: 0.0125 | E20: -0.0675 | F20: 1.66 | G20: 4.17 | H20: 0.986 | I20: 0.986 | J20: C1b 熱錢、C4 波幅減低 | K20: C1b 熱錢：升浪成交額係之前 60 日嘅 1.66×（要 ≥2.0×）；C4 波幅減低：ATR5/ATR20 0.99（要 ≤0.9）；ATR5 係升浪期 ATR 嘅 0.99×（要 ≤0.7）
B21: DHX | C21: 4.7 | D21: 0.0021 | E21: -0.0581 | F21: 1.1 | H21: 0.812 | I21: 0.621 | J21: C1a 事件日、C1b 熱錢 | K21: C1a 事件日：高位前 60 日最大量日只有 3.0× 50日均量（當日 +3.8%）；要 ≥3× 兼當日 ≥+8% 或開市跳空 ≥+5%；C1b 熱錢：升浪成交額係之前 60 日嘅 1.10×（要 ≥2.0×）
B22: DJCO | C22: 646.22 | D22: -0.0108 | E22: -0.0603 | F22: 1.31 | H22: 0.803 | I22: 0.652 | J22: C1a 事件日、C1b 熱錢 | K22: C1a 事件日：高位前 60 日最大量日只有 2.4× 50日均量（當日 +0.4%）；要 ≥3× 兼當日 ≥+8% 或開市跳空 ≥+5%；C1b 熱錢：升浪成交額係之前 60 日嘅 1.31×（要 ≥2.0×）
B23: DOCU | C23: 67.15 | D23: -0.0088 | E23: -0.0654 | F23: 1.05 | H23: 0.759 | I23: 0.667 | J23: C1a 事件日、C1b 熱錢 | K23: C1a 事件日：高位前 60 日最大量日只有 2.5× 50日均量（當日 +2.1%）；要 ≥3× 兼當日 ≥+8% 或開市跳空 ≥+5%；C1b 熱錢：升浪成交額係之前 60 日嘅 1.05×（要 ≥2.0×）
B24: EAF | C24: 8.27 | D24: 0.0154 | E24: -0.272 | F24: 1.28 | G24: 3.85 | H24: 0.841 | I24: 1.037 | J24: C1b 熱錢、C4 波幅減低 | K24: C1b 熱錢：升浪成交額係之前 60 日嘅 1.28×（要 ≥2.0×）；C4 波幅減低：ATR5/ATR20 0.84（要 ≤0.9）；ATR5 係升浪期 ATR 嘅 1.04×（要 ≤0.7）
B25: HYPD | C25: 3.745 | D25: 0.0232 | E25: -0.1019 | F25: 0.91 | G25: 5.12 | H25: 0.983 | I25: 0.922 | J25: C1b 熱錢、C4 波幅減低 | K25: C1b 熱錢：升浪成交額係之前 60 日嘅 0.91×（要 ≥2.0×）；C4 波幅減低：ATR5/ATR20 0.98（要 ≤0.9）；ATR5 係升浪期 ATR 嘅 0.92×（要 ≤0.7）
B26: IBTA | C26: 39.4 | D26: -0.0225 | E26: -0.0708 | F26: 1.7 | G26: 6.99 | H26: 1.037 | I26: 0.63 | J26: C1b 熱錢、C4 波幅減低 | K26: C1b 熱錢：升浪成交額係之前 60 日嘅 1.70×（要 ≥2.0×）；C4 波幅減低：ATR5/ATR20 1.04（要 ≤0.9）；ATR5 係升浪期 ATR 嘅 0.63×（要 ≤0.7）
B27: OPRT | C27: 8.14 | D27: 0.0139 | E27: -0.048 | F27: 1.33 | G27: 4.39 | H27: 0.867 | I27: 0.756 | J27: C1b 熱錢、C4 波幅減低 | K27: C1b 熱錢：升浪成交額係之前 60 日嘅 1.33×（要 ≥2.0×）；C4 波幅減低：ATR5/ATR20 0.87（要 ≤0.9）；ATR5 係升浪期 ATR 嘅 0.76×（要 ≤0.7）
B28: SMMT | C28: 16.91 | D28: -0.0013 | E28: -0.082 | F28: 1.28 | G28: 3.2 | H28: 1.332 | I28: 1.345 | J28: C1b 熱錢、C4 波幅減低 | K28: C1b 熱錢：升浪成交額係之前 60 日嘅 1.28×（要 ≥2.0×）；C4 波幅減低：ATR5/ATR20 1.33（要 ≤0.9）；ATR5 係升浪期 ATR 嘅 1.35×（要 ≤0.7）
B29: SNOW | C29: 339.56 | D29: 0.0195 | E29: -0.0474 | F29: 1 | G29: 4.2 | H29: 0.798 | I29: 0.831 | J29: C1b 熱錢、C4 波幅減低 | K29: C1b 熱錢：升浪成交額係之前 60 日嘅 1.00×（要 ≥2.0×）；C4 波幅減低：ATR5/ATR20 0.80（要 ≤0.9）；ATR5 係升浪期 ATR 嘅 0.83×（要 ≤0.7）
B30: ATRC | C30: 56.2 | D30: -0.0019 | E30: -0.0752 | F30: 1.98 | H30: 1.013 | I30: 0.978 | J30: C1a 事件日、C1b 熱錢、C4 波幅減低 | K30: C1a 事件日：高位前 60 日最大量日只有 9.5× 50日均量（當日 -1.7%）；要 ≥3× 兼當日 ≥+8% 或開市跳空 ≥+5%；C1b 熱錢：升浪成交額係之前 60 日嘅 1.98×（要 ≥2.0×）；C4 波幅減低：ATR5/ATR20 1.01（要 ≤0.9）；ATR5 係升浪期 ATR 嘅 0.98×（要 ≤0.7）
B31: BBY | C31: 88.24 | D31: -0.0283 | E31: -0.0695 | F31: 1.16 | H31: 0.882 | I31: 0.844 | J31: C1a 事件日、C1b 熱錢、C4 波幅減低 | K31: C1a 事件日：高位前 60 日最大量日只有 2.5× 50日均量（當日 -4.4%）；要 ≥3× 兼當日 ≥+8% 或開市跳空 ≥+5%；C1b 熱錢：升浪成交額係之前 60 日嘅 1.16×（要 ≥2.0×）；C4 波幅減低：ATR5/ATR20 0.88（要 ≤0.9）；ATR5 係升浪期 ATR 嘅 0.84×（要 ≤0.7）
B32: CODA | C32: 10.73 | D32: 0.0162 | E32: -0.0394 | F32: 0.56 | H32: 0.887 | I32: 0.894 | J32: C1a 事件日、C1b 熱錢、C4 波幅減低 | K32: C1a 事件日：高位前 60 日最大量日只有 5.0× 50日均量（當日 +7.1%）；要 ≥3× 兼當日 ≥+8% 或開市跳空 ≥+5%；C1b 熱錢：升浪成交額係之前 60 日嘅 0.56×（要 ≥2.0×）；C4 波幅減低：ATR5/ATR20 0.89（要 ≤0.9）；ATR5 係升浪期 ATR 嘅 0.89×（要 ≤0.7）
B33: COIN | C33: 186.41 | D33: 0.0042 | E33: -0.0729 | F33: 0.87 | H33: 0.782 | I33: 0.766 | J33: C1a 事件日、C1b 熱錢、C4 波幅減低 | K33: C1a 事件日：高位前 60 日最大量日只有 2.9× 50日均量（當日 +8.2%）；要 ≥3× 兼當日 ≥+8% 或開市跳空 ≥+5%；C1b 熱錢：升浪成交額係之前 60 日嘅 0.87×（要 ≥2.0×）；C4 波幅減低：ATR5/ATR20 0.78（要 ≤0.9）；ATR5 係升浪期 ATR 嘅 0.77×（要 ≤0.7）
