Workbook

Sheet 本版更新
A1: R22.00 更新重點
A3: 1 | B3: 數據更新至 2026-09-28 收市。規則同 R21 一樣（高動能 ＋ 回到上升中嘅 20MA），只有一項修正：S2 期內高位由九個月改為 52 周。
A4: 2 | B4: 合資格 2,767 隻 → 形態 23 隻 → 上榜 21 隻（1／2／3／6 個月頁 14／15／15／9）；同 R21 兩版都有 10 隻，新上榜 11、跌出 18。
A5: 3 | B5: R21 向前測試（3 日）：中位數 -1.57%，大市 -0.68%；前 10 名 +1.42%。
A6: 4 | B6: 發現並修正：兩個過時嘅 Nasdaq 快照（加咗兩道關）；09-28 Yahoo 日線未出齊（每小時K線合成、成交量還原）；S2 窗口太短；R21 一句冇量度過嘅講法。詳見「審視標記」頁。
A7: 5 | B7: 獨立重寫嘅篩選程式對 2026-09-28 同 2026-09-25 兩份名單都 0 差異。
A8: 6 | B8: 所有代號都連去 TradingView 圖表；計得出嘅欄位全部係公式。

Sheet 總表
A1: 排名 | B1: 代號 | C1: 公司 | D1: 交易所 | E1: 板塊 | F1: 行業 | G1: 市值(十億美元) | H1: 市值組 | I1: 收市價 | J1: 前收 | K1: 當日% | L1: 當日高 | M1: 當日低 | N1: MA20 | O1: 距MA20% | P1: MA50 | Q1: 距MA50% | R1: MA20（5日前） | S1: MA20 5日斜率% | T1: 63日最高收市 | U1: 高位日期 | V1: 高位至今（交易日） | W1: 距高位% | X1: 25日內最大偏離MA20% | Y1: 偏離最大日期 | Z1: 近3日最低價距MA20% | AA1: 升浪起點 | AB1: 升浪幅度% | AC1: 1個月回報 | AD1: 2個月回報 | AE1: 3個月回報 | AF1: 6個月回報 | AG1: 1個月百分位 | AH1: 2個月百分位 | AI1: 3個月百分位 | AJ1: 6個月百分位 | AK1: 動能時間框 | AL1: 覆蓋度 | AM1: 回調量比 | AN1: ATR5/ATR20 | AO1: ATR14% | AP1: 量縮 | AQ1: 貼近MA20 | AR1: MA20斜率分 | AS1: 回調深度分 | AT1: 企穩 | AU1: 波幅收窄 | AV1: 動能分數 | AW1: 回調質素 | AX1: 綜合分數 | AY1: 爆發潛力分數 | AZ1: R21 排名 | BA1: 門檻測試留低 | BB1: 審視標記 | BC1: 兩源最大差%
A2: =COUNTIF($AY$2:$AY$22,">"&AY2)+1 | B2: IRD | C2: Opus Genetics Inc. | D2: NASDAQ | E2: 醫療保健 | F2: Biotechnology: Pharmaceutical Preparations | G2: 0.396 | H2: 小型 | I2: 5.07 | J2: 4.76 | K2: =I2/J2-1 | L2: 5.14 | M2: 4.625 | N2: 5.046 | O2: =I2/N2-1 | P2: 4.2012 | Q2: =I2/P2-1 | R2: 4.7855 | S2: =N2/R2-1 | T2: 6.07 | U2: 2026-09-10 | V2: 12 | W2: =I2/T2-1 | X2: 0.45041816 | Y2: 2026-09-10 | Z2: -0.083432422 | AA2: 2026-07-23 | AB2: 1.0787671 | AC2: 0.31688312 | AD2: 0.4610951 | AE2: 0.24876847 | AF2: 0.16551724 | AG2: 0.98879248 | AH2: 0.96529284 | AI2: 0.91106291 | AJ2: 0.61329416 | AK2: 1個月、2個月、3個月 | AL2: =(AG2>=0.9)*(AC2>0)+(AH2>=0.9)*(AD2>0)+(AI2>=0.9)*(AE2>0)+IF(AJ2="",0,(AJ2>=0.9)*(AF2>0)) | AM2: 0.562861 | AN2: 0.68712781 | AO2: 0.11897718 | AP2: =MAX(0,MIN(1,(AM2-1.2)/(0.6-1.2))) | AQ2: =MAX(0,MIN(1,(ABS(O2)-0.03)/(0-0.03))) | AR2: =MAX(0,MIN(1,S2/0.03)) | AS2: =MAX(0,MIN(1,(-W2-0.3)/(0.15-0.3))) | AT2: =0.5*IF(L2>M2,(I2-M2)/(L2-M2),0.5)+0.5*(I2>=N2) | AU2: =MAX(0,MIN(1,(AN2-1.3)/(0.7-1.3))) | AV2: =100*(0.2*AG2+0.2*AH2+0.3*AI2+IF(AJ2="",0,0.3*AJ2))/(0.7+IF(AJ2="",0,0.3)) | AW2: =100*(0.25*AP2+0.2*AQ2+0.15*AR2+0.15*AS2+0.15*AT2+0.1*AU2) | AX2: =0.5*AV2+0.5*AW2 | AY2: =0.4*AV2+0.4*AW2+0.2*(AL2/4*100) | AZ2: 9 | BA2: 18/18 | BB2: 二元事件就喺今個星期：10 月 1–4 日 EURETINA 大會公佈 OPGx-BEST1 詳細數據；R21 已標記佢嘅升浪同回調都係臨床消息帶動 | BC2: 0
A3: =COUNTIF($AY$2:$AY$22,">"&AY3)+1 | B3: TTRX | C3: Turn Therapeutics Inc. | D3: NASDAQ | E3: 醫療保健 | F3: Biotechnology: Pharmaceutical Preparations | G3: 0.372 | H3: 小型 | I3: 13.04 | J3: 12.49 | K3: =I3/J3-1 | L3: 13.125 | M3: 12.285 | N3: 12.688 | O3: =I3/N3-1 | P3: 10.7292 | Q3: =I3/P3-1 | R3: 11.758 | S3: =N3/R3-1 | T3: 15.34 | U3: 2026-09-21 | V3: 5 | W3: =I3/T3-1 | X3: 0.35434622 | Y3: 2026-09-09 | Z3: -0.031762295 | AA3: 2026-06-22 | AB3: 1.6585789 | AC3: 0.28981207 | AD3: 0.75504711 | AE3: 0.88712012 | AF3: 2.7687861 | AG3: 0.98698482 | AH3: 0.98806941 | AI3: 0.99060014 | AJ3: 0.99485861 | AK3: 1個月、2個月、3個月、6個月 | AL3: =(AG3>=0.9)*(AC3>0)+(AH3>=0.9)*(AD3>0)+(AI3>=0.9)*(AE3>0)+IF(AJ3="",0,(AJ3>=0.9)*(AF3>0)) | AM3: 0.80877863 | AN3: 1.0159776 | AO3: 0.11174408 | AP3: =MAX(0,MIN(1,(AM3-1.2)/(0.6-1.2))) | AQ3: =MAX(0,MIN(1,(ABS(O3)-0.03)/(0-0.03))) | AR3: =MAX(0,MIN(1,S3/0.03)) | AS3: =MAX(0,MIN(1,(-W3-0.3)/(0.15-0.3))) | AT3: =0.5*IF(L3>M3,(I3-M3)/(L3-M3),0.5)+0.5*(I3>=N3) | AU3: =MAX(0,MIN(1,(AN3-1.3)/(0.7-1.3))) | AV3: =100*(0.2*AG3+0.2*AH3+0.3*AI3+IF(AJ3="",0,0.3*AJ3))/(0.7+IF(AJ3="",0,0.3)) | AW3: =100*(0.25*AP3+0.2*AQ3+0.15*AR3+0.15*AS3+0.15*AT3+0.1*AU3) | AX3: =0.5*AV3+0.5*AW3 | AY3: =0.4*AV3+0.4*AW3+0.2*(AL3/4*100) | BA3: 17/18 | BB3: 回調唔係有序回落：期內有一日跌 -11.6%；臨床期生物科技，升浪由試驗消息帶動（3 月 $3.22 → 9 月約 $14.8），唔係業績動能；20 日成交額中位數只有 $1.7M（股票池下限 $1M），入市出市都會有滑價 | BC3: 0
A4: =COUNTIF($AY$2:$AY$22,">"&AY4)+1 | B4: DELL | C4: Dell Technologies Inc. Class C | D4: NYSE | E4: 科技 | F4: Computer Manufacturing | G4: 357.893 | H4: 大型 | I4: 543.42 | J4: 562.89 | K4: =I4/J4-1 | L4: 557 | M4: 535.5 | N4: 533.5355 | O4: =I4/N4-1 | P4: 478.6634 | Q4: =I4/P4-1 | R4: 510.332 | S4: =N4/R4-1 | T4: 588.4 | U4: 2026-09-17 | V4: 7 | W4: =I4/T4-1 | X4: 0.18388794 | Y4: 2026-09-17 | Z4: 0.0036820418 | AA4: 2026-07-29 | AB4: 0.59181907 | AC4: 0.15067971 | AD4: 0.4701331 | AE4: 0.3106775 | AF4: 2.1629125 | AG4: 0.96348518 | AH4: 0.96746204 | AI4: 0.92950108 | AJ4: 0.99081895 | AK4: 1個月、2個月、3個月、6個月 | AL4: =(AG4>=0.9)*(AC4>0)+(AH4>=0.9)*(AD4>0)+(AI4>=0.9)*(AE4>0)+IF(AJ4="",0,(AJ4>=0.9)*(AF4>0)) | AM4: 0.89695065 | AN4: 0.81962532 | AO4: 0.059630278 | AP4: =MAX(0,MIN(1,(AM4-1.2)/(0.6-1.2))) | AQ4: =MAX(0,MIN(1,(ABS(O4)-0.03)/(0-0.03))) | AR4: =MAX(0,MIN(1,S4/0.03)) | AS4: =MAX(0,MIN(1,(-W4-0.3)/(0.15-0.3))) | AT4: =0.5*IF(L4>M4,(I4-M4)/(L4-M4),0.5)+0.5*(I4>=N4) | AU4: =MAX(0,MIN(1,(AN4-1.3)/(0.7-1.3))) | AV4: =100*(0.2*AG4+0.2*AH4+0.3*AI4+IF(AJ4="",0,0.3*AJ4))/(0.7+IF(AJ4="",0,0.3)) | AW4: =100*(0.25*AP4+0.2*AQ4+0.15*AR4+0.15*AS4+0.15*AT4+0.1*AU4) | AX4: =0.5*AV4+0.5*AW4 | AY4: =0.4*AV4+0.4*AW4+0.2*(AL4/4*100) | BA4: 17/18 | BC4: 0
A5: =COUNTIF($AY$2:$AY$22,">"&AY5)+1 | B5: PLSE | C5: Pulse Biosciences Inc | D5: NASDAQ | E5: 醫療保健 | F5: Medical/Dental Instruments | G5: 3.682 | H5: 中型 | I5: 52.32 | J5: 51.63 | K5: =I5/J5-1 | L5: 53.6 | M5: 51.14 | N5: 52.4805 | O5: =I5/N5-1 | P5: 45.3816 | Q5: =I5/P5-1 | R5: 51.576 | S5: =N5/R5-1 | T5: 55.2 | U5: 2026-09-15 | V5: 9 | W5: =I5/T5-1 | X5: 0.16942778 | Y5: 2026-08-24 | Z5: -0.027601784 | AA5: 2026-06-16 | AB5: 1.1983274 | AC5: 0.077429984 | AD5: 0.52759124 | AE5: 0.78932969 | AF5: 1.54351 | AG5: 0.92552422 | AH5: 0.97324657 | AI5: 0.98662328 | AJ5: 0.97759824 | AK5: 1個月、2個月、3個月、6個月 | AL5: =(AG5>=0.9)*(AC5>0)+(AH5>=0.9)*(AD5>0)+(AI5>=0.9)*(AE5>0)+IF(AJ5="",0,(AJ5>=0.9)*(AF5>0)) | AM5: 1.0144702 | AN5: 0.66479657 | AO5: 0.085733399 | AP5: =MAX(0,MIN(1,(AM5-1.2)/(0.6-1.2))) | AQ5: =MAX(0,MIN(1,(ABS(O5)-0.03)/(0-0.03))) | AR5: =MAX(0,MIN(1,S5/0.03)) | AS5: =MAX(0,MIN(1,(-W5-0.3)/(0.15-0.3))) | AT5: =0.5*IF(L5>M5,(I5-M5)/(L5-M5),0.5)+0.5*(I5>=N5) | AU5: =MAX(0,MIN(1,(AN5-1.3)/(0.7-1.3))) | AV5: =100*(0.2*AG5+0.2*AH5+0.3*AI5+IF(AJ5="",0,0.3*AJ5))/(0.7+IF(AJ5="",0,0.3)) | AW5: =100*(0.25*AP5+0.2*AQ5+0.15*AR5+0.15*AS5+0.15*AT5+0.1*AU5) | AX5: =0.5*AV5+0.5*AW5 | AY5: =0.4*AV5+0.4*AW5+0.2*(AL5/4*100) | AZ5: 8 | BA5: 18/18 | BB5: 回調唔係有序回落：期內有一日跌 -10.1% | BC5: 0
A6: =COUNTIF($AY$2:$AY$22,">"&AY6)+1 | B6: TITN | C6: Titan Machinery Inc. | D6: NASDAQ | E6: 非必需消費 | F6: Other Specialty Stores | G6: 0.553 | H6: 小型 | I6: 23.47 | J6: 23.49 | K6: =I6/J6-1 | L6: 23.78 | M6: 23.02 | N6: 23.591 | O6: =I6/N6-1 | P6: 20.6752 | Q6: =I6/P6-1 | R6: 22.3135 | S6: =N6/R6-1 | T6: 26.22 | U6: 2026-09-04 | V6: 15 | W6: =I6/T6-1 | X6: 0.34217194 | Y6: 2026-09-04 | Z6: -0.024204146 | AA6: 2026-07-31 | AB6: 0.54326074 | AC6: 0.27415852 | AD6: 0.30171936 | AE6: 0.12082139 | AF6: 0.45776398 | AG6: 0.98481562 | AH6: 0.92624729 | AI6: 0.82140275 | AJ6: 0.84465663 | AK6: 1個月、2個月 | AL6: =(AG6>=0.9)*(AC6>0)+(AH6>=0.9)*(AD6>0)+(AI6>=0.9)*(AE6>0)+IF(AJ6="",0,(AJ6>=0.9)*(AF6>0)) | AM6: 0.66126851 | AN6: 0.61926445 | AO6: 0.041511961 | AP6: =MAX(0,MIN(1,(AM6-1.2)/(0.6-1.2))) | AQ6: =MAX(0,MIN(1,(ABS(O6)-0.03)/(0-0.03))) | AR6: =MAX(0,MIN(1,S6/0.03)) | AS6: =MAX(0,MIN(1,(-W6-0.3)/(0.15-0.3))) | AT6: =0.5*IF(L6>M6,(I6-M6)/(L6-M6),0.5)+0.5*(I6>=N6) | AU6: =MAX(0,MIN(1,(AN6-1.3)/(0.7-1.3))) | AV6: =100*(0.2*AG6+0.2*AH6+0.3*AI6+IF(AJ6="",0,0.3*AJ6))/(0.7+IF(AJ6="",0,0.3)) | AW6: =100*(0.25*AP6+0.2*AQ6+0.15*AR6+0.15*AS6+0.15*AT6+0.1*AU6) | AX6: =0.5*AV6+0.5*AW6 | AY6: =0.4*AV6+0.4*AW6+0.2*(AL6/4*100) | BA6: 18/18 | BB6: 升浪來自券商升級（08-31 Baird），同期收入 −9.2%、虧損擴大 —— 動能冇基本面支持 | BC6: 0.00028
A7: =COUNTIF($AY$2:$AY$22,">"&AY7)+1 | B7: ESTC | C7: Elastic N.V. | D7: NYSE | E7: 科技 | F7: Computer Software: Prepackaged Software | G7: 9.252 | H7: 中型 | I7: 87.95 | J7: 88.12 | K7: =I7/J7-1 | L7: 88.695 | M7: 84.62 | N7: 88.906 | O7: =I7/N7-1 | P7: 80.0968 | Q7: =I7/P7-1 | R7: 87.8405 | S7: =N7/R7-1 | T7: 99.91 | U7: 2026-08-28 | V7: 20 | W7: =I7/T7-1 | X7: 0.24012437 | Y7: 2026-08-28 | Z7: -0.04820822 | AA7: 2026-06-25 | AB7: 0.86399254 | AC7: 0.05027466 | AD7: 0.36483551 | AE7: 0.54433714 | AF7: 0.81265458 | AG7: 0.89262473 | AH7: 0.945047 | AI7: 0.97324657 | AJ7: 0.9239809 | AK7: 2個月、3個月、6個月 | AL7: =(AG7>=0.9)*(AC7>0)+(AH7>=0.9)*(AD7>0)+(AI7>=0.9)*(AE7>0)+IF(AJ7="",0,(AJ7>=0.9)*(AF7>0)) | AM7: 0.81211629 | AN7: 0.86508178 | AO7: 0.040838951 | AP7: =MAX(0,MIN(1,(AM7-1.2)/(0.6-1.2))) | AQ7: =MAX(0,MIN(1,(ABS(O7)-0.03)/(0-0.03))) | AR7: =MAX(0,MIN(1,S7/0.03)) | AS7: =MAX(0,MIN(1,(-W7-0.3)/(0.15-0.3))) | AT7: =0.5*IF(L7>M7,(I7-M7)/(L7-M7),0.5)+0.5*(I7>=N7) | AU7: =MAX(0,MIN(1,(AN7-1.3)/(0.7-1.3))) | AV7: =100*(0.2*AG7+0.2*AH7+0.3*AI7+IF(AJ7="",0,0.3*AJ7))/(0.7+IF(AJ7="",0,0.3)) | AW7: =100*(0.25*AP7+0.2*AQ7+0.15*AR7+0.15*AS7+0.15*AT7+0.1*AU7) | AX7: =0.5*AV7+0.5*AW7 | AY7: =0.4*AV7+0.4*AW7+0.2*(AL7/4*100) | AZ7: 4 | BA7: 18/18 | BC7: 0
A8: =COUNTIF($AY$2:$AY$22,">"&AY8)+1 | B8: FIVN | C8: Five9 Inc. | D8: NASDAQ | E8: 科技 | F8: EDP Services | G8: 2.673 | H8: 中型 | I8: 34.66 | J8: 35.77 | K8: =I8/J8-1 | L8: 35.365 | M8: 33.83 | N8: 33.9155 | O8: =I8/N8-1 | P8: 31.5127 | Q8: =I8/P8-1 | R8: 33.02825 | S8: =N8/R8-1 | T8: 38.65 | U8: 2026-09-22 | V8: 4 | W8: =I8/T8-1 | X8: 0.15988566 | Y8: 2026-09-22 | Z8: -0.0025209712 | AA8: 2026-06-23 | AB8: 1.0278069 | AC8: 0.0026034134 | AD8: 0.2759065 | AE8: 0.62723005 | AF8: 1.4019404 | AG8: 0.79067245 | AH8: 0.9175705 | AI8: 0.98011569 | AJ8: 0.97208961 | AK8: 2個月、3個月、6個月 | AL8: =(AG8>=0.9)*(AC8>0)+(AH8>=0.9)*(AD8>0)+(AI8>=0.9)*(AE8>0)+IF(AJ8="",0,(AJ8>=0.9)*(AF8>0)) | AM8: 0.99414527 | AN8: 1.0923836 | AO8: 0.061023411 | AP8: =MAX(0,MIN(1,(AM8-1.2)/(0.6-1.2))) | AQ8: =MAX(0,MIN(1,(ABS(O8)-0.03)/(0-0.03))) | AR8: =MAX(0,MIN(1,S8/0.03)) | AS8: =MAX(0,MIN(1,(-W8-0.3)/(0.15-0.3))) | AT8: =0.5*IF(L8>M8,(I8-M8)/(L8-M8),0.5)+0.5*(I8>=N8) | AU8: =MAX(0,MIN(1,(AN8-1.3)/(0.7-1.3))) | AV8: =100*(0.2*AG8+0.2*AH8+0.3*AI8+IF(AJ8="",0,0.3*AJ8))/(0.7+IF(AJ8="",0,0.3)) | AW8: =100*(0.25*AP8+0.2*AQ8+0.15*AR8+0.15*AS8+0.15*AT8+0.1*AU8) | AX8: =0.5*AV8+0.5*AW8 | AY8: =0.4*AV8+0.4*AW8+0.2*(AL8/4*100) | BA8: 17/18 | BC8: 0
A9: =COUNTIF($AY$2:$AY$22,">"&AY9)+1 | B9: DHX | C9: DHI Group Inc. | D9: NYSE | E9: 非必需消費 | F9: Business Services | G9: 0.205 | H9: 小型 | I9: 4.62 | J9: 4.73 | K9: =I9/J9-1 | L9: 4.73 | M9: 4.54 | N9: 4.6485 | O9: =I9/N9-1 | P9: 4.3014 | Q9: =I9/P9-1 | R9: 4.539 | S9: =N9/R9-1 | T9: 4.99 | U9: 2026-09-17 | V9: 7 | W9: =I9/T9-1 | X9: 0.11834177 | Y9: 2026-09-02 | Z9: -0.023340863 | AA9: 2026-06-25 | AB9: 0.40960452 | AC9: 0.12682927 | AD9: 0.12958435 | AE9: 0.21259843 | AF9: 0.77692308 | AG9: 0.95336226 | AH9: 0.83261027 | AI9: 0.8922632 | AJ9: 0.91920676 | AK9: 1個月、6個月 | AL9: =(AG9>=0.9)*(AC9>0)+(AH9>=0.9)*(AD9>0)+(AI9>=0.9)*(AE9>0)+IF(AJ9="",0,(AJ9>=0.9)*(AF9>0)) | AM9: 0.83962729 | AN9: 0.59805825 | AO9: 0.04746444 | AP9: =MAX(0,MIN(1,(AM9-1.2)/(0.6-1.2))) | AQ9: =MAX(0,MIN(1,(ABS(O9)-0.03)/(0-0.03))) | AR9: =MAX(0,MIN(1,S9/0.03)) | AS9: =MAX(0,MIN(1,(-W9-0.3)/(0.15-0.3))) | AT9: =0.5*IF(L9>M9,(I9-M9)/(L9-M9),0.5)+0.5*(I9>=N9) | AU9: =MAX(0,MIN(1,(AN9-1.3)/(0.7-1.3))) | AV9: =100*(0.2*AG9+0.2*AH9+0.3*AI9+IF(AJ9="",0,0.3*AJ9))/(0.7+IF(AJ9="",0,0.3)) | AW9: =100*(0.25*AP9+0.2*AQ9+0.15*AR9+0.15*AS9+0.15*AT9+0.1*AU9) | AX9: =0.5*AV9+0.5*AW9 | AY9: =0.4*AV9+0.4*AW9+0.2*(AL9/4*100) | AZ9: 13 | BA9: 18/18 | BB9: 20 日成交額中位數只有 $1.3M（股票池下限 $1M），入市出市都會有滑價 | BC9: 0
A10: =COUNTIF($AY$2:$AY$22,">"&AY10)+1 | B10: VLO | C10: Valero Energy Corporation | D10: NYSE | E10: 能源 | F10: Integrated oil Companies | G10: 111.48 | H10: 大型 | I10: 389.57 | J10: 387.18 | K10: =I10/J10-1 | L10: 395.85 | M10: 385 | N10: 384.55 | O10: =I10/N10-1 | P10: 348.1684 | Q10: =I10/P10-1 | R10: 375.59 | S10: =N10/R10-1 | T10: 413.28 | U10: 2026-09-18 | V10: 6 | W10: =I10/T10-1 | X10: 0.11560626 | Y10: 2026-09-17 | Z10: -0.031617016 | AA10: 2026-06-18 | AB10: 0.74896318 | AC10: 0.12400819 | AD10: 0.292878 | AE10: 0.46278913 | AF10: 0.53181032 | AG10: 0.95191612 | AH10: 0.92154736 | AI10: 0.96348518 | AJ10: 0.87366875 | AK10: 1個月、2個月、3個月 | AL10: =(AG10>=0.9)*(AC10>0)+(AH10>=0.9)*(AD10>0)+(AI10>=0.9)*(AE10>0)+IF(AJ10="",0,(AJ10>=0.9)*(AF10>0)) | AM10: 1.5674537 | AN10: 1.1906389 | AO10: 0.044776475 | AP10: =MAX(0,MIN(1,(AM10-1.2)/(0.6-1.2))) | AQ10: =MAX(0,MIN(1,(ABS(O10)-0.03)/(0-0.03))) | AR10: =MAX(0,MIN(1,S10/0.03)) | AS10: =MAX(0,MIN(1,(-W10-0.3)/(0.15-0.3))) | AT10: =0.5*IF(L10>M10,(I10-M10)/(L10-M10),0.5)+0.5*(I10>=N10) | AU10: =MAX(0,MIN(1,(AN10-1.3)/(0.7-1.3))) | AV10: =100*(0.2*AG10+0.2*AH10+0.3*AI10+IF(AJ10="",0,0.3*AJ10))/(0.7+IF(AJ10="",0,0.3)) | AW10: =100*(0.25*AP10+0.2*AQ10+0.15*AR10+0.15*AS10+0.15*AT10+0.1*AU10) | AX10: =0.5*AV10+0.5*AW10 | AY10: =0.4*AV10+0.4*AW10+0.2*(AL10/4*100) | AZ10: 17 | BA10: 18/18 | BB10: 同名單入面 MPC、DINO、PSX 同向（21 日相關系數中位數 +0.91，名單其餘 +0.07）：當一個交易睇 | BC10: 0
A11: =COUNTIF($AY$2:$AY$22,">"&AY11)+1 | B11: PURR | C11: Hyperliquid Strategies Inc | D11: NASDAQ | E11: 金融 | F11: Finance: Consumer Services | G11: 3.057 | H11: 中型 | I11: 12.08 | J11: 12.85 | K11: =I11/J11-1 | L11: 12.67 | M11: 11.93 | N11: 12.41625 | O11: =I11/N11-1 | P11: 9.6601 | Q11: =I11/P11-1 | R11: 11.99625 | S11: =N11/R11-1 | T11: 14.09 | U11: 2026-09-24 | V11: 2 | W11: =I11/T11-1 | X11: 0.55874134 | Y11: 2026-08-27 | Z11: -0.039162388 | AA11: 2026-07-29 | AB11: 1.360134 | AC11: -0.058456742 | AD11: 1.0234506 | AE11: 0.42621015 | AF11: 1.440404 | AG11: 0.51156905 | AH11: 0.99240781 | AI11: 0.95300072 | AJ11: 0.97429306 | AK11: 2個月、3個月、6個月 | AL11: =(AG11>=0.9)*(AC11>0)+(AH11>=0.9)*(AD11>0)+(AI11>=0.9)*(AE11>0)+IF(AJ11="",0,(AJ11>=0.9)*(AF11>0)) | AM11: 0.89610749 | AN11: 0.87045674 | AO11: 0.096848392 | AP11: =MAX(0,MIN(1,(AM11-1.2)/(0.6-1.2))) | AQ11: =MAX(0,MIN(1,(ABS(O11)-0.03)/(0-0.03))) | AR11: =MAX(0,MIN(1,S11/0.03)) | AS11: =MAX(0,MIN(1,(-W11-0.3)/(0.15-0.3))) | AT11: =0.5*IF(L11>M11,(I11-M11)/(L11-M11),0.5)+0.5*(I11>=N11) | AU11: =MAX(0,MIN(1,(AN11-1.3)/(0.7-1.3))) | AV11: =100*(0.2*AG11+0.2*AH11+0.3*AI11+IF(AJ11="",0,0.3*AJ11))/(0.7+IF(AJ11="",0,0.3)) | AW11: =100*(0.25*AP11+0.2*AQ11+0.15*AR11+0.15*AS11+0.15*AT11+0.1*AU11) | AX11: =0.5*AV11+0.5*AW11 | AY11: =0.4*AV11+0.4*AW11+0.2*(AL11/4*100) | BA11: 17/18 | BB11: 回調唔係有序回落：期內有一日跌 -8.8%；加密貨幣庫存公司，股價跟 HYPE 代幣走；09-25 監管負面消息 | BC11: 0
A12: =COUNTIF($AY$2:$AY$22,">"&AY12)+1 | B12: SNOW | C12: Snowflake Inc. | D12: NYSE | E12: 科技 | F12: Computer Software: Prepackaged Software | G12: 118.52 | H12: 大型 | I12: 328.12 | J12: 335.94 | K12: =I12/J12-1 | L12: 333.72 | M12: 316.63 | N12: 332.1215 | O12: =I12/N12-1 | P12: 318.2176 | Q12: =I12/P12-1 | R12: 329.2625 | S12: =N12/R12-1 | T12: 356.47 | U12: 2026-09-03 | V12: 16 | W12: =I12/T12-1 | X12: 0.087092096 | Y12: 2026-09-03 | Z12: -0.046644075 | AA12: 2026-06-24 | AB12: 0.57764992 | AC12: -0.0030081128 | AD12: 0.15984447 | AE12: 0.30387443 | AF12: 1.1473822 | AG12: 0.76789588 | AH12: 0.85213304 | AI12: 0.92697035 | AJ12: 0.95813441 | AK12: 3個月、6個月 | AL12: =(AG12>=0.9)*(AC12>0)+(AH12>=0.9)*(AD12>0)+(AI12>=0.9)*(AE12>0)+IF(AJ12="",0,(AJ12>=0.9)*(AF12>0)) | AM12: 0.85668738 | AN12: 0.83876003 | AO12: 0.042485981 | AP12: =MAX(0,MIN(1,(AM12-1.2)/(0.6-1.2))) | AQ12: =MAX(0,MIN(1,(ABS(O12)-0.03)/(0-0.03))) | AR12: =MAX(0,MIN(1,S12/0.03)) | AS12: =MAX(0,MIN(1,(-W12-0.3)/(0.15-0.3))) | AT12: =0.5*IF(L12>M12,(I12-M12)/(L12-M12),0.5)+0.5*(I12>=N12) | AU12: =MAX(0,MIN(1,(AN12-1.3)/(0.7-1.3))) | AV12: =100*(0.2*AG12+0.2*AH12+0.3*AI12+IF(AJ12="",0,0.3*AJ12))/(0.7+IF(AJ12="",0,0.3)) | AW12: =100*(0.25*AP12+0.2*AQ12+0.15*AR12+0.15*AS12+0.15*AT12+0.1*AU12) | AX12: =0.5*AV12+0.5*AW12 | AY12: =0.4*AV12+0.4*AW12+0.2*(AL12/4*100) | AZ12: 11 | BA12: 17/18 | BC12: 0
A13: =COUNTIF($AY$2:$AY$22,">"&AY13)+1 | B13: MPC | C13: Marathon Petroleum Corporation | D13: NYSE | E13: 能源 | F13: Integrated oil Companies | G13: 110.51 | H13: 大型 | I13: 389.55 | J13: 393.52 | K13: =I13/J13-1 | L13: 398.33 | M13: 387.07 | N13: 396.4005 | O13: =I13/N13-1 | P13: 358.1166 | Q13: =I13/P13-1 | R13: 389.3985 | S13: =N13/R13-1 | T13: 424.89 | U13: 2026-09-18 | V13: 6 | W13: =I13/T13-1 | X13: 0.098904247 | Y13: 2026-09-17 | Z13: -0.036888744 | AA13: 2026-06-18 | AB13: 0.74916636 | AC13: 0.07154646 | AD13: 0.26182301 | AE13: 0.50277756 | AF13: 0.54638561 | AG13: 0.92118583 | AH13: 0.91070137 | AI13: 0.96890817 | AJ13: 0.87770841 | AK13: 1個月、2個月、3個月 | AL13: =(AG13>=0.9)*(AC13>0)+(AH13>=0.9)*(AD13>0)+(AI13>=0.9)*(AE13>0)+IF(AJ13="",0,(AJ13>=0.9)*(AF13>0)) | AM13: 1.1616164 | AN13: 1.0498677 | AO13: 0.041905495 | AP13: =MAX(0,MIN(1,(AM13-1.2)/(0.6-1.2))) | AQ13: =MAX(0,MIN(1,(ABS(O13)-0.03)/(0-0.03))) | AR13: =MAX(0,MIN(1,S13/0.03)) | AS13: =MAX(0,MIN(1,(-W13-0.3)/(0.15-0.3))) | AT13: =0.5*IF(L13>M13,(I13-M13)/(L13-M13),0.5)+0.5*(I13>=N13) | AU13: =MAX(0,MIN(1,(AN13-1.3)/(0.7-1.3))) | AV13: =100*(0.2*AG13+0.2*AH13+0.3*AI13+IF(AJ13="",0,0.3*AJ13))/(0.7+IF(AJ13="",0,0.3)) | AW13: =100*(0.25*AP13+0.2*AQ13+0.15*AR13+0.15*AS13+0.15*AT13+0.1*AU13) | AX13: =0.5*AV13+0.5*AW13 | AY13: =0.4*AV13+0.4*AW13+0.2*(AL13/4*100) | AZ13: 20 | BA13: 17/18 | BB13: 同名單入面 VLO、DINO、PSX 同向（21 日相關系數中位數 +0.91，名單其餘 +0.07）：當一個交易睇 | BC13: 0
A14: =COUNTIF($AY$2:$AY$22,">"&AY14)+1 | B14: KGEI | C14: Kolibri Global Energy Inc. Common stock | D14: NASDAQ | E14: 能源 | F14: Oil & Gas Production | G14: 0.228 | H14: 小型 | I14: 6.44 | J14: 6.35 | K14: =I14/J14-1 | L14: 6.58 | M14: 6.37 | N14: 6.5105 | O14: =I14/N14-1 | P14: 5.8874 | Q14: =I14/P14-1 | R14: 6.349 | S14: =N14/R14-1 | T14: 6.88 | U14: 2026-09-15 | V14: 9 | W14: =I14/T14-1 | X14: 0.11526014 | Y14: 2026-09-09 | Z14: -0.032482062 | AA14: 2026-06-25 | AB14: 0.50877193 | AC14: 0.1008547 | AD14: 0.25048544 | AE14: 0.33887734 | AF14: 0.095238095 | AG14: 0.94107014 | AH14: 0.90600145 | AI14: 0.93564714 | AJ14: 0.51230261 | AK14: 1個月、2個月、3個月 | AL14: =(AG14>=0.9)*(AC14>0)+(AH14>=0.9)*(AD14>0)+(AI14>=0.9)*(AE14>0)+IF(AJ14="",0,(AJ14>=0.9)*(AF14>0)) | AM14: 1.2041039 | AN14: 0.83769634 | AO14: 0.042147294 | AP14: =MAX(0,MIN(1,(AM14-1.2)/(0.6-1.2))) | AQ14: =MAX(0,MIN(1,(ABS(O14)-0.03)/(0-0.03))) | AR14: =MAX(0,MIN(1,S14/0.03)) | AS14: =MAX(0,MIN(1,(-W14-0.3)/(0.15-0.3))) | AT14: =0.5*IF(L14>M14,(I14-M14)/(L14-M14),0.5)+0.5*(I14>=N14) | AU14: =MAX(0,MIN(1,(AN14-1.3)/(0.7-1.3))) | AV14: =100*(0.2*AG14+0.2*AH14+0.3*AI14+IF(AJ14="",0,0.3*AJ14))/(0.7+IF(AJ14="",0,0.3)) | AW14: =100*(0.25*AP14+0.2*AQ14+0.15*AR14+0.15*AS14+0.15*AT14+0.1*AU14) | AX14: =0.5*AV14+0.5*AW14 | AY14: =0.4*AV14+0.4*AW14+0.2*(AL14/4*100) | BA14: 17/18 | BB14: 今日放量（1.8× 50日均量）收喺 20MA 下面；20 日成交額中位數只有 $1.0M（股票池下限 $1M），入市出市都會有滑價 | BC14: 0.00099
A15: =COUNTIF($AY$2:$AY$22,">"&AY15)+1 | B15: IBTA | C15: Ibotta Inc. Class A | D15: NYSE | E15: 非必需消費 | F15: Advertising | G15: 0.951 | H15: 小型 | I15: 40.05 | J15: 41.06 | K15: =I15/J15-1 | L15: 42.03 | M15: 39.16 | N15: 40.0945 | O15: =I15/N15-1 | P15: 36.1082 | Q15: =I15/P15-1 | R15: 39.283 | S15: =N15/R15-1 | T15: 42.4 | U15: 2026-09-14 | V15: 10 | W15: =I15/T15-1 | X15: 0.12240131 | Y15: 2026-08-24 | Z15: -0.023307436 | AA15: 2026-07-31 | AB15: 0.76666667 | AC15: 0.099670511 | AD15: 0.50904295 | AE15: 0.16458273 | AF15: 0.38198758 | AG15: 0.94034707 | AH15: 0.97071584 | AI15: 0.8593637 | AJ15: 0.8068307 | AK15: 1個月、2個月 | AL15: =(AG15>=0.9)*(AC15>0)+(AH15>=0.9)*(AD15>0)+(AI15>=0.9)*(AE15>0)+IF(AJ15="",0,(AJ15>=0.9)*(AF15>0)) | AM15: 1.110396 | AN15: 1.0200311 | AO15: 0.043244159 | AP15: =MAX(0,MIN(1,(AM15-1.2)/(0.6-1.2))) | AQ15: =MAX(0,MIN(1,(ABS(O15)-0.03)/(0-0.03))) | AR15: =MAX(0,MIN(1,S15/0.03)) | AS15: =MAX(0,MIN(1,(-W15-0.3)/(0.15-0.3))) | AT15: =0.5*IF(L15>M15,(I15-M15)/(L15-M15),0.5)+0.5*(I15>=N15) | AU15: =MAX(0,MIN(1,(AN15-1.3)/(0.7-1.3))) | AV15: =100*(0.2*AG15+0.2*AH15+0.3*AI15+IF(AJ15="",0,0.3*AJ15))/(0.7+IF(AJ15="",0,0.3)) | AW15: =100*(0.25*AP15+0.2*AQ15+0.15*AR15+0.15*AS15+0.15*AT15+0.1*AU15) | AX15: =0.5*AV15+0.5*AW15 | AY15: =0.4*AV15+0.4*AW15+0.2*(AL15/4*100) | BA15: 18/18 | BB15: 升幅過半來自單日：2026-07-31 起計升 77%，最大單日 +51.9% | BC15: 0
A16: =COUNTIF($AY$2:$AY$22,">"&AY16)+1 | B16: ELMT | C16: The Elmet Group Co. | D16: NASDAQ | E16: 工業 | F16: Metal Fabrications | G16: 0.598 | H16: 小型 | I16: 18.605 | J16: 19.64 | K16: =I16/J16-1 | L16: 19.6799 | M16: 18.3719 | N16: 18.68725 | O16: =I16/N16-1 | P16: 17.2327 | Q16: =I16/P16-1 | R16: 18.1225 | S16: =N16/R16-1 | T16: 22.98 | U16: 2026-09-18 | V16: 6 | W16: =I16/T16-1 | X16: 0.27486061 | Y16: 2026-09-18 | Z16: -0.016875142 | AA16: 2026-07-29 | AB16: 0.80376766 | AC16: 0.029607084 | AD16: 0.46036107 | AE16: -0.031494014 | AG16: 0.85502531 | AH16: 0.96456978 | AI16: 0.54663774 | AK16: 2個月 | AL16: =(AG16>=0.9)*(AC16>0)+(AH16>=0.9)*(AD16>0)+(AI16>=0.9)*(AE16>0)+IF(AJ16="",0,(AJ16>=0.9)*(AF16>0)) | AM16: 0.5189582 | AN16: 0.81499066 | AO16: 0.13298269 | AP16: =MAX(0,MIN(1,(AM16-1.2)/(0.6-1.2))) | AQ16: =MAX(0,MIN(1,(ABS(O16)-0.03)/(0-0.03))) | AR16: =MAX(0,MIN(1,S16/0.03)) | AS16: =MAX(0,MIN(1,(-W16-0.3)/(0.15-0.3))) | AT16: =0.5*IF(L16>M16,(I16-M16)/(L16-M16),0.5)+0.5*(I16>=N16) | AU16: =MAX(0,MIN(1,(AN16-1.3)/(0.7-1.3))) | AV16: =100*(0.2*AG16+0.2*AH16+0.3*AI16+IF(AJ16="",0,0.3*AJ16))/(0.7+IF(AJ16="",0,0.3)) | AW16: =100*(0.25*AP16+0.2*AQ16+0.15*AR16+0.15*AS16+0.15*AT16+0.1*AU16) | AX16: =0.5*AV16+0.5*AW16 | AY16: =0.4*AV16+0.4*AW16+0.2*(AL16/4*100) | BA16: 18/18 | BC16: 0.00032
A17: =COUNTIF($AY$2:$AY$22,">"&AY17)+1 | B17: LPG | C17: Dorian LPG Ltd. | D17: NYSE | E17: 非必需消費 | F17: Marine Transportation | G17: 2.286 | H17: 中型 | I17: 54.38 | J17: 53.43 | K17: =I17/J17-1 | L17: 55.77 | M17: 53.81 | N17: 54.5115 | O17: =I17/N17-1 | P17: 49.698 | Q17: =I17/P17-1 | R17: 53.537 | S17: =N17/R17-1 | T17: 58.31 | U17: 2026-09-17 | V17: 7 | W17: =I17/T17-1 | X17: 0.1223162 | Y17: 2026-09-04 | Z17: -0.03116163 | AA17: 2026-06-30 | AB17: 0.67653824 | AC17: 0.10349026 | AD17: 0.18993435 | AE17: 0.5431328 | AF17: 0.63058471 | AG17: 0.9428778 | AH17: 0.87165582 | AI17: 0.9725235 | AJ17: 0.89129636 | AK17: 1個月、3個月 | AL17: =(AG17>=0.9)*(AC17>0)+(AH17>=0.9)*(AD17>0)+(AI17>=0.9)*(AE17>0)+IF(AJ17="",0,(AJ17>=0.9)*(AF17>0)) | AM17: 1.1939557 | AN17: 1.1541003 | AO17: 0.038262491 | AP17: =MAX(0,MIN(1,(AM17-1.2)/(0.6-1.2))) | AQ17: =MAX(0,MIN(1,(ABS(O17)-0.03)/(0-0.03))) | AR17: =MAX(0,MIN(1,S17/0.03)) | AS17: =MAX(0,MIN(1,(-W17-0.3)/(0.15-0.3))) | AT17: =0.5*IF(L17>M17,(I17-M17)/(L17-M17),0.5)+0.5*(I17>=N17) | AU17: =MAX(0,MIN(1,(AN17-1.3)/(0.7-1.3))) | AV17: =100*(0.2*AG17+0.2*AH17+0.3*AI17+IF(AJ17="",0,0.3*AJ17))/(0.7+IF(AJ17="",0,0.3)) | AW17: =100*(0.25*AP17+0.2*AQ17+0.15*AR17+0.15*AS17+0.15*AT17+0.1*AU17) | AX17: =0.5*AV17+0.5*AW17 | AY17: =0.4*AV17+0.4*AW17+0.2*(AL17/4*100) | AZ17: 25 | BA17: 18/18 | BC17: 0
A18: =COUNTIF($AY$2:$AY$22,">"&AY18)+1 | B18: DC | C18: Dakota Gold Corp. | D18: AMEX | E18: 原材料 | F18: Metal Mining | G18: 0.887 | H18: 小型 | I18: 6.18 | J18: 6.61 | K18: =I18/J18-1 | L18: 6.44 | M18: 6.15 | N18: 6.1275 | O18: =I18/N18-1 | P18: 5.7566 | Q18: =I18/P18-1 | R18: 6.0225 | S18: =N18/R18-1 | T18: 6.9 | U18: 2026-09-22 | V18: 4 | W18: =I18/T18-1 | X18: 0.13889577 | Y18: 2026-09-22 | Z18: 0.0036719706 | AA18: 2026-06-25 | AB18: 0.69117647 | AC18: -0.0096153846 | AD18: 0.34056399 | AE18: 0.45070423 | AF18: 0.35526316 | AG18: 0.74150398 | AH18: 0.93926247 | AI18: 0.95878525 | AJ18: 0.7884686 | AK18: 2個月、3個月 | AL18: =(AG18>=0.9)*(AC18>0)+(AH18>=0.9)*(AD18>0)+(AI18>=0.9)*(AE18>0)+IF(AJ18="",0,(AJ18>=0.9)*(AF18>0)) | AM18: 1.0793049 | AN18: 1.3275569 | AO18: 0.056842349 | AP18: =MAX(0,MIN(1,(AM18-1.2)/(0.6-1.2))) | AQ18: =MAX(0,MIN(1,(ABS(O18)-0.03)/(0-0.03))) | AR18: =MAX(0,MIN(1,S18/0.03)) | AS18: =MAX(0,MIN(1,(-W18-0.3)/(0.15-0.3))) | AT18: =0.5*IF(L18>M18,(I18-M18)/(L18-M18),0.5)+0.5*(I18>=N18) | AU18: =MAX(0,MIN(1,(AN18-1.3)/(0.7-1.3))) | AV18: =100*(0.2*AG18+0.2*AH18+0.3*AI18+IF(AJ18="",0,0.3*AJ18))/(0.7+IF(AJ18="",0,0.3)) | AW18: =100*(0.25*AP18+0.2*AQ18+0.15*AR18+0.15*AS18+0.15*AT18+0.1*AU18) | AX18: =0.5*AV18+0.5*AW18 | AY18: =0.4*AV18+0.4*AW18+0.2*(AL18/4*100) | BA18: 17/18 | BC18: 0
A19: =COUNTIF($AY$2:$AY$22,">"&AY19)+1 | B19: BBY | C19: Best Buy Co. Inc. | D19: NYSE | E19: 非必需消費 | F19: Consumer Electronics/Video Chains | G19: 18.982 | H19: 大型 | I19: 89.96 | J19: 90.51 | K19: =I19/J19-1 | L19: 90.445 | M19: 88.12 | N19: 90.1015 | O19: =I19/N19-1 | P19: 87.3974 | Q19: =I19/P19-1 | R19: 88.5575 | S19: =N19/R19-1 | T19: 94.83 | U19: 2026-09-14 | V19: 10 | W19: =I19/T19-1 | X19: 0.091022049 | Y19: 2026-09-14 | Z19: -0.021991865 | AA19: 2026-06-17 | AB19: 0.29726402 | AC19: 0.076591671 | AD19: -0.0023289342 | AE19: 0.15868109 | AF19: 0.42838997 | AG19: 0.92480116 | AH19: 0.63159798 | AI19: 0.85466377 | AJ19: 0.83290488 | AK19: 1個月 | AL19: =(AG19>=0.9)*(AC19>0)+(AH19>=0.9)*(AD19>0)+(AI19>=0.9)*(AE19>0)+IF(AJ19="",0,(AJ19>=0.9)*(AF19>0)) | AM19: 0.82837267 | AN19: 1.0718996 | AO19: 0.033221114 | AP19: =MAX(0,MIN(1,(AM19-1.2)/(0.6-1.2))) | AQ19: =MAX(0,MIN(1,(ABS(O19)-0.03)/(0-0.03))) | AR19: =MAX(0,MIN(1,S19/0.03)) | AS19: =MAX(0,MIN(1,(-W19-0.3)/(0.15-0.3))) | AT19: =0.5*IF(L19>M19,(I19-M19)/(L19-M19),0.5)+0.5*(I19>=N19) | AU19: =MAX(0,MIN(1,(AN19-1.3)/(0.7-1.3))) | AV19: =100*(0.2*AG19+0.2*AH19+0.3*AI19+IF(AJ19="",0,0.3*AJ19))/(0.7+IF(AJ19="",0,0.3)) | AW19: =100*(0.25*AP19+0.2*AQ19+0.15*AR19+0.15*AS19+0.15*AT19+0.1*AU19) | AX19: =0.5*AV19+0.5*AW19 | AY19: =0.4*AV19+0.4*AW19+0.2*(AL19/4*100) | BA19: 16/18 | BC19: 0
A20: =COUNTIF($AY$2:$AY$22,">"&AY20)+1 | B20: TH | C20: Target Hospitality Corp. | D20: NASDAQ | E20: 非必需消費 | F20: Hotels/Resorts | G20: 2.05 | H20: 中型 | I20: 19.3 | J20: 20.58 | K20: =I20/J20-1 | L20: 20.75 | M20: 18.94 | N20: 19.6935 | O20: =I20/N20-1 | P20: 17.8276 | Q20: =I20/P20-1 | R20: 18.983 | S20: =N20/R20-1 | T20: 21.45 | U20: 2026-09-24 | V20: 2 | W20: =I20/T20-1 | X20: 0.1334061 | Y20: 2026-09-08 | Z20: -0.038261355 | AA20: 2026-07-29 | AB20: 0.49373259 | AC20: 0.017932489 | AD20: 0.34401114 | AE20: -0.055772994 | AF20: 1.0083247 | AG20: 0.83550253 | AH20: 0.93998554 | AI20: 0.4967462 | AJ20: 0.94638267 | AK20: 2個月、6個月 | AL20: =(AG20>=0.9)*(AC20>0)+(AH20>=0.9)*(AD20>0)+(AI20>=0.9)*(AE20>0)+IF(AJ20="",0,(AJ20>=0.9)*(AF20>0)) | AM20: 0.81372062 | AN20: 1.14957 | AO20: 0.050399704 | AP20: =MAX(0,MIN(1,(AM20-1.2)/(0.6-1.2))) | AQ20: =MAX(0,MIN(1,(ABS(O20)-0.03)/(0-0.03))) | AR20: =MAX(0,MIN(1,S20/0.03)) | AS20: =MAX(0,MIN(1,(-W20-0.3)/(0.15-0.3))) | AT20: =0.5*IF(L20>M20,(I20-M20)/(L20-M20),0.5)+0.5*(I20>=N20) | AU20: =MAX(0,MIN(1,(AN20-1.3)/(0.7-1.3))) | AV20: =100*(0.2*AG20+0.2*AH20+0.3*AI20+IF(AJ20="",0,0.3*AJ20))/(0.7+IF(AJ20="",0,0.3)) | AW20: =100*(0.25*AP20+0.2*AQ20+0.15*AR20+0.15*AS20+0.15*AT20+0.1*AU20) | AX20: =0.5*AV20+0.5*AW20 | AY20: =0.4*AV20+0.4*AW20+0.2*(AL20/4*100) | BA20: 17/18 | BC20: 0
A21: =COUNTIF($AY$2:$AY$22,">"&AY21)+1 | B21: DINO | C21: HF Sinclair Corporation | D21: NYSE | E21: 能源 | F21: Natural Gas Distribution | G21: 18.991 | H21: 大型 | I21: 106.2 | J21: 106.82 | K21: =I21/J21-1 | L21: 108.035 | M21: 105 | N21: 108.0895 | O21: =I21/N21-1 | P21: 97.8316 | Q21: =I21/P21-1 | R21: 105.59 | S21: =N21/R21-1 | T21: 116.62 | U21: 2026-09-17 | V21: 7 | W21: =I21/T21-1 | X21: 0.1299748 | Y21: 2026-09-02 | Z21: -0.043288637 | AA21: 2026-06-18 | AB21: 0.80806202 | AC21: 0.094845361 | AD21: 0.18 | AE21: 0.49978817 | AF21: 0.66614371 | AG21: 0.93781634 | AH21: 0.86767896 | AI21: 0.96746204 | AJ21: 0.89827396 | AK21: 1個月、3個月 | AL21: =(AG21>=0.9)*(AC21>0)+(AH21>=0.9)*(AD21>0)+(AI21>=0.9)*(AE21>0)+IF(AJ21="",0,(AJ21>=0.9)*(AF21>0)) | AM21: 1.5413936 | AN21: 1.0091404 | AO21: 0.048106672 | AP21: =MAX(0,MIN(1,(AM21-1.2)/(0.6-1.2))) | AQ21: =MAX(0,MIN(1,(ABS(O21)-0.03)/(0-0.03))) | AR21: =MAX(0,MIN(1,S21/0.03)) | AS21: =MAX(0,MIN(1,(-W21-0.3)/(0.15-0.3))) | AT21: =0.5*IF(L21>M21,(I21-M21)/(L21-M21),0.5)+0.5*(I21>=N21) | AU21: =MAX(0,MIN(1,(AN21-1.3)/(0.7-1.3))) | AV21: =100*(0.2*AG21+0.2*AH21+0.3*AI21+IF(AJ21="",0,0.3*AJ21))/(0.7+IF(AJ21="",0,0.3)) | AW21: =100*(0.25*AP21+0.2*AQ21+0.15*AR21+0.15*AS21+0.15*AT21+0.1*AU21) | AX21: =0.5*AV21+0.5*AW21 | AY21: =0.4*AV21+0.4*AW21+0.2*(AL21/4*100) | AZ21: 15 | BA21: 18/18 | BB21: 同名單入面 VLO、MPC、PSX 同向（21 日相關系數中位數 +0.91，名單其餘 +0.07）：當一個交易睇 | BC21: 0
A22: =COUNTIF($AY$2:$AY$22,">"&AY22)+1 | B22: PSX | C22: Phillips 66 | D22: NYSE | E22: 能源 | F22: Integrated oil Companies | G22: 102.05 | H22: 大型 | I22: 253.55 | J22: 255.75 | K22: =I22/J22-1 | L22: 259.11 | M22: 251.64 | N22: 258.824 | O22: =I22/N22-1 | P22: 236.7064 | Q22: =I22/P22-1 | R22: 255.148 | S22: =N22/R22-1 | T22: 274.21 | U22: 2026-09-17 | V22: 7 | W22: =I22/T22-1 | X22: 0.089458423 | Y22: 2026-08-24 | Z22: -0.03196089 | AA22: 2026-06-18 | AB22: 0.6504755 | AC22: 0.057295359 | AD22: 0.22600455 | AE22: 0.4567653 | AF22: 0.34666454 | AG22: 0.90491685 | AH22: 0.89515546 | AI22: 0.96167751 | AJ22: 0.78222549 | AK22: 1個月、3個月 | AL22: =(AG22>=0.9)*(AC22>0)+(AH22>=0.9)*(AD22>0)+(AI22>=0.9)*(AE22>0)+IF(AJ22="",0,(AJ22>=0.9)*(AF22>0)) | AM22: 1.6519196 | AN22: 1.0650956 | AO22: 0.036498859 | AP22: =MAX(0,MIN(1,(AM22-1.2)/(0.6-1.2))) | AQ22: =MAX(0,MIN(1,(ABS(O22)-0.03)/(0-0.03))) | AR22: =MAX(0,MIN(1,S22/0.03)) | AS22: =MAX(0,MIN(1,(-W22-0.3)/(0.15-0.3))) | AT22: =0.5*IF(L22>M22,(I22-M22)/(L22-M22),0.5)+0.5*(I22>=N22) | AU22: =MAX(0,MIN(1,(AN22-1.3)/(0.7-1.3))) | AV22: =100*(0.2*AG22+0.2*AH22+0.3*AI22+IF(AJ22="",0,0.3*AJ22))/(0.7+IF(AJ22="",0,0.3)) | AW22: =100*(0.25*AP22+0.2*AQ22+0.15*AR22+0.15*AS22+0.15*AT22+0.1*AU22) | AX22: =0.5*AV22+0.5*AW22 | AY22: =0.4*AV22+0.4*AW22+0.2*(AL22/4*100) | AZ22: 24 | BA22: 16/18 | BB22: 同名單入面 VLO、MPC、DINO 同向（21 日相關系數中位數 +0.91，名單其餘 +0.07）：當一個交易睇 | BC22: 0

Sheet 1個月動能
A1: 1個月動能（21 個交易日回報排全體合資格股票前 10%）＋ 回到上升中嘅 20MA · 以綜合分數排序 · 2026-09-28 收市
A3: 頁內排名 | B3: 總表排名 | C3: 代號 | D3: 公司 | E3: 板塊 | F3: 市值組 | G3: 收市價 | H3: 距MA20% | I3: 距高位% | J3: 1個月回報 | K3: 1個月百分位 | L3: 覆蓋度 | M3: 動能分數 | N3: 回調質素 | O3: 綜合分數 | P3: 審視標記
A4: =COUNTIF($O$4:$O$17,">"&O4)+1 | B4: ='總表'!A2 | C4: IRD | D4: ='總表'!C2 | E4: ='總表'!E2 | F4: ='總表'!H2 | G4: ='總表'!I2 | H4: ='總表'!O2 | I4: ='總表'!W2 | J4: ='總表'!AC2 | K4: ='總表'!AG2 | L4: ='總表'!AL2 | M4: ='總表'!AV2 | N4: ='總表'!AW2 | O4: ='總表'!AX2 | P4: ='總表'!BB2
A5: =COUNTIF($O$4:$O$17,">"&O5)+1 | B5: ='總表'!A6 | C5: TITN | D5: ='總表'!C6 | E5: ='總表'!E6 | F5: ='總表'!H6 | G5: ='總表'!I6 | H5: ='總表'!O6 | I5: ='總表'!W6 | J5: ='總表'!AC6 | K5: ='總表'!AG6 | L5: ='總表'!AL6 | M5: ='總表'!AV6 | N5: ='總表'!AW6 | O5: ='總表'!AX6 | P5: ='總表'!BB6
A6: =COUNTIF($O$4:$O$17,">"&O6)+1 | B6: ='總表'!A3 | C6: TTRX | D6: ='總表'!C3 | E6: ='總表'!E3 | F6: ='總表'!H3 | G6: ='總表'!I3 | H6: ='總表'!O3 | I6: ='總表'!W3 | J6: ='總表'!AC3 | K6: ='總表'!AG3 | L6: ='總表'!AL3 | M6: ='總表'!AV3 | N6: ='總表'!AW3 | O6: ='總表'!AX3 | P6: ='總表'!BB3
A7: =COUNTIF($O$4:$O$17,">"&O7)+1 | B7: ='總表'!A4 | C7: DELL | D7: ='總表'!C4 | E7: ='總表'!E4 | F7: ='總表'!H4 | G7: ='總表'!I4 | H7: ='總表'!O4 | I7: ='總表'!W4 | J7: ='總表'!AC4 | K7: ='總表'!AG4 | L7: ='總表'!AL4 | M7: ='總表'!AV4 | N7: ='總表'!AW4 | O7: ='總表'!AX4 | P7: ='總表'!BB4
A8: =COUNTIF($O$4:$O$17,">"&O8)+1 | B8: ='總表'!A9 | C8: DHX | D8: ='總表'!C9 | E8: ='總表'!E9 | F8: ='總表'!H9 | G8: ='總表'!I9 | H8: ='總表'!O9 | I8: ='總表'!W9 | J8: ='總表'!AC9 | K8: ='總表'!AG9 | L8: ='總表'!AL9 | M8: ='總表'!AV9 | N8: ='總表'!AW9 | O8: ='總表'!AX9 | P8: ='總表'!BB9
A9: =COUNTIF($O$4:$O$17,">"&O9)+1 | B9: ='總表'!A5 | C9: PLSE | D9: ='總表'!C5 | E9: ='總表'!E5 | F9: ='總表'!H5 | G9: ='總表'!I5 | H9: ='總表'!O5 | I9: ='總表'!W5 | J9: ='總表'!AC5 | K9: ='總表'!AG5 | L9: ='總表'!AL5 | M9: ='總表'!AV5 | N9: ='總表'!AW5 | O9: ='總表'!AX5 | P9: ='總表'!BB5
A10: =COUNTIF($O$4:$O$17,">"&O10)+1 | B10: ='總表'!A19 | C10: BBY | D10: ='總表'!C19 | E10: ='總表'!E19 | F10: ='總表'!H19 | G10: ='總表'!I19 | H10: ='總表'!O19 | I10: ='總表'!W19 | J10: ='總表'!AC19 | K10: ='總表'!AG19 | L10: ='總表'!AL19 | M10: ='總表'!AV19 | N10: ='總表'!AW19 | O10: ='總表'!AX19 | P10: ='總表'!BB19
A11: =COUNTIF($O$4:$O$17,">"&O11)+1 | B11: ='總表'!A15 | C11: IBTA | D11: ='總表'!C15 | E11: ='總表'!E15 | F11: ='總表'!H15 | G11: ='總表'!I15 | H11: ='總表'!O15 | I11: ='總表'!W15 | J11: ='總表'!AC15 | K11: ='總表'!AG15 | L11: ='總表'!AL15 | M11: ='總表'!AV15 | N11: ='總表'!AW15 | O11: ='總表'!AX15 | P11: ='總表'!BB15
A12: =COUNTIF($O$4:$O$17,">"&O12)+1 | B12: ='總表'!A10 | C12: VLO | D12: ='總表'!C10 | E12: ='總表'!E10 | F12: ='總表'!H10 | G12: ='總表'!I10 | H12: ='總表'!O10 | I12: ='總表'!W10 | J12: ='總表'!AC10 | K12: ='總表'!AG10 | L12: ='總表'!AL10 | M12: ='總表'!AV10 | N12: ='總表'!AW10 | O12: ='總表'!AX10 | P12: ='總表'!BB10
A13: =COUNTIF($O$4:$O$17,">"&O13)+1 | B13: ='總表'!A17 | C13: LPG | D13: ='總表'!C17 | E13: ='總表'!E17 | F13: ='總表'!H17 | G13: ='總表'!I17 | H13: ='總表'!O17 | I13: ='總表'!W17 | J13: ='總表'!AC17 | K13: ='總表'!AG17 | L13: ='總表'!AL17 | M13: ='總表'!AV17 | N13: ='總表'!AW17 | O13: ='總表'!AX17 | P13: ='總表'!BB17
A14: =COUNTIF($O$4:$O$17,">"&O14)+1 | B14: ='總表'!A21 | C14: DINO | D14: ='總表'!C21 | E14: ='總表'!E21 | F14: ='總表'!H21 | G14: ='總表'!I21 | H14: ='總表'!O21 | I14: ='總表'!W21 | J14: ='總表'!AC21 | K14: ='總表'!AG21 | L14: ='總表'!AL21 | M14: ='總表'!AV21 | N14: ='總表'!AW21 | O14: ='總表'!AX21 | P14: ='總表'!BB21
A15: =COUNTIF($O$4:$O$17,">"&O15)+1 | B15: ='總表'!A13 | C15: MPC | D15: ='總表'!C13 | E15: ='總表'!E13 | F15: ='總表'!H13 | G15: ='總表'!I13 | H15: ='總表'!O13 | I15: ='總表'!W13 | J15: ='總表'!AC13 | K15: ='總表'!AG13 | L15: ='總表'!AL13 | M15: ='總表'!AV13 | N15: ='總表'!AW13 | O15: ='總表'!AX13 | P15: ='總表'!BB13
A16: =COUNTIF($O$4:$O$17,">"&O16)+1 | B16: ='總表'!A14 | C16: KGEI | D16: ='總表'!C14 | E16: ='總表'!E14 | F16: ='總表'!H14 | G16: ='總表'!I14 | H16: ='總表'!O14 | I16: ='總表'!W14 | J16: ='總表'!AC14 | K16: ='總表'!AG14 | L16: ='總表'!AL14 | M16: ='總表'!AV14 | N16: ='總表'!AW14 | O16: ='總表'!AX14 | P16: ='總表'!BB14
A17: =COUNTIF($O$4:$O$17,">"&O17)+1 | B17: ='總表'!A22 | C17: PSX | D17: ='總表'!C22 | E17: ='總表'!E22 | F17: ='總表'!H22 | G17: ='總表'!I22 | H17: ='總表'!O22 | I17: ='總表'!W22 | J17: ='總表'!AC22 | K17: ='總表'!AG22 | L17: ='總表'!AL22 | M17: ='總表'!AV22 | N17: ='總表'!AW22 | O17: ='總表'!AX22 | P17: ='總表'!BB22

Sheet 2個月動能
A1: 2個月動能（42 個交易日回報排全體合資格股票前 10%）＋ 回到上升中嘅 20MA · 以綜合分數排序 · 2026-09-28 收市
A3: 頁內排名 | B3: 總表排名 | C3: 代號 | D3: 公司 | E3: 板塊 | F3: 市值組 | G3: 收市價 | H3: 距MA20% | I3: 距高位% | J3: 2個月回報 | K3: 2個月百分位 | L3: 覆蓋度 | M3: 動能分數 | N3: 回調質素 | O3: 綜合分數 | P3: 審視標記
A4: =COUNTIF($O$4:$O$18,">"&O4)+1 | B4: ='總表'!A2 | C4: IRD | D4: ='總表'!C2 | E4: ='總表'!E2 | F4: ='總表'!H2 | G4: ='總表'!I2 | H4: ='總表'!O2 | I4: ='總表'!W2 | J4: ='總表'!AD2 | K4: ='總表'!AH2 | L4: ='總表'!AL2 | M4: ='總表'!AV2 | N4: ='總表'!AW2 | O4: ='總表'!AX2 | P4: ='總表'!BB2
A5: =COUNTIF($O$4:$O$18,">"&O5)+1 | B5: ='總表'!A6 | C5: TITN | D5: ='總表'!C6 | E5: ='總表'!E6 | F5: ='總表'!H6 | G5: ='總表'!I6 | H5: ='總表'!O6 | I5: ='總表'!W6 | J5: ='總表'!AD6 | K5: ='總表'!AH6 | L5: ='總表'!AL6 | M5: ='總表'!AV6 | N5: ='總表'!AW6 | O5: ='總表'!AX6 | P5: ='總表'!BB6
A6: =COUNTIF($O$4:$O$18,">"&O6)+1 | B6: ='總表'!A3 | C6: TTRX | D6: ='總表'!C3 | E6: ='總表'!E3 | F6: ='總表'!H3 | G6: ='總表'!I3 | H6: ='總表'!O3 | I6: ='總表'!W3 | J6: ='總表'!AD3 | K6: ='總表'!AH3 | L6: ='總表'!AL3 | M6: ='總表'!AV3 | N6: ='總表'!AW3 | O6: ='總表'!AX3 | P6: ='總表'!BB3
A7: =COUNTIF($O$4:$O$18,">"&O7)+1 | B7: ='總表'!A4 | C7: DELL | D7: ='總表'!C4 | E7: ='總表'!E4 | F7: ='總表'!H4 | G7: ='總表'!I4 | H7: ='總表'!O4 | I7: ='總表'!W4 | J7: ='總表'!AD4 | K7: ='總表'!AH4 | L7: ='總表'!AL4 | M7: ='總表'!AV4 | N7: ='總表'!AW4 | O7: ='總表'!AX4 | P7: ='總表'!BB4
A8: =COUNTIF($O$4:$O$18,">"&O8)+1 | B8: ='總表'!A5 | C8: PLSE | D8: ='總表'!C5 | E8: ='總表'!E5 | F8: ='總表'!H5 | G8: ='總表'!I5 | H8: ='總表'!O5 | I8: ='總表'!W5 | J8: ='總表'!AD5 | K8: ='總表'!AH5 | L8: ='總表'!AL5 | M8: ='總表'!AV5 | N8: ='總表'!AW5 | O8: ='總表'!AX5 | P8: ='總表'!BB5
A9: =COUNTIF($O$4:$O$18,">"&O9)+1 | B9: ='總表'!A7 | C9: ESTC | D9: ='總表'!C7 | E9: ='總表'!E7 | F9: ='總表'!H7 | G9: ='總表'!I7 | H9: ='總表'!O7 | I9: ='總表'!W7 | J9: ='總表'!AD7 | K9: ='總表'!AH7 | L9: ='總表'!AL7 | M9: ='總表'!AV7 | N9: ='總表'!AW7 | O9: ='總表'!AX7 | P9: ='總表'!BB7
A10: =COUNTIF($O$4:$O$18,">"&O10)+1 | B10: ='總表'!A16 | C10: ELMT | D10: ='總表'!C16 | E10: ='總表'!E16 | F10: ='總表'!H16 | G10: ='總表'!I16 | H10: ='總表'!O16 | I10: ='總表'!W16 | J10: ='總表'!AD16 | K10: ='總表'!AH16 | L10: ='總表'!AL16 | M10: ='總表'!AV16 | N10: ='總表'!AW16 | O10: ='總表'!AX16 | P10: ='總表'!BB16
A11: =COUNTIF($O$4:$O$18,">"&O11)+1 | B11: ='總表'!A8 | C11: FIVN | D11: ='總表'!C8 | E11: ='總表'!E8 | F11: ='總表'!H8 | G11: ='總表'!I8 | H11: ='總表'!O8 | I11: ='總表'!W8 | J11: ='總表'!AD8 | K11: ='總表'!AH8 | L11: ='總表'!AL8 | M11: ='總表'!AV8 | N11: ='總表'!AW8 | O11: ='總表'!AX8 | P11: ='總表'!BB8
A12: =COUNTIF($O$4:$O$18,">"&O12)+1 | B12: ='總表'!A15 | C12: IBTA | D12: ='總表'!C15 | E12: ='總表'!E15 | F12: ='總表'!H15 | G12: ='總表'!I15 | H12: ='總表'!O15 | I12: ='總表'!W15 | J12: ='總表'!AD15 | K12: ='總表'!AH15 | L12: ='總表'!AL15 | M12: ='總表'!AV15 | N12: ='總表'!AW15 | O12: ='總表'!AX15 | P12: ='總表'!BB15
A13: =COUNTIF($O$4:$O$18,">"&O13)+1 | B13: ='總表'!A10 | C13: VLO | D13: ='總表'!C10 | E13: ='總表'!E10 | F13: ='總表'!H10 | G13: ='總表'!I10 | H13: ='總表'!O10 | I13: ='總表'!W10 | J13: ='總表'!AD10 | K13: ='總表'!AH10 | L13: ='總表'!AL10 | M13: ='總表'!AV10 | N13: ='總表'!AW10 | O13: ='總表'!AX10 | P13: ='總表'!BB10
A14: =COUNTIF($O$4:$O$18,">"&O14)+1 | B14: ='總表'!A11 | C14: PURR | D14: ='總表'!C11 | E14: ='總表'!E11 | F14: ='總表'!H11 | G14: ='總表'!I11 | H14: ='總表'!O11 | I14: ='總表'!W11 | J14: ='總表'!AD11 | K14: ='總表'!AH11 | L14: ='總表'!AL11 | M14: ='總表'!AV11 | N14: ='總表'!AW11 | O14: ='總表'!AX11 | P14: ='總表'!BB11
A15: =COUNTIF($O$4:$O$18,">"&O15)+1 | B15: ='總表'!A18 | C15: DC | D15: ='總表'!C18 | E15: ='總表'!E18 | F15: ='總表'!H18 | G15: ='總表'!I18 | H15: ='總表'!O18 | I15: ='總表'!W18 | J15: ='總表'!AD18 | K15: ='總表'!AH18 | L15: ='總表'!AL18 | M15: ='總表'!AV18 | N15: ='總表'!AW18 | O15: ='總表'!AX18 | P15: ='總表'!BB18
A16: =COUNTIF($O$4:$O$18,">"&O16)+1 | B16: ='總表'!A20 | C16: TH | D16: ='總表'!C20 | E16: ='總表'!E20 | F16: ='總表'!H20 | G16: ='總表'!I20 | H16: ='總表'!O20 | I16: ='總表'!W20 | J16: ='總表'!AD20 | K16: ='總表'!AH20 | L16: ='總表'!AL20 | M16: ='總表'!AV20 | N16: ='總表'!AW20 | O16: ='總表'!AX20 | P16: ='總表'!BB20
A17: =COUNTIF($O$4:$O$18,">"&O17)+1 | B17: ='總表'!A13 | C17: MPC | D17: ='總表'!C13 | E17: ='總表'!E13 | F17: ='總表'!H13 | G17: ='總表'!I13 | H17: ='總表'!O13 | I17: ='總表'!W13 | J17: ='總表'!AD13 | K17: ='總表'!AH13 | L17: ='總表'!AL13 | M17: ='總表'!AV13 | N17: ='總表'!AW13 | O17: ='總表'!AX13 | P17: ='總表'!BB13
A18: =COUNTIF($O$4:$O$18,">"&O18)+1 | B18: ='總表'!A14 | C18: KGEI | D18: ='總表'!C14 | E18: ='總表'!E14 | F18: ='總表'!H14 | G18: ='總表'!I14 | H18: ='總表'!O14 | I18: ='總表'!W14 | J18: ='總表'!AD14 | K18: ='總表'!AH14 | L18: ='總表'!AL14 | M18: ='總表'!AV14 | N18: ='總表'!AW14 | O18: ='總表'!AX14 | P18: ='總表'!BB14

Sheet 3個月動能
A1: 3個月動能（63 個交易日回報排全體合資格股票前 10%）＋ 回到上升中嘅 20MA · 以綜合分數排序 · 2026-09-28 收市
A3: 頁內排名 | B3: 總表排名 | C3: 代號 | D3: 公司 | E3: 板塊 | F3: 市值組 | G3: 收市價 | H3: 距MA20% | I3: 距高位% | J3: 3個月回報 | K3: 3個月百分位 | L3: 覆蓋度 | M3: 動能分數 | N3: 回調質素 | O3: 綜合分數 | P3: 審視標記
A4: =COUNTIF($O$4:$O$18,">"&O4)+1 | B4: ='總表'!A2 | C4: IRD | D4: ='總表'!C2 | E4: ='總表'!E2 | F4: ='總表'!H2 | G4: ='總表'!I2 | H4: ='總表'!O2 | I4: ='總表'!W2 | J4: ='總表'!AE2 | K4: ='總表'!AI2 | L4: ='總表'!AL2 | M4: ='總表'!AV2 | N4: ='總表'!AW2 | O4: ='總表'!AX2 | P4: ='總表'!BB2
A5: =COUNTIF($O$4:$O$18,">"&O5)+1 | B5: ='總表'!A3 | C5: TTRX | D5: ='總表'!C3 | E5: ='總表'!E3 | F5: ='總表'!H3 | G5: ='總表'!I3 | H5: ='總表'!O3 | I5: ='總表'!W3 | J5: ='總表'!AE3 | K5: ='總表'!AI3 | L5: ='總表'!AL3 | M5: ='總表'!AV3 | N5: ='總表'!AW3 | O5: ='總表'!AX3 | P5: ='總表'!BB3
A6: =COUNTIF($O$4:$O$18,">"&O6)+1 | B6: ='總表'!A4 | C6: DELL | D6: ='總表'!C4 | E6: ='總表'!E4 | F6: ='總表'!H4 | G6: ='總表'!I4 | H6: ='總表'!O4 | I6: ='總表'!W4 | J6: ='總表'!AE4 | K6: ='總表'!AI4 | L6: ='總表'!AL4 | M6: ='總表'!AV4 | N6: ='總表'!AW4 | O6: ='總表'!AX4 | P6: ='總表'!BB4
A7: =COUNTIF($O$4:$O$18,">"&O7)+1 | B7: ='總表'!A5 | C7: PLSE | D7: ='總表'!C5 | E7: ='總表'!E5 | F7: ='總表'!H5 | G7: ='總表'!I5 | H7: ='總表'!O5 | I7: ='總表'!W5 | J7: ='總表'!AE5 | K7: ='總表'!AI5 | L7: ='總表'!AL5 | M7: ='總表'!AV5 | N7: ='總表'!AW5 | O7: ='總表'!AX5 | P7: ='總表'!BB5
A8: =COUNTIF($O$4:$O$18,">"&O8)+1 | B8: ='總表'!A7 | C8: ESTC | D8: ='總表'!C7 | E8: ='總表'!E7 | F8: ='總表'!H7 | G8: ='總表'!I7 | H8: ='總表'!O7 | I8: ='總表'!W7 | J8: ='總表'!AE7 | K8: ='總表'!AI7 | L8: ='總表'!AL7 | M8: ='總表'!AV7 | N8: ='總表'!AW7 | O8: ='總表'!AX7 | P8: ='總表'!BB7
A9: =COUNTIF($O$4:$O$18,">"&O9)+1 | B9: ='總表'!A8 | C9: FIVN | D9: ='總表'!C8 | E9: ='總表'!E8 | F9: ='總表'!H8 | G9: ='總表'!I8 | H9: ='總表'!O8 | I9: ='總表'!W8 | J9: ='總表'!AE8 | K9: ='總表'!AI8 | L9: ='總表'!AL8 | M9: ='總表'!AV8 | N9: ='總表'!AW8 | O9: ='總表'!AX8 | P9: ='總表'!BB8
A10: =COUNTIF($O$4:$O$18,">"&O10)+1 | B10: ='總表'!A12 | C10: SNOW | D10: ='總表'!C12 | E10: ='總表'!E12 | F10: ='總表'!H12 | G10: ='總表'!I12 | H10: ='總表'!O12 | I10: ='總表'!W12 | J10: ='總表'!AE12 | K10: ='總表'!AI12 | L10: ='總表'!AL12 | M10: ='總表'!AV12 | N10: ='總表'!AW12 | O10: ='總表'!AX12 | P10: ='總表'!BB12
A11: =COUNTIF($O$4:$O$18,">"&O11)+1 | B11: ='總表'!A10 | C11: VLO | D11: ='總表'!C10 | E11: ='總表'!E10 | F11: ='總表'!H10 | G11: ='總表'!I10 | H11: ='總表'!O10 | I11: ='總表'!W10 | J11: ='總表'!AE10 | K11: ='總表'!AI10 | L11: ='總表'!AL10 | M11: ='總表'!AV10 | N11: ='總表'!AW10 | O11: ='總表'!AX10 | P11: ='總表'!BB10
A12: =COUNTIF($O$4:$O$18,">"&O12)+1 | B12: ='總表'!A11 | C12: PURR | D12: ='總表'!C11 | E12: ='總表'!E11 | F12: ='總表'!H11 | G12: ='總表'!I11 | H12: ='總表'!O11 | I12: ='總表'!W11 | J12: ='總表'!AE11 | K12: ='總表'!AI11 | L12: ='總表'!AL11 | M12: ='總表'!AV11 | N12: ='總表'!AW11 | O12: ='總表'!AX11 | P12: ='總表'!BB11
A13: =COUNTIF($O$4:$O$18,">"&O13)+1 | B13: ='總表'!A17 | C13: LPG | D13: ='總表'!C17 | E13: ='總表'!E17 | F13: ='總表'!H17 | G13: ='總表'!I17 | H13: ='總表'!O17 | I13: ='總表'!W17 | J13: ='總表'!AE17 | K13: ='總表'!AI17 | L13: ='總表'!AL17 | M13: ='總表'!AV17 | N13: ='總表'!AW17 | O13: ='總表'!AX17 | P13: ='總表'!BB17
A14: =COUNTIF($O$4:$O$18,">"&O14)+1 | B14: ='總表'!A18 | C14: DC | D14: ='總表'!C18 | E14: ='總表'!E18 | F14: ='總表'!H18 | G14: ='總表'!I18 | H14: ='總表'!O18 | I14: ='總表'!W18 | J14: ='總表'!AE18 | K14: ='總表'!AI18 | L14: ='總表'!AL18 | M14: ='總表'!AV18 | N14: ='總表'!AW18 | O14: ='總表'!AX18 | P14: ='總表'!BB18
A15: =COUNTIF($O$4:$O$18,">"&O15)+1 | B15: ='總表'!A21 | C15: DINO | D15: ='總表'!C21 | E15: ='總表'!E21 | F15: ='總表'!H21 | G15: ='總表'!I21 | H15: ='總表'!O21 | I15: ='總表'!W21 | J15: ='總表'!AE21 | K15: ='總表'!AI21 | L15: ='總表'!AL21 | M15: ='總表'!AV21 | N15: ='總表'!AW21 | O15: ='總表'!AX21 | P15: ='總表'!BB21
A16: =COUNTIF($O$4:$O$18,">"&O16)+1 | B16: ='總表'!A13 | C16: MPC | D16: ='總表'!C13 | E16: ='總表'!E13 | F16: ='總表'!H13 | G16: ='總表'!I13 | H16: ='總表'!O13 | I16: ='總表'!W13 | J16: ='總表'!AE13 | K16: ='總表'!AI13 | L16: ='總表'!AL13 | M16: ='總表'!AV13 | N16: ='總表'!AW13 | O16: ='總表'!AX13 | P16: ='總表'!BB13
A17: =COUNTIF($O$4:$O$18,">"&O17)+1 | B17: ='總表'!A14 | C17: KGEI | D17: ='總表'!C14 | E17: ='總表'!E14 | F17: ='總表'!H14 | G17: ='總表'!I14 | H17: ='總表'!O14 | I17: ='總表'!W14 | J17: ='總表'!AE14 | K17: ='總表'!AI14 | L17: ='總表'!AL14 | M17: ='總表'!AV14 | N17: ='總表'!AW14 | O17: ='總表'!AX14 | P17: ='總表'!BB14
A18: =COUNTIF($O$4:$O$18,">"&O18)+1 | B18: ='總表'!A22 | C18: PSX | D18: ='總表'!C22 | E18: ='總表'!E22 | F18: ='總表'!H22 | G18: ='總表'!I22 | H18: ='總表'!O22 | I18: ='總表'!W22 | J18: ='總表'!AE22 | K18: ='總表'!AI22 | L18: ='總表'!AL22 | M18: ='總表'!AV22 | N18: ='總表'!AW22 | O18: ='總表'!AX22 | P18: ='總表'!BB22

Sheet 6個月動能
A1: 6個月動能（126 個交易日回報排全體合資格股票前 10%）＋ 回到上升中嘅 20MA · 以綜合分數排序 · 2026-09-28 收市
A3: 頁內排名 | B3: 總表排名 | C3: 代號 | D3: 公司 | E3: 板塊 | F3: 市值組 | G3: 收市價 | H3: 距MA20% | I3: 距高位% | J3: 6個月回報 | K3: 6個月百分位 | L3: 覆蓋度 | M3: 動能分數 | N3: 回調質素 | O3: 綜合分數 | P3: 審視標記
A4: =COUNTIF($O$4:$O$12,">"&O4)+1 | B4: ='總表'!A3 | C4: TTRX | D4: ='總表'!C3 | E4: ='總表'!E3 | F4: ='總表'!H3 | G4: ='總表'!I3 | H4: ='總表'!O3 | I4: ='總表'!W3 | J4: ='總表'!AF3 | K4: ='總表'!AJ3 | L4: ='總表'!AL3 | M4: ='總表'!AV3 | N4: ='總表'!AW3 | O4: ='總表'!AX3 | P4: ='總表'!BB3
A5: =COUNTIF($O$4:$O$12,">"&O5)+1 | B5: ='總表'!A4 | C5: DELL | D5: ='總表'!C4 | E5: ='總表'!E4 | F5: ='總表'!H4 | G5: ='總表'!I4 | H5: ='總表'!O4 | I5: ='總表'!W4 | J5: ='總表'!AF4 | K5: ='總表'!AJ4 | L5: ='總表'!AL4 | M5: ='總表'!AV4 | N5: ='總表'!AW4 | O5: ='總表'!AX4 | P5: ='總表'!BB4
A6: =COUNTIF($O$4:$O$12,">"&O6)+1 | B6: ='總表'!A9 | C6: DHX | D6: ='總表'!C9 | E6: ='總表'!E9 | F6: ='總表'!H9 | G6: ='總表'!I9 | H6: ='總表'!O9 | I6: ='總表'!W9 | J6: ='總表'!AF9 | K6: ='總表'!AJ9 | L6: ='總表'!AL9 | M6: ='總表'!AV9 | N6: ='總表'!AW9 | O6: ='總表'!AX9 | P6: ='總表'!BB9
A7: =COUNTIF($O$4:$O$12,">"&O7)+1 | B7: ='總表'!A5 | C7: PLSE | D7: ='總表'!C5 | E7: ='總表'!E5 | F7: ='總表'!H5 | G7: ='總表'!I5 | H7: ='總表'!O5 | I7: ='總表'!W5 | J7: ='總表'!AF5 | K7: ='總表'!AJ5 | L7: ='總表'!AL5 | M7: ='總表'!AV5 | N7: ='總表'!AW5 | O7: ='總表'!AX5 | P7: ='總表'!BB5
A8: =COUNTIF($O$4:$O$12,">"&O8)+1 | B8: ='總表'!A7 | C8: ESTC | D8: ='總表'!C7 | E8: ='總表'!E7 | F8: ='總表'!H7 | G8: ='總表'!I7 | H8: ='總表'!O7 | I8: ='總表'!W7 | J8: ='總表'!AF7 | K8: ='總表'!AJ7 | L8: ='總表'!AL7 | M8: ='總表'!AV7 | N8: ='總表'!AW7 | O8: ='總表'!AX7 | P8: ='總表'!BB7
A9: =COUNTIF($O$4:$O$12,">"&O9)+1 | B9: ='總表'!A8 | C9: FIVN | D9: ='總表'!C8 | E9: ='總表'!E8 | F9: ='總表'!H8 | G9: ='總表'!I8 | H9: ='總表'!O8 | I9: ='總表'!W8 | J9: ='總表'!AF8 | K9: ='總表'!AJ8 | L9: ='總表'!AL8 | M9: ='總表'!AV8 | N9: ='總表'!AW8 | O9: ='總表'!AX8 | P9: ='總表'!BB8
A10: =COUNTIF($O$4:$O$12,">"&O10)+1 | B10: ='總表'!A12 | C10: SNOW | D10: ='總表'!C12 | E10: ='總表'!E12 | F10: ='總表'!H12 | G10: ='總表'!I12 | H10: ='總表'!O12 | I10: ='總表'!W12 | J10: ='總表'!AF12 | K10: ='總表'!AJ12 | L10: ='總表'!AL12 | M10: ='總表'!AV12 | N10: ='總表'!AW12 | O10: ='總表'!AX12 | P10: ='總表'!BB12
A11: =COUNTIF($O$4:$O$12,">"&O11)+1 | B11: ='總表'!A11 | C11: PURR | D11: ='總表'!C11 | E11: ='總表'!E11 | F11: ='總表'!H11 | G11: ='總表'!I11 | H11: ='總表'!O11 | I11: ='總表'!W11 | J11: ='總表'!AF11 | K11: ='總表'!AJ11 | L11: ='總表'!AL11 | M11: ='總表'!AV11 | N11: ='總表'!AW11 | O11: ='總表'!AX11 | P11: ='總表'!BB11
A12: =COUNTIF($O$4:$O$12,">"&O12)+1 | B12: ='總表'!A20 | C12: TH | D12: ='總表'!C20 | E12: ='總表'!E20 | F12: ='總表'!H20 | G12: ='總表'!I20 | H12: ='總表'!O20 | I12: ='總表'!W20 | J12: ='總表'!AF20 | K12: ='總表'!AJ20 | L12: ='總表'!AL20 | M12: ='總表'!AV20 | N12: ='總表'!AW20 | O12: ='總表'!AX20 | P12: ='總表'!BB20

Sheet 篩選規則
A1: R22.00 篩選條件：高動能 ＋ 回到上升中嘅 20MA
A3: 說明 | B3: 由 R21 起取代 R1–R20 嘅「10MA 上升＋一底高於一底」規則。股票池規則不變；池之後嘅條件全部重寫。價格改用 Yahoo 日線（開高低收量），因為「觸及 20MA」要用當日最低價，而舊序列只有收市價。數據終點 2026-09-28，共 252 個交易日（2025-09-26 起）。
C4: 門檻 | D4: 通過數目
A5: 股票池 | B5: 當日有成交、≥90 個交易日歷史、收市 ≥$2、普通股（ADR、名有 Trust 嘅銀行／REIT、BDC、MLP 保留；基金、優先股、票據剔除）、20 日成交額中位數 ≥$1M | C5: 同 R1–R20 | D5: 2767
A6: S1 趨勢 | B6: MA20 高過 5 日前；MA20 > MA50；MA50 高過 10 日前；收市 > MA50 | D6: 379
A7: S2 近期高位 | B7: 近 63 日最高收市喺 2–25 個交易日前出現，而且唔低過數據期內（2025-09-26 起、約一年即 52 周）最高收市嘅 95% | D7: 147
A8: S3 回調深度 | B8: 收市比嗰個高位低 3%–30% | D8: 79
A9: S4 曾經拉開 | B9: 近 25 日內，有一日收市高過當日 MA20 至少 8%（即係先離開咗條線，先至講得上「回到」） | D9: 58
A10: S5 回到 20MA | B10: 收市喺 MA20 嘅 -3% 至 +3% 之內；而且近 3 日有一日最低價去到當日 MA20 嘅 1.5% 之內（最低價 ≤ MA20×1.015；插穿都計） | D10: 23
A11: 動能（逐頁） | B11: 1／2／3／6 個月（21／42／63／126 個交易日）回報，喺全體合資格股票排頭 10%（百分位 ≥90%）而且係正數。形態 S1–S5 全部通過、再有至少一個時間框達標就上總表；覆蓋度 = 幾多個時間框達標（1–4） | D11: 21
A13: 各時間框分界
A14: 時間框 | B14: 合資格股票數 | C14: 中位數回報（大市） | D14: 頭 10% 分界回報 | E14: 本頁數目
A15: 1個月（21日） | B15: 2767 | C15: -0.060445875 | D15: 0.054709207 | E15: 14
A16: 2個月（42日） | B16: 2767 | C16: -0.044879306 | D16: 0.2374418 | E16: 15
A17: 3個月（63日） | B17: 2767 | C17: -0.053755523 | D17: 0.22826032 | E17: 15
A18: 6個月（126日） | B18: 2724 | C18: 0.088223204 | D18: 0.67136791 | E18: 9
A20: 評分
A21: 動能分數 | B21: 四個時間框回報百分位嘅加權平均：1個月 0.2、2個月 0.2、3個月 0.3、6個月 0.3；上市未夠 126 日嘅按有嘅時間框重新攤分權重
A22: 回調質素 | B22: 0.25 量縮 + 0.20 貼近MA20 + 0.15 MA20斜率 + 0.15 回調深度 + 0.15 企穩 + 0.10 波幅收窄；每項 0–1，線性、兩頭封頂
A23: 量縮 | B23: 高位之後嘅平均成交量 ÷ 高位前 20 日（連高位日）平均成交量：≤0.6 滿分、≥1.2 零分
A24: 貼近MA20 | B24: |收市 ÷ MA20 − 1|：0% 滿分、3% 零分
A25: MA20斜率 | B25: MA20 ÷ 5 日前 MA20 − 1：≥3% 滿分、≤0% 零分
A26: 回調深度 | B26: 距高位跌幅：≤15% 滿分、30% 零分
A27: 企穩 | B27: 0.5 × 當日收市喺當日高低區間嘅位置（收喺最高 = 1）+ 0.5 ×（收市 ≥ MA20 就 1）
A28: 波幅收窄 | B28: ATR5 ÷ ATR20：≤0.7 滿分、≥1.3 零分
A29: 綜合分數 | B29: 0.5 × 動能分數 + 0.5 × 回調質素（時間框頁排名用）
A30: 爆發潛力分數 | B30: 0.4 × 動能分數 + 0.4 × 回調質素 + 0.2 × 覆蓋度 ÷ 4 × 100（總表排名用）
A31: 欄位顏色 | B31: 藍字 = 量度值（輸入）；黑字 = 公式；橙底 = 有審視標記
A33: 同舊規則分別 | B33: R1–R20：MA（5／10 日）喺 1星期／2星期／1個月／2個月 時間框上升 ＋ 一底高於一底，以 VCP 收縮 × 底部確定性排序 —— 捉嘅係「築底後轉強」。R22.00：先要已經係強勢股（回報排頭 10%），再等佢回調到上升中嘅 20MA —— 捉嘅係「強勢股回調買位」。兩套名單重疊好少係預期之內（見「同R20對照」頁）。

Sheet 敏感度
A1: 每次只郁一個門檻，睇名單點變（基準 = 本版門檻）
A3: 門檻 | B3: 基準 | C3: 改為 | D3: 名單數目 | E3: 變動 | F3: 新增／剔走嘅代號 →
A4: 觸及容差 | B4: 0.015 | C4: 0 | D4: 19 | E4: +0 / −2 | F4: DC | G4: DELL
A5: 觸及容差 | B5: 0.015 | C5: 0.03 | D5: 22 | E5: +1 / −0 | F5: OMER
A6: 距MA20上限 | B6: 0.03 | C6: 0.02 | D6: 19 | E6: +0 / −2 | F6: FIVN | G6: TTRX
A7: 距MA20上限 | B7: 0.03 | C7: 0.05 | D7: 24 | E7: +3 / −0 | F7: NEO | G7: RNG | H7: S
A8: 距MA20下限 | B8: -0.03 | C8: -0.02 | D8: 19 | E8: +0 / −2 | F8: PSX | G8: PURR
A9: 距MA20下限 | B9: -0.03 | C9: -0.05 | D9: 28 | E9: +7 / −0 | F9: ANF | G9: APA | H9: BLTE | I9: CLMT | J9: GTLB | K9: HPQ | L9: TARS
A10: 曾經拉開 | B10: 0.08 | C10: 0.06 | D10: 25 | E10: +4 / −0 | F10: AVTR | G10: MGNI | H10: NSIT | I10: PBF
A11: 曾經拉開 | B11: 0.08 | C11: 0.1 | D11: 17 | E11: +0 / −4 | F11: BBY | G11: MPC | H11: PSX | I11: SNOW
A12: 最淺回調 | B12: 0.03 | C12: 0.02 | D12: 25 | E12: +4 / −0 | F12: AMWL | G12: CBLL | H12: DE | I12: HAE
A13: 最淺回調 | B13: 0.03 | C13: 0.05 | D13: 21 | E13: +0 / −0
A14: 最深回調 | B14: 0.3 | C14: 0.25 | D14: 21 | E14: +0 / −0
A15: 最深回調 | B15: 0.3 | C15: 0.35 | D15: 21 | E15: +0 / −0
A16: 高位最遠日數 | B16: 25 | C16: 20 | D16: 21 | E16: +0 / −0
A17: 高位最遠日數 | B17: 25 | C17: 30 | D17: 21 | E17: +0 / −0
A18: 貼近紀錄高 | B18: 0.95 | C18: 0.9 | D18: 24 | E18: +3 / −0 | F18: ASO | G18: LITE | H18: XRX
A19: 貼近紀錄高 | B19: 0.95 | C19: 0.98 | D19: 21 | E19: +0 / −0
A20: 動能百分位 | B20: 0.9 | C20: 0.85 | D20: 22 | E20: +1 / −0 | F20: DJCO
A21: 動能百分位 | B21: 0.9 | C21: 0.95 | D21: 18 | E21: +0 / −3 | F21: BBY | G21: KGEI | H21: TH
A23: 黃底 = 放寬後新增；橙底 = 收緊後剔走

Sheet 差一項
A1: 動能達標、形態只差一項嘅股票（下一兩日最有機會上榜或者已經走遠）
A3: 代號 | B3: 唔通過嘅一項 | C3: 覆蓋度 | D3: 收市價 | E3: 距MA20% | F3: 距高位% | G3: 高位至今 | H3: 說明
A4: AMPL | B4: S1 趨勢 | C4: 3 | D4: 13.32 | E4: 0.0019369276 | F4: -0.068531469 | G4: 20 | H4: MA20 ↓（vs 5日前）；MA20 > MA50；MA50 ↑（vs 10日前）；收市 > MA50
A5: CORT | B5: S1 趨勢 | C5: 3 | D5: 115.56 | E5: 0.016837298 | F5: -0.064821559 | G5: 23 | H5: MA20 ↓（vs 5日前）；MA20 > MA50；MA50 ↑（vs 10日前）；收市 > MA50
A6: PAYC | B6: S1 趨勢 | C6: 3 | D6: 220.58 | E6: -0.023787922 | F6: -0.082903709 | G6: 16 | H6: MA20 ↓（vs 5日前）；MA20 > MA50；MA50 ↑（vs 10日前）；收市 > MA50
A7: PAYS | B7: S1 趨勢 | C7: 3 | D7: 12.715 | E7: 0.00041306871 | F7: -0.10077793 | G7: 23 | H7: MA20 ↓（vs 5日前）；MA20 > MA50；MA50 ↑（vs 10日前）；收市 > MA50
A8: RCMT | B8: S1 趨勢 | C8: 3 | D8: 40.67 | E8: 0.0065835066 | F8: -0.031666667 | G8: 23 | H8: MA20 ↓（vs 5日前）；MA20 > MA50；MA50 ↑（vs 10日前）；收市 > MA50
A9: WT | B9: S1 趨勢 | C9: 3 | D9: 24.06 | E9: 0.014034644 | F9: -0.03913738 | G9: 21 | H9: MA20 ↓（vs 5日前）；MA20 > MA50；MA50 ↑（vs 10日前）；收市 > MA50
A10: XNCR | B10: S1 趨勢 | C10: 3 | D10: 25.6 | E10: 0.017336446 | F10: -0.12627986 | G10: 23 | H10: MA20 ↓（vs 5日前）；MA20 > MA50；MA50 ↑（vs 10日前）；收市 > MA50
A11: ETON | B11: S1 趨勢 | C11: 2 | D11: 59.25 | E11: 0.021358018 | F11: -0.08039733 | G11: 24 | H11: MA20 ↓（vs 5日前）；MA20 > MA50；MA50 ↑（vs 10日前）；收市 > MA50
A12: KRO | B12: S1 趨勢 | C12: 2 | D12: 8.14 | E12: -0.02122287 | F12: -0.086419753 | G12: 23 | H12: MA20 ↓（vs 5日前）；MA20 > MA50；MA50 ↑（vs 10日前）；收市 > MA50
A13: MAN | B13: S1 趨勢 | C13: 2 | D13: 57.06 | E13: -0.022995394 | F13: -0.093566322 | G13: 19 | H13: MA20 ↓（vs 5日前）；MA20 > MA50；MA50 ↑（vs 10日前）；收市 ≤ MA50
A14: PRCH | B14: S1 趨勢 | C14: 2 | D14: 16.83 | E14: 0.0065037004 | F14: -0.068106312 | G14: 16 | H14: MA20 ↓（vs 5日前）；MA20 > MA50；MA50 ↑（vs 10日前）；收市 > MA50
A15: PSNL | B15: S1 趨勢 | C15: 2 | D15: 16.32 | E15: -0.0096185939 | F15: -0.11207835 | G15: 25 | H15: MA20 ↓（vs 5日前）；MA20 > MA50；MA50 ↑（vs 10日前）；收市 > MA50
... A90: VRA | B90: S5 回到20MA | C90: 1 | D90: 4.15 | E90: 0.1303282 | F90: -0.032634033 | G90: 4 | H90: 收市距 MA20 +13.0%（要 -3% 至 +3%）；近 3 日最低價最近去到 MA20 +9.5%（要 ≤+1.5%）

Sheet 同R21對照
A1: R21（2026-09-23 收市）名單 vs R22.00（2026-09-28 收市）名單 · 同一套規則
A3: 類別 | B3: 代號 | C3: R21 排名 | D3: R22.00 排名 | E3: 說明
A4: 兩版都上榜 | B4: IRD | C4: 9 | D4: 1
A5: 兩版都上榜 | B5: PLSE | C5: 8 | D5: 4
A6: 兩版都上榜 | B6: ESTC | C6: 4 | D6: 6
A7: 兩版都上榜 | B7: DHX | C7: 13 | D7: 8
A8: 兩版都上榜 | B8: VLO | C8: 17 | D8: 9
A9: 兩版都上榜 | B9: SNOW | C9: 11 | D9: 11
A10: 兩版都上榜 | B10: MPC | C10: 20 | D10: 12
A11: 兩版都上榜 | B11: LPG | C11: 25 | D11: 16
A12: 兩版都上榜 | B12: DINO | C12: 15 | D12: 20
A13: 兩版都上榜 | B13: PSX | C13: 24 | D13: 21
A14: 新上榜 | B14: TTRX | D14: 2 | E14: 2026-09-23：形態唔過：S5 回到20MA（距 MA20 +10.5%、距高位 -11.9%）
A15: 新上榜 | B15: DELL | D15: 3 | E15: 2026-09-23：形態唔過：S5 回到20MA（距 MA20 +5.5%、距高位 -6.6%）
A16: 新上榜 | B16: TITN | D16: 5 | E16: 2026-09-23：形態唔過：S5 回到20MA（距 MA20 +6.1%、距高位 -7.6%）
A17: 新上榜 | B17: FIVN | D17: 7 | E17: 2026-09-23：形態唔過：S2 近期高位、S3 回調深度、S5 回到20MA（距 MA20 +12.2%、距高位 -2.5%）
A18: 新上榜 | B18: PURR | D18: 10 | E18: 2026-09-23：形態唔過：S3 回調深度、S5 回到20MA（距 MA20 +13.7%、距高位 -1.1%）
A19: 新上榜 | B19: KGEI | D19: 13 | E19: 2026-09-23 唔喺股票池
A20: 新上榜 | B20: IBTA | D20: 14 | E20: 2026-09-23：形態唔過：S3 回調深度、S5 回到20MA（距 MA20 +4.3%、距高位 -2.8%）
A21: 新上榜 | B21: ELMT | D21: 15 | E21: 2026-09-23：形態唔過：S5 回到20MA（距 MA20 +11.7%、距高位 -10.4%）
A22: 新上榜 | B22: DC | D22: 17 | E22: 2026-09-23：形態唔過：S2 近期高位、S5 回到20MA（距 MA20 +9.4%、距高位 -3.8%）
A23: 新上榜 | B23: BBY | D23: 18 | E23: 2026-09-23：動能：四個時間框都唔入頭 10%（距 MA20 +1.8%、距高位 -4.2%）
A24: 新上榜 | B24: TH | D24: 19 | E24: 2026-09-23：形態唔過：S3 回調深度、S5 回到20MA（距 MA20 +9.6%、距高位 -0.4%）
A25: 跌出 | B25: VEEV | C25: 1 | E25: 形態唔過：S2 近期高位、S3 回調深度、S5 回到20MA（距 MA20 +3.6%、距高位 -2.0%）
A26: 跌出 | B26: NUTX | C26: 2 | E26: 形態唔過：S2 近期高位、S5 回到20MA（距 MA20 +4.8%、距高位 -3.2%）
A27: 跌出 | B27: CLMT | C27: 3 | E27: 形態唔過：S5 回到20MA（距 MA20 -4.6%、距高位 -10.9%）
A28: 跌出 | B28: NEO | C28: 5 | E28: 形態唔過：S5 回到20MA（距 MA20 +4.7%、距高位 -3.1%）
A29: 跌出 | B29: NOW | C29: 6 | E29: 形態唔過：S2 近期高位、S5 回到20MA（距 MA20 -4.8%、距高位 -11.2%）
A30: 跌出 | B30: HPQ | C30: 7 | E30: 形態唔過：S5 回到20MA（距 MA20 -3.7%、距高位 -11.7%）
A31: 跌出 | B31: AMWL | C31: 10 | E31: 形態唔過：S3 回調深度（距 MA20 +2.6%、距高位 -2.7%）
A32: 跌出 | B32: AMPL | C32: 12 | E32: 形態唔過：S1 趨勢（距 MA20 +0.2%、距高位 -6.9%）
A33: 跌出 | B33: ZETA | C33: 14 | E33: 形態唔過：S5 回到20MA（距 MA20 -5.2%、距高位 -11.3%）
A34: 跌出 | B34: MGNI | C34: 16 | E34: 形態唔過：S4 曾經拉開（距 MA20 -2.9%、距高位 -8.7%）
A35: 跌出 | B35: SABR | C35: 18 | E35: 形態唔過：S1 趨勢、S5 回到20MA；動能：四個時間框都唔入頭 10%（距 MA20 -3.8%、距高位 -9.9%）
A36: 跌出 | B36: VIR | C36: 19 | E36: 形態唔過：S5 回到20MA；動能：四個時間框都唔入頭 10%（距 MA20 -3.9%、距高位 -9.6%）
... A42: 跌出 | B42: CBLL | C42: 28 | E42: 形態唔過：S3 回調深度（距 MA20 +1.0%、距高位 -2.0%）

Sheet R21向前測試
A1: R21 名單（2026-09-23 收市）之後 3 個交易日點行（至 2026-09-28 收市）
A3: 整體 | B3: R21 28 隻由 2026-09-23 收市到 2026-09-28 收市（3 個交易日）中位數 -1.57%，13 隻升；同期全體合資格股票中位數 -0.68%。最好 NUTX +5.5%，最差 SGP -7.7%。
A4: 排名有冇用 | B4: 前 10 名中位數 +1.42%（6/10 升），其餘 -2.16%（7/18 升）；爆發潛力分數同期間回報嘅排名相關 +0.15。只係 3 日，樣本太細，唔可以當證明。
A5: 收市喺 MA20 上定下 | B5: 2026-09-23 收市企喺 MA20 上面嘅 15 隻中位數 -2.00%；收喺 MA20 下面（規則容許低 3%）嘅 13 隻 -1.14%。
A6: 審視標記 | B6: 有標記嘅 11 隻中位數 +0.30%，冇標記嘅 17 隻 -2.63%；「放量跌穿」嘅 3 隻 +0.30%。
A7: 而家狀態 | B7: 跌穿 MA20 超過 3% 10 隻；仍然上榜 10 隻；仍喺 MA20 附近（其他條件唔過） 5 隻；已反彈離開 MA20 3 隻
A9: R21 排名 | B9: 代號 | C9: 2026-09-23 收市 | D9: 2026-09-28 收市 | E9: 期間回報 | F9: 減大市中位數 | G9: 2026-09-28 距 MA20% | H9: 狀態 | I9: R22.00 排名 | J9: R21 標記
A10: 1 | B10: VEEV | C10: 270.75 | D10: 279.96 | E10: =D10/C10-1 | F10: =E10-(-0.0067584799795971096) | G10: 0.0362 | H10: 已反彈離開 MA20
A11: 2 | B11: NUTX | C11: 201.86 | D11: 213.03 | E11: =D11/C11-1 | F11: =E11-(-0.0067584799795971096) | G11: 0.048 | H11: 已反彈離開 MA20
A12: 3 | B12: CLMT | C12: 54.38 | D12: 52.61 | E12: =D12/C12-1 | F12: =E12-(-0.0067584799795971096) | G12: -0.046 | H12: 跌穿 MA20 超過 3% | J12: 09-22 Jefferies 將 VLO、MPC 由買入降至持有（目標 $401／$413，理由係大升後估值偏高）；同日 Bloomberg 報道柴油出口禁令提案獲政治支持，煉油股升勢停頓。回調有明確評級同政策催化，唔係單純技術性回吐。（五隻 21 日相關系數中位數 +0.89，名單其餘 +0.08）
A13: 4 | B13: ESTC | C13: 91.28 | D13: 87.95 | E13: =D13/C13-1 | F13: =E13-(-0.0067584799795971096) | G13: -0.0108 | H13: 仍然上榜 | I13: 6
A14: 5 | B14: NEO | C14: 18.36 | D14: 19.3 | E14: =D14/C14-1 | F14: =E14-(-0.0067584799795971096) | G14: 0.0471 | H14: 已反彈離開 MA20
A15: 6 | B15: NOW | C15: 140.78 | D15: 131.45 | E15: =D15/C15-1 | F15: =E15-(-0.0067584799795971096) | G15: -0.0481 | H15: 跌穿 MA20 超過 3%
A16: 7 | B16: HPQ | C16: 32.16 | D16: 31.315 | E16: =D16/C16-1 | F16: =E16-(-0.0067584799795971096) | G16: -0.0367 | H16: 跌穿 MA20 超過 3%
A17: 8 | B17: PLSE | C17: 51.98 | D17: 52.32 | E17: =D17/C17-1 | F17: =E17-(-0.0067584799795971096) | G17: -0.0031 | H17: 仍然上榜 | I17: 4 | J17: 回調唔係有序回落：期內有一日跌 -10.1%
A18: 9 | B18: IRD | C18: 4.83 | D18: 5.07 | E18: =D18/C18-1 | F18: =E18-(-0.0067584799795971096) | G18: 0.0048 | H18: 仍然上榜 | I18: 1 | J18: 升浪同回調都係單一臨床事件：09 月第二個星期公佈 OPGx-BEST1 第一組三個月頂線數據，多間券商將目標價加到 $13–$20，股價高位喺 09-10；之後回吐約兩成。10 月 1–4 日 EURETINA 大會再公佈詳細數據 —— 二元事件風險仲未完。
A19: 10 | B19: AMWL | C19: 13.21 | D19: 13.5 | E19: =D19/C19-1 | F19: =E19-(-0.0067584799795971096) | G19: 0.0265 | H19: 仍喺 MA20 附近（其他條件唔過） | J19: 20 日成交額中位數只有 $1.3M（股票池下限 $1M），入市出市都會有滑價
A20: 11 | B20: SNOW | C20: 334.81 | D20: 328.12 | E20: =D20/C20-1 | F20: =E20-(-0.0067584799795971096) | G20: -0.012 | H20: 仍然上榜 | I20: 11
A21: 12 | B21: AMPL | C21: 13.755 | D21: 13.32 | E21: =D21/C21-1 | F21: =E21-(-0.0067584799795971096) | G21: 0.0019 | H21: 仍喺 MA20 附近（其他條件唔過）
A22: 13 | B22: DHX | C22: 4.6 | D22: 4.62 | E22: =D22/C22-1 | F22: =E22-(-0.0067584799795971096) | G22: -0.0061 | H22: 仍然上榜 | I22: 8 | J22: 20 日成交額中位數只有 $1.3M（股票池下限 $1M），入市出市都會有滑價
A23: 14 | B23: ZETA | C23: 29.79 | D23: 28.99 | E23: =D23/C23-1 | F23: =E23-(-0.0067584799795971096) | G23: -0.0519 | H23: 跌穿 MA20 超過 3%
A24: 15 | B24: DINO | C24: 106.14 | D24: 106.2 | E24: =D24/C24-1 | F24: =E24-(-0.0067584799795971096) | G24: -0.0175 | H24: 仍然上榜 | I24: 20 | J24: 今日放量（1.7× 50日均量）收喺 20MA 下面；09-22 Jefferies 將 VLO、MPC 由買入降至持有（目標 $401／$413，理由係大升後估值偏高）；同日 Bloomberg 報道柴油出口禁令提案獲政治支持，煉油股升勢停頓。回調有明確評級同政策催化，唔係單純技術性回吐。（五隻 21 日相關系數中位數 +0.89，名單其餘 +0.08）
A25: 16 | B25: MGNI | C25: 24.06 | D25: 23.41 | E25: =D25/C25-1 | F25: =E25-(-0.0067584799795971096) | G25: -0.0294 | H25: 仍喺 MA20 附近（其他條件唔過）
A26: 17 | B26: VLO | C26: 375.84 | D26: 389.57 | E26: =D26/C26-1 | F26: =E26-(-0.0067584799795971096) | G26: 0.0131 | H26: 仍然上榜 | I26: 9 | J26: 今日放量（2.3× 50日均量）收喺 20MA 下面；09-22 Jefferies 將 VLO、MPC 由買入降至持有（目標 $401／$413，理由係大升後估值偏高）；同日 Bloomberg 報道柴油出口禁令提案獲政治支持，煉油股升勢停頓。回調有明確評級同政策催化，唔係單純技術性回吐。（五隻 21 日相關系數中位數 +0.89，名單其餘 +0.08）
A27: 18 | B27: SABR | C27: 2.19 | D27: 2.1 | E27: =D27/C27-1 | F27: =E27-(-0.0067584799795971096) | G27: -0.0377 | H27: 跌穿 MA20 超過 3% | J27: 收市 $2.19，貼近股票池 $2 下限；1 個月回報 -3%，靠 2個月 動能上榜
A28: 19 | B28: VIR | C28: 11.09 | D28: 10.51 | E28: =D28/C28-1 | F28: =E28-(-0.0067584799795971096) | G28: -0.0389 | H28: 跌穿 MA20 超過 3%
A29: 20 | B29: MPC | C29: 388.38 | D29: 389.55 | E29: =D29/C29-1 | F29: =E29-(-0.0067584799795971096) | G29: -0.0173 | H29: 仍然上榜 | I29: 12 | J29: 今日放量（1.6× 50日均量）收喺 20MA 下面；09-22 Jefferies 將 VLO、MPC 由買入降至持有（目標 $401／$413，理由係大升後估值偏高）；同日 Bloomberg 報道柴油出口禁令提案獲政治支持，煉油股升勢停頓。回調有明確評級同政策催化，唔係單純技術性回吐。（五隻 21 日相關系數中位數 +0.89，名單其餘 +0.08）
A30: 21 | B30: SGP | C30: 28.16 | D30: 25.98 | E30: =D30/C30-1 | F30: =E30-(-0.0067584799795971096) | G30: -0.0731 | H30: 跌穿 MA20 超過 3% | J30: 20 日成交額中位數只有 $3.3M（股票池下限 $1M），入市出市都會有滑價
A31: 22 | B31: ANGX | C31: 4.85 | D31: 4.57 | E31: =D31/C31-1 | F31: =E31-(-0.0067584799795971096) | G31: -0.0707 | H31: 跌穿 MA20 超過 3%
A32: 23 | B32: DJCO | C32: 659.4 | D32: 659.91 | E32: =D32/C32-1 | F32: =E32-(-0.0067584799795971096) | G32: 0.0152 | H32: 仍喺 MA20 附近（其他條件唔過）
A33: 24 | B33: PSX | C33: 256.48 | D33: 253.55 | E33: =D33/C33-1 | F33: =E33-(-0.0067584799795971096) | G33: -0.0204 | H33: 仍然上榜 | I33: 21 | J33: 09-22 Jefferies 將 VLO、MPC 由買入降至持有（目標 $401／$413，理由係大升後估值偏高）；同日 Bloomberg 報道柴油出口禁令提案獲政治支持，煉油股升勢停頓。回調有明確評級同政策催化，唔係單純技術性回吐。（五隻 21 日相關系數中位數 +0.89，名單其餘 +0.08）
A34: 25 | B34: LPG | C34: 53.16 | D34: 54.38 | E34: =D34/C34-1 | F34: =E34-(-0.0067584799795971096) | G34: -0.0024 | H34: 仍然上榜 | I34: 16
A35: 26 | B35: REPX | C35: 41.07 | D35: 40.12 | E35: =D35/C35-1 | F35: =E35-(-0.0067584799795971096) | G35: -0.0434 | H35: 跌穿 MA20 超過 3%
A36: 27 | B36: APA | C36: 43.7 | D36: 42.33 | E36: =D36/C36-1 | F36: =E36-(-0.0067584799795971096) | G36: -0.0411 | H36: 跌穿 MA20 超過 3%
A37: 28 | B37: CBLL | C37: 23.62 | D37: 24.53 | E37: =D37/C37-1 | F37: =E37-(-0.0067584799795971096) | G37: 0.0098 | H37: 仍喺 MA20 附近（其他條件唔過）

Sheet 同上日對照
A1: 同一套規則回算 2026-09-25 收市嘅名單，對比 2026-09-28
A3: 類別 | B3: 代號 | C3: 2026-09-25 排名 | D3: 2026-09-28 排名 | E3: 說明
A4: 兩日都上榜 | B4: TTRX | C4: 1 | D4: 2
A5: 兩日都上榜 | B5: PLSE | C5: 4 | D5: 4
A6: 兩日都上榜 | B6: TITN | C6: 8 | D6: 5
A7: 兩日都上榜 | B7: ESTC | C7: 3 | D7: 6
A8: 兩日都上榜 | B8: DHX | C8: 11 | D8: 8
A9: 兩日都上榜 | B9: VLO | C9: 10 | D9: 9
A10: 兩日都上榜 | B10: SNOW | C10: 5 | D10: 11
A11: 兩日都上榜 | B11: MPC | C11: 12 | D11: 12
A12: 兩日都上榜 | B12: LPG | C12: 15 | D12: 16
A13: 兩日都上榜 | B13: DINO | C13: 13 | D13: 20
A14: 兩日都上榜 | B14: PSX | C14: 16 | D14: 21
