Workbook

Sheet 本版更新
A1: R21.00 更新重點
A3: 1 | B3: 篩選條件全面更新為「高動能 ＋ 回到上升中嘅 20MA」：先要 1／2／3／6 個月回報至少一個排全體合資格股票頭 10%，再要趨勢向上、兩至二十五日前見過期內高位、回調 3–30%、曾經離開 MA20 至少 8%、而家收市喺 MA20 ±3% 之內兼近 3 日觸及過。細節見「篩選規則」頁。
A4: 2 | B4: 數據更新至 2026-09-23 收市（186 個交易日）。價格改用 Yahoo 日線，因為「觸及 20MA」要用當日最低價；Nasdaq 序列同收市後快照做核對。
A5: 3 | B5: 合資格 2,766 隻 → 形態 37 隻 → 上榜 28 隻（1 個月頁 15、2 個月 19、3 個月 22、6 個月 13）。
A6: 4 | B6: 評分改為動能分數 × 回調質素（量縮、貼近 MA20、MA20 斜率、回調深度、企穩、波幅收窄），取代舊嘅 VCP × 底部確定性。
A7: 5 | B7: 批判性覆核改咗四個問題（Yahoo 缺 09-22、SPAC 空殼期扮動能、修正空殼期時會誤傷鏡像斷檔嘅大型股、兩源核對假警報），另外標記咗煉油股集中、事件驅動、流動性同低價股，詳見「審視標記」頁。
A8: 6 | B8: 獨立重寫嘅篩選程式（只按規則文字，唔共用代碼）得出同一份 28 隻名單，逐欄比對 0 個差異。
A9: 7 | B9: 所有代號都連去 TradingView 圖表；計得出嘅欄位（距 MA%、斜率、分數、排名、覆蓋度）全部係公式。

Sheet 總表
A1: 排名 | B1: 代號 | C1: 公司 | D1: 交易所 | E1: 板塊 | F1: 行業 | G1: 市值(十億美元) | H1: 市值組 | I1: 收市價 | J1: 前收 | K1: 當日% | L1: 當日高 | M1: 當日低 | N1: MA20 | O1: 距MA20% | P1: MA50 | Q1: 距MA50% | R1: MA20（5日前） | S1: MA20 5日斜率% | T1: 63日最高收市 | U1: 高位日期 | V1: 高位至今（交易日） | W1: 距高位% | X1: 25日內最大偏離MA20% | Y1: 偏離最大日期 | Z1: 近3日最低價距MA20% | AA1: 升浪起點 | AB1: 升浪幅度% | AC1: 1個月回報 | AD1: 2個月回報 | AE1: 3個月回報 | AF1: 6個月回報 | AG1: 1個月百分位 | AH1: 2個月百分位 | AI1: 3個月百分位 | AJ1: 6個月百分位 | AK1: 動能時間框 | AL1: 覆蓋度 | AM1: 回調量比 | AN1: ATR5/ATR20 | AO1: ATR14% | AP1: 量縮 | AQ1: 貼近MA20 | AR1: MA20斜率分 | AS1: 回調深度分 | AT1: 企穩 | AU1: 波幅收窄 | AV1: 動能分數 | AW1: 回調質素 | AX1: 綜合分數 | AY1: 爆發潛力分數 | AZ1: R20 10MA名單 | BA1: 門檻測試留低 | BB1: 審視標記 | BC1: 兩源最大差%
A2: =COUNTIF($AY$2:$AY$29,">"&AY2)+1 | B2: VEEV | C2: Veeva Systems Inc. Class A | D2: NYSE | E2: 醫療保健 | F2: Computer Software: Prepackaged Software | G2: 43.837 | H2: 大型 | I2: 270.75 | J2: 260.91 | K2: =I2/J2-1 | L2: 272.18 | M2: 263 | N2: 268.599 | O2: =I2/N2-1 | P2: 238.383 | Q2: =I2/P2-1 | R2: 264.986 | S2: =N2/R2-1 | T2: 285.69 | U2: 2026-08-31 | V2: 16 | W2: =I2/T2-1 | X2: 0.18900717 | Y2: 2026-08-27 | Z2: -0.033391059 | AA2: 2026-06-22 | AB2: 0.86530426 | AC2: 0.08971263 | AD2: 0.45376933 | AE2: 0.67802913 | AF2: 0.51164089 | AG2: 0.91500904 | AH2: 0.96491863 | AI2: 0.9761302 | AJ2: 0.87344094 | AK2: 1個月、2個月、3個月 | AL2: =(AG2>=0.9)*(AC2>0)+(AH2>=0.9)*(AD2>0)+(AI2>=0.9)*(AE2>0)+IF(AJ2="",0,(AJ2>=0.9)*(AF2>0)) | AM2: 0.75751375 | AN2: 0.56590766 | AO2: 0.027867036 | AP2: =MAX(0,MIN(1,(AM2-1.2)/(0.6-1.2))) | AQ2: =MAX(0,MIN(1,(ABS(O2)-0.03)/(0-0.03))) | AR2: =MAX(0,MIN(1,S2/0.03)) | AS2: =MAX(0,MIN(1,(-W2-0.3)/(0.15-0.3))) | AT2: =0.5*IF(L2>M2,(I2-M2)/(L2-M2),0.5)+0.5*(I2>=N2) | AU2: =MAX(0,MIN(1,(AN2-1.3)/(0.7-1.3))) | AV2: =100*(0.2*AG2+0.2*AH2+0.3*AI2+IF(AJ2="",0,0.3*AJ2))/(0.7+IF(AJ2="",0,0.3)) | AW2: =100*(0.25*AP2+0.2*AQ2+0.15*AR2+0.15*AS2+0.15*AT2+0.1*AU2) | AX2: =0.5*AV2+0.5*AW2 | AY2: =0.4*AV2+0.4*AW2+0.2*(AL2/4*100) | BA2: 18/18 | BC2: 0
A3: =COUNTIF($AY$2:$AY$29,">"&AY3)+1 | B3: NUTX | C3: Nutex Health Inc. | D3: NASDAQ | E3: 非必需消費 | F3: Business Services | G3: 1.382 | H3: 小型 | I3: 201.86 | J3: 208.82 | K3: =I3/J3-1 | L3: 210.025 | M3: 199.92 | N3: 200.34075 | O3: =I3/N3-1 | P3: 180.8067 | Q3: =I3/P3-1 | R3: 195.61225 | S3: =N3/R3-1 | T3: 217.325 | U3: 2026-09-16 | V3: 5 | W3: =I3/T3-1 | X3: 0.15768984 | Y3: 2026-08-19 | Z3: -0.0021001718 | AA3: 2026-07-29 | AB3: 0.54690725 | AC3: 0.076012793 | AD3: 0.38383492 | AE3: 0.36817134 | AF3: 1.0289476 | AG3: 0.90162749 | AH3: 0.95081374 | AI3: 0.92477396 | AJ3: 0.95341159 | AK3: 1個月、2個月、3個月、6個月 | AL3: =(AG3>=0.9)*(AC3>0)+(AH3>=0.9)*(AD3>0)+(AI3>=0.9)*(AE3>0)+IF(AJ3="",0,(AJ3>=0.9)*(AF3>0)) | AM3: 0.97807766 | AN3: 0.95869381 | AO3: 0.053410426 | AP3: =MAX(0,MIN(1,(AM3-1.2)/(0.6-1.2))) | AQ3: =MAX(0,MIN(1,(ABS(O3)-0.03)/(0-0.03))) | AR3: =MAX(0,MIN(1,S3/0.03)) | AS3: =MAX(0,MIN(1,(-W3-0.3)/(0.15-0.3))) | AT3: =0.5*IF(L3>M3,(I3-M3)/(L3-M3),0.5)+0.5*(I3>=N3) | AU3: =MAX(0,MIN(1,(AN3-1.3)/(0.7-1.3))) | AV3: =100*(0.2*AG3+0.2*AH3+0.3*AI3+IF(AJ3="",0,0.3*AJ3))/(0.7+IF(AJ3="",0,0.3)) | AW3: =100*(0.25*AP3+0.2*AQ3+0.15*AR3+0.15*AS3+0.15*AT3+0.1*AU3) | AX3: =0.5*AV3+0.5*AW3 | AY3: =0.4*AV3+0.4*AW3+0.2*(AL3/4*100) | AZ3: 有 | BA3: 18/18 | BC3: 0
A4: =COUNTIF($AY$2:$AY$29,">"&AY4)+1 | B4: CLMT | C4: Calumet Inc. | D4: NASDAQ | E4: 能源 | F4: Integrated oil Companies | G4: 4.78 | H4: 中型 | I4: 54.38 | J4: 56.42 | K4: =I4/J4-1 | L4: 57.16 | M4: 51.92 | N4: 54.209 | O4: =I4/N4-1 | P4: 48.3644 | Q4: =I4/P4-1 | R4: 51.9025 | S4: =N4/R4-1 | T4: 59.05 | U4: 2026-09-17 | V4: 4 | W4: =I4/T4-1 | X4: 0.12700518 | Y4: 2026-09-17 | Z4: -0.042225461 | AA4: 2026-06-18 | AB4: 0.8091299 | AC4: 0.14919696 | AD4: 0.30438954 | AE4: 0.66096518 | AF4: 0.8591453 | AG4: 0.94900542 | AH4: 0.92549729 | AI4: 0.97504521 | AJ4: 0.93580337 | AK4: 1個月、2個月、3個月、6個月 | AL4: =(AG4>=0.9)*(AC4>0)+(AH4>=0.9)*(AD4>0)+(AI4>=0.9)*(AE4>0)+IF(AJ4="",0,(AJ4>=0.9)*(AF4>0)) | AM4: 1.6747537 | AN4: 1.0593014 | AO4: 0.044107603 | AP4: =MAX(0,MIN(1,(AM4-1.2)/(0.6-1.2))) | AQ4: =MAX(0,MIN(1,(ABS(O4)-0.03)/(0-0.03))) | AR4: =MAX(0,MIN(1,S4/0.03)) | AS4: =MAX(0,MIN(1,(-W4-0.3)/(0.15-0.3))) | AT4: =0.5*IF(L4>M4,(I4-M4)/(L4-M4),0.5)+0.5*(I4>=N4) | AU4: =MAX(0,MIN(1,(AN4-1.3)/(0.7-1.3))) | AV4: =100*(0.2*AG4+0.2*AH4+0.3*AI4+IF(AJ4="",0,0.3*AJ4))/(0.7+IF(AJ4="",0,0.3)) | AW4: =100*(0.25*AP4+0.2*AQ4+0.15*AR4+0.15*AS4+0.15*AT4+0.1*AU4) | AX4: =0.5*AV4+0.5*AW4 | AY4: =0.4*AV4+0.4*AW4+0.2*(AL4/4*100) | BA4: 18/18 | BB4: 09-22 Jefferies 將 VLO、MPC 由買入降至持有（目標 $401／$413，理由係大升後估值偏高）；同日 Bloomberg 報道柴油出口禁令提案獲政治支持，煉油股升勢停頓。回調有明確評級同政策催化，唔係單純技術性回吐。（五隻 21 日相關系數中位數 +0.89，名單其餘 +0.08） | BC4: 0
A5: =COUNTIF($AY$2:$AY$29,">"&AY5)+1 | B5: ESTC | C5: Elastic N.V. | D5: NYSE | E5: 科技 | F5: Computer Software: Prepackaged Software | G5: 9.584 | H5: 中型 | I5: 91.28 | J5: 89.22 | K5: =I5/J5-1 | L5: 91.52 | M5: 88.77 | N5: 88.6835 | O5: =I5/N5-1 | P5: 78.4686 | Q5: =I5/P5-1 | R5: 87.5175 | S5: =N5/R5-1 | T5: 99.91 | U5: 2026-08-28 | V5: 17 | W5: =I5/T5-1 | X5: 0.24012437 | Y5: 2026-08-28 | Z5: -0.01002385 | AA5: 2026-06-25 | AB5: 0.86399254 | AC5: 0.096588179 | AD5: 0.55555556 | AE5: 0.55476069 | AF5: 0.83772901 | AG5: 0.92151899 | AH5: 0.97576854 | AI5: 0.96274864 | AJ5: 0.93250183 | AK5: 1個月、2個月、3個月、6個月 | AL5: =(AG5>=0.9)*(AC5>0)+(AH5>=0.9)*(AD5>0)+(AI5>=0.9)*(AE5>0)+IF(AJ5="",0,(AJ5>=0.9)*(AF5>0)) | AM5: 0.84908072 | AN5: 0.61749503 | AO5: 0.039924252 | AP5: =MAX(0,MIN(1,(AM5-1.2)/(0.6-1.2))) | AQ5: =MAX(0,MIN(1,(ABS(O5)-0.03)/(0-0.03))) | AR5: =MAX(0,MIN(1,S5/0.03)) | AS5: =MAX(0,MIN(1,(-W5-0.3)/(0.15-0.3))) | AT5: =0.5*IF(L5>M5,(I5-M5)/(L5-M5),0.5)+0.5*(I5>=N5) | AU5: =MAX(0,MIN(1,(AN5-1.3)/(0.7-1.3))) | AV5: =100*(0.2*AG5+0.2*AH5+0.3*AI5+IF(AJ5="",0,0.3*AJ5))/(0.7+IF(AJ5="",0,0.3)) | AW5: =100*(0.25*AP5+0.2*AQ5+0.15*AR5+0.15*AS5+0.15*AT5+0.1*AU5) | AX5: =0.5*AV5+0.5*AW5 | AY5: =0.4*AV5+0.4*AW5+0.2*(AL5/4*100) | BA5: 17/18 | BC5: 0
A6: =COUNTIF($AY$2:$AY$29,">"&AY6)+1 | B6: NEO | C6: NeoGenomics Inc. | D6: NASDAQ | E6: 醫療保健 | F6: Precision Instruments | G6: 2.359 | H6: 中型 | I6: 18.36 | J6: 18.89 | K6: =I6/J6-1 | L6: 19.08 | M6: 18.27 | N6: 18.2255 | O6: =I6/N6-1 | P6: 16.592 | Q6: =I6/P6-1 | R6: 17.571 | S6: =N6/R6-1 | T6: 19.91 | U6: 2026-09-18 | V6: 3 | W6: =I6/T6-1 | X6: 0.13440648 | Y6: 2026-08-27 | Z6: 0.002441634 | AA6: 2026-06-18 | AB6: 0.78885894 | AC6: 0.11882998 | AD6: 0.32181425 | AE6: 0.42325581 | AF6: 1.3358779 | AG6: 0.93562387 | AH6: 0.93128391 | AI6: 0.93851718 | AJ6: 0.97322084 | AK6: 1個月、2個月、3個月、6個月 | AL6: =(AG6>=0.9)*(AC6>0)+(AH6>=0.9)*(AD6>0)+(AI6>=0.9)*(AE6>0)+IF(AJ6="",0,(AJ6>=0.9)*(AF6>0)) | AM6: 1.5300734 | AN6: 0.84695052 | AO6: 0.041588858 | AP6: =MAX(0,MIN(1,(AM6-1.2)/(0.6-1.2))) | AQ6: =MAX(0,MIN(1,(ABS(O6)-0.03)/(0-0.03))) | AR6: =MAX(0,MIN(1,S6/0.03)) | AS6: =MAX(0,MIN(1,(-W6-0.3)/(0.15-0.3))) | AT6: =0.5*IF(L6>M6,(I6-M6)/(L6-M6),0.5)+0.5*(I6>=N6) | AU6: =MAX(0,MIN(1,(AN6-1.3)/(0.7-1.3))) | AV6: =100*(0.2*AG6+0.2*AH6+0.3*AI6+IF(AJ6="",0,0.3*AJ6))/(0.7+IF(AJ6="",0,0.3)) | AW6: =100*(0.25*AP6+0.2*AQ6+0.15*AR6+0.15*AS6+0.15*AT6+0.1*AU6) | AX6: =0.5*AV6+0.5*AW6 | AY6: =0.4*AV6+0.4*AW6+0.2*(AL6/4*100) | BA6: 17/18 | BC6: 0.0003
A7: =COUNTIF($AY$2:$AY$29,">"&AY7)+1 | B7: NOW | C7: ServiceNow Inc. | D7: NYSE | E7: 科技 | F7: Computer Software: Prepackaged Software | G7: 145.567 | H7: 大型 | I7: 140.78 | J7: 137 | K7: =I7/J7-1 | L7: 141.54 | M7: 136.15 | N7: 138.2945 | O7: =I7/N7-1 | P7: 124.4934 | Q7: =I7/P7-1 | R7: 135.8485 | S7: =N7/R7-1 | T7: 147.99 | U7: 2026-08-31 | V7: 16 | W7: =I7/T7-1 | X7: 0.16373616 | Y7: 2026-08-31 | Z7: -0.017263118 | AA7: 2026-06-25 | AB7: 0.65315013 | AC7: 0.099414291 | AD7: 0.42518728 | AE7: 0.50085288 | AF7: 0.34524606 | AG7: 0.92260398 | AH7: 0.95877034 | AI7: 0.95334539 | AJ7: 0.80044021 | AK7: 1個月、2個月、3個月 | AL7: =(AG7>=0.9)*(AC7>0)+(AH7>=0.9)*(AD7>0)+(AI7>=0.9)*(AE7>0)+IF(AJ7="",0,(AJ7>=0.9)*(AF7>0)) | AM7: 0.74382592 | AN7: 0.78804185 | AO7: 0.044080937 | AP7: =MAX(0,MIN(1,(AM7-1.2)/(0.6-1.2))) | AQ7: =MAX(0,MIN(1,(ABS(O7)-0.03)/(0-0.03))) | AR7: =MAX(0,MIN(1,S7/0.03)) | AS7: =MAX(0,MIN(1,(-W7-0.3)/(0.15-0.3))) | AT7: =0.5*IF(L7>M7,(I7-M7)/(L7-M7),0.5)+0.5*(I7>=N7) | AU7: =MAX(0,MIN(1,(AN7-1.3)/(0.7-1.3))) | AV7: =100*(0.2*AG7+0.2*AH7+0.3*AI7+IF(AJ7="",0,0.3*AJ7))/(0.7+IF(AJ7="",0,0.3)) | AW7: =100*(0.25*AP7+0.2*AQ7+0.15*AR7+0.15*AS7+0.15*AT7+0.1*AU7) | AX7: =0.5*AV7+0.5*AW7 | AY7: =0.4*AV7+0.4*AW7+0.2*(AL7/4*100) | AZ7: 有 | BA7: 16/18 | BC7: 0
A8: =COUNTIF($AY$2:$AY$29,">"&AY8)+1 | B8: HPQ | C8: HP Inc. | D8: NYSE | E8: 科技 | F8: Computer Manufacturing | G8: 29.002 | H8: 大型 | I8: 32.16 | J8: 32.04 | K8: =I8/J8-1 | L8: 32.72 | M8: 31.61 | N8: 32.3545 | O8: =I8/N8-1 | P8: 29.6084 | Q8: =I8/P8-1 | R8: 31.405 | S8: =N8/R8-1 | T8: 35.48 | U8: 2026-09-11 | V8: 8 | W8: =I8/T8-1 | X8: 0.15002512 | Y8: 2026-09-11 | Z8: -0.023010709 | AA8: 2026-07-02 | AB8: 0.61787506 | AC8: 0.12526242 | AD8: 0.24893204 | AE8: 0.38085015 | AF8: 0.70248809 | AG8: 0.93960217 | AH8: 0.90379747 | AI8: 0.92947559 | AJ8: 0.91562729 | AK8: 1個月、2個月、3個月、6個月 | AL8: =(AG8>=0.9)*(AC8>0)+(AH8>=0.9)*(AD8>0)+(AI8>=0.9)*(AE8>0)+IF(AJ8="",0,(AJ8>=0.9)*(AF8>0)) | AM8: 1.1551112 | AN8: 0.91242129 | AO8: 0.052016702 | AP8: =MAX(0,MIN(1,(AM8-1.2)/(0.6-1.2))) | AQ8: =MAX(0,MIN(1,(ABS(O8)-0.03)/(0-0.03))) | AR8: =MAX(0,MIN(1,S8/0.03)) | AS8: =MAX(0,MIN(1,(-W8-0.3)/(0.15-0.3))) | AT8: =0.5*IF(L8>M8,(I8-M8)/(L8-M8),0.5)+0.5*(I8>=N8) | AU8: =MAX(0,MIN(1,(AN8-1.3)/(0.7-1.3))) | AV8: =100*(0.2*AG8+0.2*AH8+0.3*AI8+IF(AJ8="",0,0.3*AJ8))/(0.7+IF(AJ8="",0,0.3)) | AW8: =100*(0.25*AP8+0.2*AQ8+0.15*AR8+0.15*AS8+0.15*AT8+0.1*AU8) | AX8: =0.5*AV8+0.5*AW8 | AY8: =0.4*AV8+0.4*AW8+0.2*(AL8/4*100) | AZ8: 有 | BA8: 17/18 | BC8: 0
A9: =COUNTIF($AY$2:$AY$29,">"&AY9)+1 | B9: PLSE | C9: Pulse Biosciences Inc | D9: NASDAQ | E9: 醫療保健 | F9: Medical/Dental Instruments | G9: 3.707 | H9: 中型 | I9: 51.98 | J9: 52.69 | K9: =I9/J9-1 | L9: 56.74 | M9: 51.87 | N9: 51.903 | O9: =I9/N9-1 | P9: 43.9136 | Q9: =I9/P9-1 | R9: 50.951 | S9: =N9/R9-1 | T9: 55.2 | U9: 2026-09-15 | V9: 6 | W9: =I9/T9-1 | X9: 0.22393494 | Y9: 2026-08-21 | Z9: -0.0006358014 | AA9: 2026-06-16 | AB9: 1.1983274 | AC9: 0.058009363 | AD9: 0.71948396 | AE9: 1.0304688 | AF9: 1.4415218 | AG9: 0.879566 | AH9: 0.9880651 | AI9: 0.9920434 | AJ9: 0.97835657 | AK9: 2個月、3個月、6個月 | AL9: =(AG9>=0.9)*(AC9>0)+(AH9>=0.9)*(AD9>0)+(AI9>=0.9)*(AE9>0)+IF(AJ9="",0,(AJ9>=0.9)*(AF9>0)) | AM9: 1.0486871 | AN9: 0.84407193 | AO9: 0.088844611 | AP9: =MAX(0,MIN(1,(AM9-1.2)/(0.6-1.2))) | AQ9: =MAX(0,MIN(1,(ABS(O9)-0.03)/(0-0.03))) | AR9: =MAX(0,MIN(1,S9/0.03)) | AS9: =MAX(0,MIN(1,(-W9-0.3)/(0.15-0.3))) | AT9: =0.5*IF(L9>M9,(I9-M9)/(L9-M9),0.5)+0.5*(I9>=N9) | AU9: =MAX(0,MIN(1,(AN9-1.3)/(0.7-1.3))) | AV9: =100*(0.2*AG9+0.2*AH9+0.3*AI9+IF(AJ9="",0,0.3*AJ9))/(0.7+IF(AJ9="",0,0.3)) | AW9: =100*(0.25*AP9+0.2*AQ9+0.15*AR9+0.15*AS9+0.15*AT9+0.1*AU9) | AX9: =0.5*AV9+0.5*AW9 | AY9: =0.4*AV9+0.4*AW9+0.2*(AL9/4*100) | BA9: 18/18 | BB9: 回調唔係有序回落：期內有一日跌 -10.1% | BC9: 0
A10: =COUNTIF($AY$2:$AY$29,">"&AY10)+1 | B10: IRD | C10: Opus Genetics Inc. | D10: NASDAQ | E10: 醫療保健 | F10: Biotechnology: Pharmaceutical Preparations | G10: 0.402 | H10: 小型 | I10: 4.83 | J10: 5.16 | K10: =I10/J10-1 | L10: 5.16 | M10: 4.65 | N10: 4.878 | O10: =I10/N10-1 | P10: 4.1078 | Q10: =I10/P10-1 | R10: 4.6135 | S10: =N10/R10-1 | T10: 6.07 | U10: 2026-09-10 | V10: 9 | W10: =I10/T10-1 | X10: 0.45041816 | Y10: 2026-09-10 | Z10: -0.046740467 | AA10: 2026-07-23 | AB10: 1.0787671 | AC10: 0.19851117 | AD10: 0.56818182 | AE10: 0.30188679 | AF10: 0.070953437 | AG10: 0.96600362 | AH10: 0.97866184 | AI10: 0.90994575 | AJ10: 0.49779897 | AK10: 1個月、2個月、3個月 | AL10: =(AG10>=0.9)*(AC10>0)+(AH10>=0.9)*(AD10>0)+(AI10>=0.9)*(AE10>0)+IF(AJ10="",0,(AJ10>=0.9)*(AF10>0)) | AM10: 0.63843621 | AN10: 0.60326609 | AO10: 0.12496303 | AP10: =MAX(0,MIN(1,(AM10-1.2)/(0.6-1.2))) | AQ10: =MAX(0,MIN(1,(ABS(O10)-0.03)/(0-0.03))) | AR10: =MAX(0,MIN(1,S10/0.03)) | AS10: =MAX(0,MIN(1,(-W10-0.3)/(0.15-0.3))) | AT10: =0.5*IF(L10>M10,(I10-M10)/(L10-M10),0.5)+0.5*(I10>=N10) | AU10: =MAX(0,MIN(1,(AN10-1.3)/(0.7-1.3))) | AV10: =100*(0.2*AG10+0.2*AH10+0.3*AI10+IF(AJ10="",0,0.3*AJ10))/(0.7+IF(AJ10="",0,0.3)) | AW10: =100*(0.25*AP10+0.2*AQ10+0.15*AR10+0.15*AS10+0.15*AT10+0.1*AU10) | AX10: =0.5*AV10+0.5*AW10 | AY10: =0.4*AV10+0.4*AW10+0.2*(AL10/4*100) | BA10: 18/18 | BB10: 升浪同回調都係單一臨床事件：09 月第二個星期公佈 OPGx-BEST1 第一組三個月頂線數據，多間券商將目標價加到 $13–$20，股價高位喺 09-10；之後回吐約兩成。10 月 1–4 日 EURETINA 大會再公佈詳細數據 —— 二元事件風險仲未完。 | BC10: 0
A11: =COUNTIF($AY$2:$AY$29,">"&AY11)+1 | B11: AMWL | C11: American Well Corporation Class A | D11: NYSE | E11: 非必需消費 | F11: Business Services | G11: 0.225 | H11: 小型 | I11: 13.21 | J11: 13.21 | K11: =I11/J11-1 | L11: 13.685 | M11: 13.07 | N11: 12.9115 | O11: =I11/N11-1 | P11: 12.314 | Q11: =I11/P11-1 | R11: 12.534 | S11: =N11/R11-1 | T11: 13.87 | U11: 2026-09-14 | V11: 7 | W11: =I11/T11-1 | X11: 0.11755701 | Y11: 2026-09-14 | Z11: 0.012275878 | AA11: 2026-06-22 | AB11: 0.68734793 | AC11: 0.10822148 | AD11: 0.22201665 | AE11: 0.55594817 | AF11: 1.2934028 | AG11: 0.9283906 | AH11: 0.89077758 | AI11: 0.96347197 | AJ11: 0.97175348 | AK11: 1個月、3個月、6個月 | AL11: =(AG11>=0.9)*(AC11>0)+(AH11>=0.9)*(AD11>0)+(AI11>=0.9)*(AE11>0)+IF(AJ11="",0,(AJ11>=0.9)*(AF11>0)) | AM11: 0.99602653 | AN11: 0.79651468 | AO11: 0.051508597 | AP11: =MAX(0,MIN(1,(AM11-1.2)/(0.6-1.2))) | AQ11: =MAX(0,MIN(1,(ABS(O11)-0.03)/(0-0.03))) | AR11: =MAX(0,MIN(1,S11/0.03)) | AS11: =MAX(0,MIN(1,(-W11-0.3)/(0.15-0.3))) | AT11: =0.5*IF(L11>M11,(I11-M11)/(L11-M11),0.5)+0.5*(I11>=N11) | AU11: =MAX(0,MIN(1,(AN11-1.3)/(0.7-1.3))) | AV11: =100*(0.2*AG11+0.2*AH11+0.3*AI11+IF(AJ11="",0,0.3*AJ11))/(0.7+IF(AJ11="",0,0.3)) | AW11: =100*(0.25*AP11+0.2*AQ11+0.15*AR11+0.15*AS11+0.15*AT11+0.1*AU11) | AX11: =0.5*AV11+0.5*AW11 | AY11: =0.4*AV11+0.4*AW11+0.2*(AL11/4*100) | BA11: 15/18 | BB11: 20 日成交額中位數只有 $1.3M（股票池下限 $1M），入市出市都會有滑價 | BC11: 0
A12: =COUNTIF($AY$2:$AY$29,">"&AY12)+1 | B12: SNOW | C12: Snowflake Inc. | D12: NYSE | E12: 科技 | F12: Computer Software: Prepackaged Software | G12: 118.121 | H12: 大型 | I12: 334.81 | J12: 336.59 | K12: =I12/J12-1 | L12: 348.61 | M12: 333.16 | N12: 330.8425 | O12: =I12/N12-1 | P12: 314.4722 | Q12: =I12/P12-1 | R12: 327.706 | S12: =N12/R12-1 | T12: 356.47 | U12: 2026-09-03 | V12: 13 | W12: =I12/T12-1 | X12: 0.087092096 | Y12: 2026-09-03 | Z12: -0.00040241449 | AA12: 2026-06-24 | AB12: 0.57764992 | AC12: 0.037269967 | AD12: 0.24901142 | AE12: 0.48178801 | AF12: 1.0751828 | AG12: 0.84918626 | AH12: 0.90415913 | AI12: 0.95009042 | AJ12: 0.95744681 | AK12: 2個月、3個月、6個月 | AL12: =(AG12>=0.9)*(AC12>0)+(AH12>=0.9)*(AD12>0)+(AI12>=0.9)*(AE12>0)+IF(AJ12="",0,(AJ12>=0.9)*(AF12>0)) | AM12: 0.89885555 | AN12: 0.6704598 | AO12: 0.053226137 | AP12: =MAX(0,MIN(1,(AM12-1.2)/(0.6-1.2))) | AQ12: =MAX(0,MIN(1,(ABS(O12)-0.03)/(0-0.03))) | AR12: =MAX(0,MIN(1,S12/0.03)) | AS12: =MAX(0,MIN(1,(-W12-0.3)/(0.15-0.3))) | AT12: =0.5*IF(L12>M12,(I12-M12)/(L12-M12),0.5)+0.5*(I12>=N12) | AU12: =MAX(0,MIN(1,(AN12-1.3)/(0.7-1.3))) | AV12: =100*(0.2*AG12+0.2*AH12+0.3*AI12+IF(AJ12="",0,0.3*AJ12))/(0.7+IF(AJ12="",0,0.3)) | AW12: =100*(0.25*AP12+0.2*AQ12+0.15*AR12+0.15*AS12+0.15*AT12+0.1*AU12) | AX12: =0.5*AV12+0.5*AW12 | AY12: =0.4*AV12+0.4*AW12+0.2*(AL12/4*100) | BA12: 17/18 | BC12: 0
A13: =COUNTIF($AY$2:$AY$29,">"&AY13)+1 | B13: AMPL | C13: Amplitude Inc. Class A | D13: NASDAQ | E13: 科技 | F13: Computer Software: Prepackaged Software | G13: 1.718 | H13: 小型 | I13: 13.755 | J13: 13.14 | K13: =I13/J13-1 | L13: 13.775 | M13: 12.842 | N13: 13.35575 | O13: =I13/N13-1 | P13: 11.7929 | Q13: =I13/P13-1 | R13: 13.2545 | S13: =N13/R13-1 | T13: 14.3 | U13: 2026-08-28 | V13: 17 | W13: =I13/T13-1 | X13: 0.20469484 | Y13: 2026-08-19 | Z13: -0.038466578 | AA13: 2026-06-22 | AB13: 1.2136223 | AC13: 0.046007605 | AD13: 0.69814815 | AE13: 1.0139092 | AF13: 1.0377778 | AG13: 0.86220615 | AH13: 0.98698011 | AI13: 0.99168174 | AJ13: 0.95487894 | AK13: 2個月、3個月、6個月 | AL13: =(AG13>=0.9)*(AC13>0)+(AH13>=0.9)*(AD13>0)+(AI13>=0.9)*(AE13>0)+IF(AJ13="",0,(AJ13>=0.9)*(AF13>0)) | AM13: 0.71519412 | AN13: 0.96644907 | AO13: 0.047037441 | AP13: =MAX(0,MIN(1,(AM13-1.2)/(0.6-1.2))) | AQ13: =MAX(0,MIN(1,(ABS(O13)-0.03)/(0-0.03))) | AR13: =MAX(0,MIN(1,S13/0.03)) | AS13: =MAX(0,MIN(1,(-W13-0.3)/(0.15-0.3))) | AT13: =0.5*IF(L13>M13,(I13-M13)/(L13-M13),0.5)+0.5*(I13>=N13) | AU13: =MAX(0,MIN(1,(AN13-1.3)/(0.7-1.3))) | AV13: =100*(0.2*AG13+0.2*AH13+0.3*AI13+IF(AJ13="",0,0.3*AJ13))/(0.7+IF(AJ13="",0,0.3)) | AW13: =100*(0.25*AP13+0.2*AQ13+0.15*AR13+0.15*AS13+0.15*AT13+0.1*AU13) | AX13: =0.5*AV13+0.5*AW13 | AY13: =0.4*AV13+0.4*AW13+0.2*(AL13/4*100) | BA13: 16/18 | BC13: 0
A14: =COUNTIF($AY$2:$AY$29,">"&AY14)+1 | B14: DHX | C14: DHI Group Inc. | D14: NYSE | E14: 非必需消費 | F14: Business Services | G14: 0.2 | H14: 小型 | I14: 4.6 | J14: 4.71 | K14: =I14/J14-1 | L14: 4.72 | M14: 4.56 | N14: 4.5745 | O14: =I14/N14-1 | P14: 4.2628 | Q14: =I14/P14-1 | R14: 4.434 | S14: =N14/R14-1 | T14: 4.99 | U14: 2026-09-17 | V14: 4 | W14: =I14/T14-1 | X14: 0.11834177 | Y14: 2026-09-02 | Z14: -0.0031697453 | AA14: 2026-06-25 | AB14: 0.40960452 | AC14: 0.090047393 | AD14: 0.19480519 | AE14: 0.2568306 | AF14: 0.7037037 | AG14: 0.91537071 | AH14: 0.87594937 | AI14: 0.88860759 | AJ14: 0.91599413 | AK14: 1個月、6個月 | AL14: =(AG14>=0.9)*(AC14>0)+(AH14>=0.9)*(AD14>0)+(AI14>=0.9)*(AE14>0)+IF(AJ14="",0,(AJ14>=0.9)*(AF14>0)) | AM14: 1.0684174 | AN14: 0.6654479 | AO14: 0.054813665 | AP14: =MAX(0,MIN(1,(AM14-1.2)/(0.6-1.2))) | AQ14: =MAX(0,MIN(1,(ABS(O14)-0.03)/(0-0.03))) | AR14: =MAX(0,MIN(1,S14/0.03)) | AS14: =MAX(0,MIN(1,(-W14-0.3)/(0.15-0.3))) | AT14: =0.5*IF(L14>M14,(I14-M14)/(L14-M14),0.5)+0.5*(I14>=N14) | AU14: =MAX(0,MIN(1,(AN14-1.3)/(0.7-1.3))) | AV14: =100*(0.2*AG14+0.2*AH14+0.3*AI14+IF(AJ14="",0,0.3*AJ14))/(0.7+IF(AJ14="",0,0.3)) | AW14: =100*(0.25*AP14+0.2*AQ14+0.15*AR14+0.15*AS14+0.15*AT14+0.1*AU14) | AX14: =0.5*AV14+0.5*AW14 | AY14: =0.4*AV14+0.4*AW14+0.2*(AL14/4*100) | BA14: 17/18 | BB14: 20 日成交額中位數只有 $1.3M（股票池下限 $1M），入市出市都會有滑價 | BC14: 0
A15: =COUNTIF($AY$2:$AY$29,">"&AY15)+1 | B15: ZETA | C15: Zeta Global Holdings Corp. Class A | D15: NYSE | E15: 科技 | F15: Computer Software: Prepackaged Software | G15: 7.478 | H15: 中型 | I15: 29.79 | J15: 30.13 | K15: =I15/J15-1 | L15: 30.875 | M15: 29.76 | N15: 30.6255 | O15: =I15/N15-1 | P15: 27.1204 | Q15: =I15/P15-1 | R15: 30.145 | S15: =N15/R15-1 | T15: 32.68 | U15: 2026-09-03 | V15: 13 | W15: =I15/T15-1 | X15: 0.14692056 | Y15: 2026-08-19 | Z15: -0.032885686 | AA15: 2026-06-25 | AB15: 0.82774049 | AC15: 0.046364594 | AD15: 0.55723994 | AE15: 0.58121019 | AF15: 0.84458204 | AG15: 0.86256781 | AH15: 0.97649186 | AI15: 0.9681736 | AJ15: 0.93396919 | AK15: 2個月、3個月、6個月 | AL15: =(AG15>=0.9)*(AC15>0)+(AH15>=0.9)*(AD15>0)+(AI15>=0.9)*(AE15>0)+IF(AJ15="",0,(AJ15>=0.9)*(AF15>0)) | AM15: 0.64369992 | AN15: 1.0068426 | AO15: 0.048093799 | AP15: =MAX(0,MIN(1,(AM15-1.2)/(0.6-1.2))) | AQ15: =MAX(0,MIN(1,(ABS(O15)-0.03)/(0-0.03))) | AR15: =MAX(0,MIN(1,S15/0.03)) | AS15: =MAX(0,MIN(1,(-W15-0.3)/(0.15-0.3))) | AT15: =0.5*IF(L15>M15,(I15-M15)/(L15-M15),0.5)+0.5*(I15>=N15) | AU15: =MAX(0,MIN(1,(AN15-1.3)/(0.7-1.3))) | AV15: =100*(0.2*AG15+0.2*AH15+0.3*AI15+IF(AJ15="",0,0.3*AJ15))/(0.7+IF(AJ15="",0,0.3)) | AW15: =100*(0.25*AP15+0.2*AQ15+0.15*AR15+0.15*AS15+0.15*AT15+0.1*AU15) | AX15: =0.5*AV15+0.5*AW15 | AY15: =0.4*AV15+0.4*AW15+0.2*(AL15/4*100) | BA15: 17/18 | BC15: 0
A16: =COUNTIF($AY$2:$AY$29,">"&AY16)+1 | B16: DINO | C16: HF Sinclair Corporation | D16: NYSE | E16: 能源 | F16: Natural Gas Distribution | G16: 18.87 | H16: 大型 | I16: 106.14 | J16: 106.69 | K16: =I16/J16-1 | L16: 110.84 | M16: 103 | N16: 106.8105 | O16: =I16/N16-1 | P16: 96.6426 | Q16: =I16/P16-1 | R16: 102.7325 | S16: =N16/R16-1 | T16: 116.62 | U16: 2026-09-17 | V16: 4 | W16: =I16/T16-1 | X16: 0.1299748 | Y16: 2026-09-02 | Z16: -0.035675332 | AA16: 2026-06-18 | AB16: 0.80806202 | AC16: 0.11515024 | AD16: 0.20203851 | AE16: 0.61405109 | AF16: 0.72753906 | AG16: 0.93273056 | AH16: 0.87848101 | AI16: 0.97179024 | AJ16: 0.91966251 | AK16: 1個月、3個月、6個月 | AL16: =(AG16>=0.9)*(AC16>0)+(AH16>=0.9)*(AD16>0)+(AI16>=0.9)*(AE16>0)+IF(AJ16="",0,(AJ16>=0.9)*(AF16>0)) | AM16: 1.9662104 | AN16: 1.2236536 | AO16: 0.046818219 | AP16: =MAX(0,MIN(1,(AM16-1.2)/(0.6-1.2))) | AQ16: =MAX(0,MIN(1,(ABS(O16)-0.03)/(0-0.03))) | AR16: =MAX(0,MIN(1,S16/0.03)) | AS16: =MAX(0,MIN(1,(-W16-0.3)/(0.15-0.3))) | AT16: =0.5*IF(L16>M16,(I16-M16)/(L16-M16),0.5)+0.5*(I16>=N16) | AU16: =MAX(0,MIN(1,(AN16-1.3)/(0.7-1.3))) | AV16: =100*(0.2*AG16+0.2*AH16+0.3*AI16+IF(AJ16="",0,0.3*AJ16))/(0.7+IF(AJ16="",0,0.3)) | AW16: =100*(0.25*AP16+0.2*AQ16+0.15*AR16+0.15*AS16+0.15*AT16+0.1*AU16) | AX16: =0.5*AV16+0.5*AW16 | AY16: =0.4*AV16+0.4*AW16+0.2*(AL16/4*100) | BA16: 18/18 | BB16: 今日放量（1.7× 50日均量）收喺 20MA 下面；09-22 Jefferies 將 VLO、MPC 由買入降至持有（目標 $401／$413，理由係大升後估值偏高）；同日 Bloomberg 報道柴油出口禁令提案獲政治支持，煉油股升勢停頓。回調有明確評級同政策催化，唔係單純技術性回吐。（五隻 21 日相關系數中位數 +0.89，名單其餘 +0.08） | BC16: 0
A17: =COUNTIF($AY$2:$AY$29,">"&AY17)+1 | B17: MGNI | C17: Magnite Inc. | D17: NASDAQ | E17: 科技 | F17: Computer Software: Programming Data Processing | G17: 3.451 | H17: 中型 | I17: 24.06 | J17: 24.8 | K17: =I17/J17-1 | L17: 24.71 | M17: 23.87 | N17: 24.0675 | O17: =I17/N17-1 | P17: 22.5992 | Q17: =I17/P17-1 | R17: 23.7275 | S17: =N17/R17-1 | T17: 25.63 | U17: 2026-09-17 | V17: 4 | W17: =I17/T17-1 | X17: 0.087774509 | Y17: 2026-08-19 | Z17: -0.008206087 | AA17: 2026-06-25 | AB17: 0.47979215 | AC17: 0.021222411 | AD17: 0.29983793 | AE17: 0.31547294 | AF17: 1 | AG17: 0.82206148 | AH17: 0.92368897 | AI17: 0.91392405 | AJ17: 0.95047689 | AK17: 2個月、3個月、6個月 | AL17: =(AG17>=0.9)*(AC17>0)+(AH17>=0.9)*(AD17>0)+(AI17>=0.9)*(AE17>0)+IF(AJ17="",0,(AJ17>=0.9)*(AF17>0)) | AM17: 1.0546424 | AN17: 1.270751 | AO17: 0.039929937 | AP17: =MAX(0,MIN(1,(AM17-1.2)/(0.6-1.2))) | AQ17: =MAX(0,MIN(1,(ABS(O17)-0.03)/(0-0.03))) | AR17: =MAX(0,MIN(1,S17/0.03)) | AS17: =MAX(0,MIN(1,(-W17-0.3)/(0.15-0.3))) | AT17: =0.5*IF(L17>M17,(I17-M17)/(L17-M17),0.5)+0.5*(I17>=N17) | AU17: =MAX(0,MIN(1,(AN17-1.3)/(0.7-1.3))) | AV17: =100*(0.2*AG17+0.2*AH17+0.3*AI17+IF(AJ17="",0,0.3*AJ17))/(0.7+IF(AJ17="",0,0.3)) | AW17: =100*(0.25*AP17+0.2*AQ17+0.15*AR17+0.15*AS17+0.15*AT17+0.1*AU17) | AX17: =0.5*AV17+0.5*AW17 | AY17: =0.4*AV17+0.4*AW17+0.2*(AL17/4*100) | BA17: 17/18 | BC17: 0
A18: =COUNTIF($AY$2:$AY$29,">"&AY18)+1 | B18: VLO | C18: Valero Energy Corporation | D18: NYSE | E18: 能源 | F18: Integrated oil Companies | G18: 108.215 | H18: 大型 | I18: 375.84 | J18: 377.14 | K18: =I18/J18-1 | L18: 388.01 | M18: 364.96 | N18: 378.9185 | O18: =I18/N18-1 | P18: 343.0276 | Q18: =I18/P18-1 | R18: 366.4675 | S18: =N18/R18-1 | T18: 413.28 | U18: 2026-09-18 | V18: 3 | W18: =I18/T18-1 | X18: 0.11560626 | Y18: 2026-09-17 | Z18: -0.036837737 | AA18: 2026-06-18 | AB18: 0.74896318 | AC18: 0.086242775 | AD18: 0.24244628 | AE18: 0.55030318 | AF18: 0.55466391 | AG18: 0.91103074 | AH18: 0.90090416 | AI18: 0.96057866 | AJ18: 0.88407924 | AK18: 1個月、2個月、3個月 | AL18: =(AG18>=0.9)*(AC18>0)+(AH18>=0.9)*(AD18>0)+(AI18>=0.9)*(AE18>0)+IF(AJ18="",0,(AJ18>=0.9)*(AF18>0)) | AM18: 1.9568585 | AN18: 1.2906809 | AO18: 0.043386623 | AP18: =MAX(0,MIN(1,(AM18-1.2)/(0.6-1.2))) | AQ18: =MAX(0,MIN(1,(ABS(O18)-0.03)/(0-0.03))) | AR18: =MAX(0,MIN(1,S18/0.03)) | AS18: =MAX(0,MIN(1,(-W18-0.3)/(0.15-0.3))) | AT18: =0.5*IF(L18>M18,(I18-M18)/(L18-M18),0.5)+0.5*(I18>=N18) | AU18: =MAX(0,MIN(1,(AN18-1.3)/(0.7-1.3))) | AV18: =100*(0.2*AG18+0.2*AH18+0.3*AI18+IF(AJ18="",0,0.3*AJ18))/(0.7+IF(AJ18="",0,0.3)) | AW18: =100*(0.25*AP18+0.2*AQ18+0.15*AR18+0.15*AS18+0.15*AT18+0.1*AU18) | AX18: =0.5*AV18+0.5*AW18 | AY18: =0.4*AV18+0.4*AW18+0.2*(AL18/4*100) | BA18: 18/18 | BB18: 今日放量（2.3× 50日均量）收喺 20MA 下面；09-22 Jefferies 將 VLO、MPC 由買入降至持有（目標 $401／$413，理由係大升後估值偏高）；同日 Bloomberg 報道柴油出口禁令提案獲政治支持，煉油股升勢停頓。回調有明確評級同政策催化，唔係單純技術性回吐。（五隻 21 日相關系數中位數 +0.89，名單其餘 +0.08） | BC18: 0
A19: =COUNTIF($AY$2:$AY$29,">"&AY19)+1 | B19: SABR | C19: Sabre Corporation | D19: NASDAQ | E19: 科技 | F19: Computer Software: Programming Data Processing | G19: 0.884 | H19: 小型 | I19: 2.19 | J19: 2.27 | K19: =I19/J19-1 | L19: 2.25 | M19: 2.16 | N19: 2.18175 | O19: =I19/N19-1 | P19: 2.0548 | Q19: =I19/P19-1 | R19: 2.15375 | S19: =N19/R19-1 | T19: 2.33 | U19: 2026-09-21 | V19: 2 | W19: =I19/T19-1 | X19: 0.094298511 | Y19: 2026-08-24 | Z19: -0.0099690615 | AA19: 2026-07-22 | AB19: 0.40361446 | AC19: -0.030973451 | AD19: 0.31927711 | AE19: 0.16489362 | AF19: 0.54225352 | AG19: 0.62495479 | AH19: 0.93056058 | AI19: 0.83110307 | AJ19: 0.88114453 | AK19: 2個月 | AL19: =(AG19>=0.9)*(AC19>0)+(AH19>=0.9)*(AD19>0)+(AI19>=0.9)*(AE19>0)+IF(AJ19="",0,(AJ19>=0.9)*(AF19>0)) | AM19: 0.83835512 | AN19: 0.88335221 | AO19: 0.060795825 | AP19: =MAX(0,MIN(1,(AM19-1.2)/(0.6-1.2))) | AQ19: =MAX(0,MIN(1,(ABS(O19)-0.03)/(0-0.03))) | AR19: =MAX(0,MIN(1,S19/0.03)) | AS19: =MAX(0,MIN(1,(-W19-0.3)/(0.15-0.3))) | AT19: =0.5*IF(L19>M19,(I19-M19)/(L19-M19),0.5)+0.5*(I19>=N19) | AU19: =MAX(0,MIN(1,(AN19-1.3)/(0.7-1.3))) | AV19: =100*(0.2*AG19+0.2*AH19+0.3*AI19+IF(AJ19="",0,0.3*AJ19))/(0.7+IF(AJ19="",0,0.3)) | AW19: =100*(0.25*AP19+0.2*AQ19+0.15*AR19+0.15*AS19+0.15*AT19+0.1*AU19) | AX19: =0.5*AV19+0.5*AW19 | AY19: =0.4*AV19+0.4*AW19+0.2*(AL19/4*100) | BA19: 16/18 | BB19: 收市 $2.19，貼近股票池 $2 下限；1 個月回報 -3%，靠 2個月 動能上榜 | BC19: 0
A20: =COUNTIF($AY$2:$AY$29,">"&AY20)+1 | B20: VIR | C20: Vir Biotechnology Inc. | D20: NASDAQ | E20: 醫療保健 | F20: Biotechnology: Biological Products (No Diagnostic Substances) | G20: 1.877 | H20: 小型 | I20: 11.09 | J20: 11.5 | K20: =I20/J20-1 | L20: 11.53 | M20: 10.85 | N20: 11.0015 | O20: =I20/N20-1 | P20: 9.9279 | Q20: =I20/P20-1 | R20: 10.721 | S20: =N20/R20-1 | T20: 11.63 | U20: 2026-09-01 | V20: 15 | W20: =I20/T20-1 | X20: 0.19622412 | Y20: 2026-08-27 | Z20: -0.022287444 | AA20: 2026-06-10 | AB20: 0.40969697 | AC20: 0.11907164 | AD20: 0.27617952 | AE20: 0.11457286 | AF20: 0.29404901 | AG20: 0.9363472 | AH20: 0.91717902 | AI20: 0.77142857 | AJ20: 0.76889215 | AK20: 1個月、2個月 | AL20: =(AG20>=0.9)*(AC20>0)+(AH20>=0.9)*(AD20>0)+(AI20>=0.9)*(AE20>0)+IF(AJ20="",0,(AJ20>=0.9)*(AF20>0)) | AM20: 1.2737592 | AN20: 1.0357495 | AO20: 0.045150071 | AP20: =MAX(0,MIN(1,(AM20-1.2)/(0.6-1.2))) | AQ20: =MAX(0,MIN(1,(ABS(O20)-0.03)/(0-0.03))) | AR20: =MAX(0,MIN(1,S20/0.03)) | AS20: =MAX(0,MIN(1,(-W20-0.3)/(0.15-0.3))) | AT20: =0.5*IF(L20>M20,(I20-M20)/(L20-M20),0.5)+0.5*(I20>=N20) | AU20: =MAX(0,MIN(1,(AN20-1.3)/(0.7-1.3))) | AV20: =100*(0.2*AG20+0.2*AH20+0.3*AI20+IF(AJ20="",0,0.3*AJ20))/(0.7+IF(AJ20="",0,0.3)) | AW20: =100*(0.25*AP20+0.2*AQ20+0.15*AR20+0.15*AS20+0.15*AT20+0.1*AU20) | AX20: =0.5*AV20+0.5*AW20 | AY20: =0.4*AV20+0.4*AW20+0.2*(AL20/4*100) | BA20: 16/18 | BC20: 0
A21: =COUNTIF($AY$2:$AY$29,">"&AY21)+1 | B21: MPC | C21: Marathon Petroleum Corporation | D21: NYSE | E21: 能源 | F21: Integrated oil Companies | G21: 109.067 | H21: 大型 | I21: 388.38 | J21: 389.68 | K21: =I21/J21-1 | L21: 400.72 | M21: 378.8 | N21: 392.4315 | O21: =I21/N21-1 | P21: 352.9888 | Q21: =I21/P21-1 | R21: 380.922 | S21: =N21/R21-1 | T21: 424.89 | U21: 2026-09-18 | V21: 3 | W21: =I21/T21-1 | X21: 0.11069376 | Y21: 2026-08-19 | Z21: -0.034735999 | AA21: 2026-06-18 | AB21: 0.74916636 | AC21: 0.071333995 | AD21: 0.25591773 | AE21: 0.57551418 | AF21: 0.59230864 | AG21: 0.89475588 | AH21: 0.90777577 | AI21: 0.96600362 | AJ21: 0.89288335 | AK21: 2個月、3個月 | AL21: =(AG21>=0.9)*(AC21>0)+(AH21>=0.9)*(AD21>0)+(AI21>=0.9)*(AE21>0)+IF(AJ21="",0,(AJ21>=0.9)*(AF21>0)) | AM21: 1.5687827 | AN21: 1.2723242 | AO21: 0.041014691 | AP21: =MAX(0,MIN(1,(AM21-1.2)/(0.6-1.2))) | AQ21: =MAX(0,MIN(1,(ABS(O21)-0.03)/(0-0.03))) | AR21: =MAX(0,MIN(1,S21/0.03)) | AS21: =MAX(0,MIN(1,(-W21-0.3)/(0.15-0.3))) | AT21: =0.5*IF(L21>M21,(I21-M21)/(L21-M21),0.5)+0.5*(I21>=N21) | AU21: =MAX(0,MIN(1,(AN21-1.3)/(0.7-1.3))) | AV21: =100*(0.2*AG21+0.2*AH21+0.3*AI21+IF(AJ21="",0,0.3*AJ21))/(0.7+IF(AJ21="",0,0.3)) | AW21: =100*(0.25*AP21+0.2*AQ21+0.15*AR21+0.15*AS21+0.15*AT21+0.1*AU21) | AX21: =0.5*AV21+0.5*AW21 | AY21: =0.4*AV21+0.4*AW21+0.2*(AL21/4*100) | BA21: 18/18 | BB21: 今日放量（1.6× 50日均量）收喺 20MA 下面；09-22 Jefferies 將 VLO、MPC 由買入降至持有（目標 $401／$413，理由係大升後估值偏高）；同日 Bloomberg 報道柴油出口禁令提案獲政治支持，煉油股升勢停頓。回調有明確評級同政策催化，唔係單純技術性回吐。（五隻 21 日相關系數中位數 +0.89，名單其餘 +0.08） | BC21: 0
A22: =COUNTIF($AY$2:$AY$29,">"&AY22)+1 | B22: SGP | C22: SpyGlass Pharma Inc. | D22: NASDAQ | E22: 醫療保健 | F22: Medical/Dental Instruments | G22: 0.942 | H22: 小型 | I22: 28.16 | J22: 28.69 | K22: =I22/J22-1 | L22: 29.28 | M22: 27.76 | N22: 27.9925 | O22: =I22/N22-1 | P22: 25.2882 | Q22: =I22/P22-1 | R22: 27.473 | S22: =N22/R22-1 | T22: 29.33 | U22: 2026-09-17 | V22: 4 | W22: =I22/T22-1 | X22: 0.14171908 | Y22: 2026-08-19 | Z22: -0.018098082 | AA22: 2026-06-17 | AB22: 0.61153846 | AC22: 0.072353389 | AD22: 0.37432894 | AE22: 0.44040921 | AF22: 0.18618366 | AG22: 0.89692586 | AH22: 0.94792043 | AI22: 0.94249548 | AJ22: 0.65957447 | AK22: 2個月、3個月 | AL22: =(AG22>=0.9)*(AC22>0)+(AH22>=0.9)*(AD22>0)+(AI22>=0.9)*(AE22>0)+IF(AJ22="",0,(AJ22>=0.9)*(AF22>0)) | AM22: 2.7303323 | AN22: 1.0856198 | AO22: 0.056539164 | AP22: =MAX(0,MIN(1,(AM22-1.2)/(0.6-1.2))) | AQ22: =MAX(0,MIN(1,(ABS(O22)-0.03)/(0-0.03))) | AR22: =MAX(0,MIN(1,S22/0.03)) | AS22: =MAX(0,MIN(1,(-W22-0.3)/(0.15-0.3))) | AT22: =0.5*IF(L22>M22,(I22-M22)/(L22-M22),0.5)+0.5*(I22>=N22) | AU22: =MAX(0,MIN(1,(AN22-1.3)/(0.7-1.3))) | AV22: =100*(0.2*AG22+0.2*AH22+0.3*AI22+IF(AJ22="",0,0.3*AJ22))/(0.7+IF(AJ22="",0,0.3)) | AW22: =100*(0.25*AP22+0.2*AQ22+0.15*AR22+0.15*AS22+0.15*AT22+0.1*AU22) | AX22: =0.5*AV22+0.5*AW22 | AY22: =0.4*AV22+0.4*AW22+0.2*(AL22/4*100) | AZ22: 有 | BA22: 16/18 | BB22: 20 日成交額中位數只有 $3.3M（股票池下限 $1M），入市出市都會有滑價 | BC22: 0
A23: =COUNTIF($AY$2:$AY$29,">"&AY23)+1 | B23: ANGX | C23: Angel Studios Inc. Class A | D23: NYSE | E23: 非必需消費 | F23: Movies/Entertainment | G23: 0.906 | H23: 小型 | I23: 4.85 | J23: 5.1 | K23: =I23/J23-1 | L23: 5.04 | M23: 4.73 | N23: 4.871 | O23: =I23/N23-1 | P23: 4.5058 | Q23: =I23/P23-1 | R23: 4.724 | S23: =N23/R23-1 | T23: 5.48 | U23: 2026-09-14 | V23: 7 | W23: =I23/T23-1 | X23: 0.18016457 | Y23: 2026-09-11 | Z23: -0.028946828 | AA23: 2026-06-12 | AB23: 0.88965517 | AC23: 0.068281938 | AD23: 0.19753086 | AE23: 0.53481013 | AG23: 0.89294756 | AH23: 0.87775769 | AI23: 0.95840868 | AK23: 3個月 | AL23: =(AG23>=0.9)*(AC23>0)+(AH23>=0.9)*(AD23>0)+(AI23>=0.9)*(AE23>0)+IF(AJ23="",0,(AJ23>=0.9)*(AF23>0)) | AM23: 1.8452409 | AN23: 1.156051 | AO23: 0.072164948 | AP23: =MAX(0,MIN(1,(AM23-1.2)/(0.6-1.2))) | AQ23: =MAX(0,MIN(1,(ABS(O23)-0.03)/(0-0.03))) | AR23: =MAX(0,MIN(1,S23/0.03)) | AS23: =MAX(0,MIN(1,(-W23-0.3)/(0.15-0.3))) | AT23: =0.5*IF(L23>M23,(I23-M23)/(L23-M23),0.5)+0.5*(I23>=N23) | AU23: =MAX(0,MIN(1,(AN23-1.3)/(0.7-1.3))) | AV23: =100*(0.2*AG23+0.2*AH23+0.3*AI23+IF(AJ23="",0,0.3*AJ23))/(0.7+IF(AJ23="",0,0.3)) | AW23: =100*(0.25*AP23+0.2*AQ23+0.15*AR23+0.15*AS23+0.15*AT23+0.1*AU23) | AX23: =0.5*AV23+0.5*AW23 | AY23: =0.4*AV23+0.4*AW23+0.2*(AL23/4*100) | BA23: 18/18 | BC23: 0
A24: =COUNTIF($AY$2:$AY$29,">"&AY24)+1 | B24: DJCO | C24: Daily Journal Corp. (S.C.) | D24: NASDAQ | E24: 非必需消費 | F24: Newspapers/Magazines | G24: 0.909 | H24: 小型 | I24: 659.4 | J24: 657.01 | K24: =I24/J24-1 | L24: 666.83 | M24: 650.21 | N24: 645.834 | O24: =I24/N24-1 | P24: 612.2838 | Q24: =I24/P24-1 | R24: 632.6375 | S24: =N24/R24-1 | T24: 687.66 | U24: 2026-09-15 | V24: 6 | W24: =I24/T24-1 | X24: 0.093407768 | Y24: 2026-09-15 | Z24: 2.7287789e-05 | AA24: 2026-06-22 | AB24: 0.30428845 | AC24: 0.085861081 | AD24: 0.1465832 | AE24: 0.21676231 | AF24: 0.35117413 | AG24: 0.90994575 | AH24: 0.84195298 | AI24: 0.86943942 | AJ24: 0.80337491 | AK24: 1個月 | AL24: =(AG24>=0.9)*(AC24>0)+(AH24>=0.9)*(AD24>0)+(AI24>=0.9)*(AE24>0)+IF(AJ24="",0,(AJ24>=0.9)*(AF24>0)) | AM24: 1.1361403 | AN24: 0.81065981 | AO24: 0.034727458 | AP24: =MAX(0,MIN(1,(AM24-1.2)/(0.6-1.2))) | AQ24: =MAX(0,MIN(1,(ABS(O24)-0.03)/(0-0.03))) | AR24: =MAX(0,MIN(1,S24/0.03)) | AS24: =MAX(0,MIN(1,(-W24-0.3)/(0.15-0.3))) | AT24: =0.5*IF(L24>M24,(I24-M24)/(L24-M24),0.5)+0.5*(I24>=N24) | AU24: =MAX(0,MIN(1,(AN24-1.3)/(0.7-1.3))) | AV24: =100*(0.2*AG24+0.2*AH24+0.3*AI24+IF(AJ24="",0,0.3*AJ24))/(0.7+IF(AJ24="",0,0.3)) | AW24: =100*(0.25*AP24+0.2*AQ24+0.15*AR24+0.15*AS24+0.15*AT24+0.1*AU24) | AX24: =0.5*AV24+0.5*AW24 | AY24: =0.4*AV24+0.4*AW24+0.2*(AL24/4*100) | BA24: 13/18 | BC24: 1e-05
A25: =COUNTIF($AY$2:$AY$29,">"&AY25)+1 | B25: PSX | C25: Phillips 66 | D25: NYSE | E25: 能源 | F25: Integrated oil Companies | G25: 102.341 | H25: 大型 | I25: 256.48 | J25: 256.78 | K25: =I25/J25-1 | L25: 263.82 | M25: 250.26 | N25: 256.868 | O25: =I25/N25-1 | P25: 233.4898 | Q25: =I25/P25-1 | R25: 250.9515 | S25: =N25/R25-1 | T25: 274.21 | U25: 2026-09-17 | V25: 4 | W25: =I25/T25-1 | X25: 0.11690922 | Y25: 2026-08-19 | Z25: -0.025725275 | AA25: 2026-06-18 | AB25: 0.6504755 | AC25: 0.060009919 | AD25: 0.24041205 | AE25: 0.52087287 | AF25: 0.39300456 | AG25: 0.88137432 | AH25: 0.8994575 | AI25: 0.95587703 | AJ25: 0.83015407 | AK25: 3個月 | AL25: =(AG25>=0.9)*(AC25>0)+(AH25>=0.9)*(AD25>0)+(AI25>=0.9)*(AE25>0)+IF(AJ25="",0,(AJ25>=0.9)*(AF25>0)) | AM25: 2.0108968 | AN25: 1.2914021 | AO25: 0.034413711 | AP25: =MAX(0,MIN(1,(AM25-1.2)/(0.6-1.2))) | AQ25: =MAX(0,MIN(1,(ABS(O25)-0.03)/(0-0.03))) | AR25: =MAX(0,MIN(1,S25/0.03)) | AS25: =MAX(0,MIN(1,(-W25-0.3)/(0.15-0.3))) | AT25: =0.5*IF(L25>M25,(I25-M25)/(L25-M25),0.5)+0.5*(I25>=N25) | AU25: =MAX(0,MIN(1,(AN25-1.3)/(0.7-1.3))) | AV25: =100*(0.2*AG25+0.2*AH25+0.3*AI25+IF(AJ25="",0,0.3*AJ25))/(0.7+IF(AJ25="",0,0.3)) | AW25: =100*(0.25*AP25+0.2*AQ25+0.15*AR25+0.15*AS25+0.15*AT25+0.1*AU25) | AX25: =0.5*AV25+0.5*AW25 | AY25: =0.4*AV25+0.4*AW25+0.2*(AL25/4*100) | BA25: 18/18 | BB25: 09-22 Jefferies 將 VLO、MPC 由買入降至持有（目標 $401／$413，理由係大升後估值偏高）；同日 Bloomberg 報道柴油出口禁令提案獲政治支持，煉油股升勢停頓。回調有明確評級同政策催化，唔係單純技術性回吐。（五隻 21 日相關系數中位數 +0.89，名單其餘 +0.08） | BC25: 0
A26: =COUNTIF($AY$2:$AY$29,">"&AY26)+1 | B26: LPG | C26: Dorian LPG Ltd. | D26: NYSE | E26: 非必需消費 | F26: Marine Transportation | G26: 2.274 | H26: 中型 | I26: 53.16 | J26: 53.54 | K26: =I26/J26-1 | L26: 54.025 | M26: 52.09 | N26: 53.7665 | O26: =I26/N26-1 | P26: 48.948 | Q26: =I26/P26-1 | R26: 52.4025 | S26: =N26/R26-1 | T26: 58.31 | U26: 2026-09-17 | V26: 4 | W26: =I26/T26-1 | X26: 0.1223162 | Y26: 2026-09-04 | Z26: -0.031181126 | AA26: 2026-06-30 | AB26: 0.67653824 | AC26: 0.035853468 | AD26: 0.17299206 | AE26: 0.33166333 | AF26: 0.53686036 | AG26: 0.84737794 | AH26: 0.86220615 | AI26: 0.91754069 | AJ26: 0.87967718 | AK26: 3個月 | AL26: =(AG26>=0.9)*(AC26>0)+(AH26>=0.9)*(AD26>0)+(AI26>=0.9)*(AE26>0)+IF(AJ26="",0,(AJ26>=0.9)*(AF26>0)) | AM26: 1.3653588 | AN26: 1.0328014 | AO26: 0.038244384 | AP26: =MAX(0,MIN(1,(AM26-1.2)/(0.6-1.2))) | AQ26: =MAX(0,MIN(1,(ABS(O26)-0.03)/(0-0.03))) | AR26: =MAX(0,MIN(1,S26/0.03)) | AS26: =MAX(0,MIN(1,(-W26-0.3)/(0.15-0.3))) | AT26: =0.5*IF(L26>M26,(I26-M26)/(L26-M26),0.5)+0.5*(I26>=N26) | AU26: =MAX(0,MIN(1,(AN26-1.3)/(0.7-1.3))) | AV26: =100*(0.2*AG26+0.2*AH26+0.3*AI26+IF(AJ26="",0,0.3*AJ26))/(0.7+IF(AJ26="",0,0.3)) | AW26: =100*(0.25*AP26+0.2*AQ26+0.15*AR26+0.15*AS26+0.15*AT26+0.1*AU26) | AX26: =0.5*AV26+0.5*AW26 | AY26: =0.4*AV26+0.4*AW26+0.2*(AL26/4*100) | BA26: 17/18 | BC26: 0
A27: =COUNTIF($AY$2:$AY$29,">"&AY27)+1 | B27: REPX | C27: Riley Exploration Permian Inc. | D27: AMEX | E27: 能源 | F27: Oil & Gas Production | G27: 0.91 | H27: 小型 | I27: 41.07 | J27: 40.2 | K27: =I27/J27-1 | L27: 41.61 | M27: 39.96 | N27: 41.521 | O27: =I27/N27-1 | P27: 37.87 | Q27: =I27/P27-1 | R27: 40.506 | S27: =N27/R27-1 | T27: 44.9 | U27: 2026-09-15 | V27: 6 | W27: =I27/T27-1 | X27: 0.11703822 | Y27: 2026-09-03 | Z27: -0.037595434 | AA27: 2026-07-06 | AB27: 0.41417323 | AC27: 0.091706539 | AD27: 0.15755355 | AE27: 0.25634751 | AF27: 0.13735807 | AG27: 0.91862568 | AH27: 0.84990958 | AI27: 0.88824593 | AJ27: 0.59611152 | AK27: 1個月 | AL27: =(AG27>=0.9)*(AC27>0)+(AH27>=0.9)*(AD27>0)+(AI27>=0.9)*(AE27>0)+IF(AJ27="",0,(AJ27>=0.9)*(AF27>0)) | AM27: 2.1731467 | AN27: 1.0563476 | AO27: 0.036644753 | AP27: =MAX(0,MIN(1,(AM27-1.2)/(0.6-1.2))) | AQ27: =MAX(0,MIN(1,(ABS(O27)-0.03)/(0-0.03))) | AR27: =MAX(0,MIN(1,S27/0.03)) | AS27: =MAX(0,MIN(1,(-W27-0.3)/(0.15-0.3))) | AT27: =0.5*IF(L27>M27,(I27-M27)/(L27-M27),0.5)+0.5*(I27>=N27) | AU27: =MAX(0,MIN(1,(AN27-1.3)/(0.7-1.3))) | AV27: =100*(0.2*AG27+0.2*AH27+0.3*AI27+IF(AJ27="",0,0.3*AJ27))/(0.7+IF(AJ27="",0,0.3)) | AW27: =100*(0.25*AP27+0.2*AQ27+0.15*AR27+0.15*AS27+0.15*AT27+0.1*AU27) | AX27: =0.5*AV27+0.5*AW27 | AY27: =0.4*AV27+0.4*AW27+0.2*(AL27/4*100) | AZ27: 有 | BA27: 17/18 | BC27: 0
A28: =COUNTIF($AY$2:$AY$29,">"&AY28)+1 | B28: APA | C28: APA Corporation | D28: NASDAQ | E28: 能源 | F28: Oil & Gas Production | G28: 15.31 | H28: 大型 | I28: 43.7 | J28: 42.3 | K28: =I28/J28-1 | L28: 44.19 | M28: 42.3 | N28: 44.0115 | O28: =I28/N28-1 | P28: 40.5288 | Q28: =I28/P28-1 | R28: 43.7815 | S28: =N28/R28-1 | T28: 47.41 | U28: 2026-09-15 | V28: 6 | W28: =I28/T28-1 | X28: 0.15070056 | Y28: 2026-08-20 | Z28: -0.038887563 | AA28: 2026-07-01 | AB28: 0.4876059 | AC28: 0.017225326 | AD28: 0.20885201 | AE28: 0.31113111 | AF28: 0.071078431 | AG28: 0.81084991 | AH28: 0.8835443 | AI28: 0.91283906 | AJ28: 0.49816581 | AK28: 3個月 | AL28: =(AG28>=0.9)*(AC28>0)+(AH28>=0.9)*(AD28>0)+(AI28>=0.9)*(AE28>0)+IF(AJ28="",0,(AJ28>=0.9)*(AF28>0)) | AM28: 1.4075489 | AN28: 0.86688103 | AO28: 0.036727689 | AP28: =MAX(0,MIN(1,(AM28-1.2)/(0.6-1.2))) | AQ28: =MAX(0,MIN(1,(ABS(O28)-0.03)/(0-0.03))) | AR28: =MAX(0,MIN(1,S28/0.03)) | AS28: =MAX(0,MIN(1,(-W28-0.3)/(0.15-0.3))) | AT28: =0.5*IF(L28>M28,(I28-M28)/(L28-M28),0.5)+0.5*(I28>=N28) | AU28: =MAX(0,MIN(1,(AN28-1.3)/(0.7-1.3))) | AV28: =100*(0.2*AG28+0.2*AH28+0.3*AI28+IF(AJ28="",0,0.3*AJ28))/(0.7+IF(AJ28="",0,0.3)) | AW28: =100*(0.25*AP28+0.2*AQ28+0.15*AR28+0.15*AS28+0.15*AT28+0.1*AU28) | AX28: =0.5*AV28+0.5*AW28 | AY28: =0.4*AV28+0.4*AW28+0.2*(AL28/4*100) | BA28: 17/18 | BC28: 0.00012
A29: =COUNTIF($AY$2:$AY$29,">"&AY29)+1 | B29: CBLL | C29: CeriBell Inc. | D29: NASDAQ | E29: 醫療保健 | F29: Biotechnology: Electromedical & Electrotherapeutic Apparatus | G29: 0.906 | H29: 小型 | I29: 23.62 | J29: 24.25 | K29: =I29/J29-1 | L29: 24.22 | M29: 23.331 | N29: 24.2175 | O29: =I29/N29-1 | P29: 21.7828 | Q29: =I29/P29-1 | R29: 24.2075 | S29: =N29/R29-1 | T29: 25.04 | U29: 2026-09-15 | V29: 6 | W29: =I29/T29-1 | X29: 0.2507852 | Y29: 2026-08-19 | Z29: -0.03660576 | AA29: 2026-07-23 | AB29: 0.53808354 | AC29: -0.01336675 | AD29: 0.39680662 | AE29: 0.2692101 | AF29: 0.24841438 | AG29: 0.71428571 | AH29: 0.95298373 | AI29: 0.89475588 | AJ29: 0.73624358 | AK29: 2個月 | AL29: =(AG29>=0.9)*(AC29>0)+(AH29>=0.9)*(AD29>0)+(AI29>=0.9)*(AE29>0)+IF(AJ29="",0,(AJ29>=0.9)*(AF29>0)) | AM29: 1.627677 | AN29: 0.78507322 | AO29: 0.036745494 | AP29: =MAX(0,MIN(1,(AM29-1.2)/(0.6-1.2))) | AQ29: =MAX(0,MIN(1,(ABS(O29)-0.03)/(0-0.03))) | AR29: =MAX(0,MIN(1,S29/0.03)) | AS29: =MAX(0,MIN(1,(-W29-0.3)/(0.15-0.3))) | AT29: =0.5*IF(L29>M29,(I29-M29)/(L29-M29),0.5)+0.5*(I29>=N29) | AU29: =MAX(0,MIN(1,(AN29-1.3)/(0.7-1.3))) | AV29: =100*(0.2*AG29+0.2*AH29+0.3*AI29+IF(AJ29="",0,0.3*AJ29))/(0.7+IF(AJ29="",0,0.3)) | AW29: =100*(0.25*AP29+0.2*AQ29+0.15*AR29+0.15*AS29+0.15*AT29+0.1*AU29) | AX29: =0.5*AV29+0.5*AW29 | AY29: =0.4*AV29+0.4*AW29+0.2*(AL29/4*100) | BA29: 17/18 | BC29: 0

Sheet 1個月動能
A1: 1個月動能（21 個交易日回報排全體合資格股票前 10%）＋ 回到上升中嘅 20MA · 以綜合分數排序 · 2026-09-23 收市
A3: 頁內排名 | B3: 總表排名 | C3: 代號 | D3: 公司 | E3: 板塊 | F3: 市值組 | G3: 收市價 | H3: 距MA20% | I3: 距高位% | J3: 1個月回報 | K3: 1個月百分位 | L3: 覆蓋度 | M3: 動能分數 | N3: 回調質素 | O3: 綜合分數 | P3: 審視標記
A4: =COUNTIF($O$4:$O$18,">"&O4)+1 | B4: ='總表'!A2 | C4: VEEV | D4: ='總表'!C2 | E4: ='總表'!E2 | F4: ='總表'!H2 | G4: ='總表'!I2 | H4: ='總表'!O2 | I4: ='總表'!W2 | J4: ='總表'!AC2 | K4: ='總表'!AG2 | L4: ='總表'!AL2 | M4: ='總表'!AV2 | N4: ='總表'!AW2 | O4: ='總表'!AX2 | P4: ='總表'!BB2
A5: =COUNTIF($O$4:$O$18,">"&O5)+1 | B5: ='總表'!A7 | C5: NOW | D5: ='總表'!C7 | E5: ='總表'!E7 | F5: ='總表'!H7 | G5: ='總表'!I7 | H5: ='總表'!O7 | I5: ='總表'!W7 | J5: ='總表'!AC7 | K5: ='總表'!AG7 | L5: ='總表'!AL7 | M5: ='總表'!AV7 | N5: ='總表'!AW7 | O5: ='總表'!AX7 | P5: ='總表'!BB7
A6: =COUNTIF($O$4:$O$18,">"&O6)+1 | B6: ='總表'!A14 | C6: DHX | D6: ='總表'!C14 | E6: ='總表'!E14 | F6: ='總表'!H14 | G6: ='總表'!I14 | H6: ='總表'!O14 | I6: ='總表'!W14 | J6: ='總表'!AC14 | K6: ='總表'!AG14 | L6: ='總表'!AL14 | M6: ='總表'!AV14 | N6: ='總表'!AW14 | O6: ='總表'!AX14 | P6: ='總表'!BB14
A7: =COUNTIF($O$4:$O$18,">"&O7)+1 | B7: ='總表'!A3 | C7: NUTX | D7: ='總表'!C3 | E7: ='總表'!E3 | F7: ='總表'!H3 | G7: ='總表'!I3 | H7: ='總表'!O3 | I7: ='總表'!W3 | J7: ='總表'!AC3 | K7: ='總表'!AG3 | L7: ='總表'!AL3 | M7: ='總表'!AV3 | N7: ='總表'!AW3 | O7: ='總表'!AX3 | P7: ='總表'!BB3
A8: =COUNTIF($O$4:$O$18,">"&O8)+1 | B8: ='總表'!A4 | C8: CLMT | D8: ='總表'!C4 | E8: ='總表'!E4 | F8: ='總表'!H4 | G8: ='總表'!I4 | H8: ='總表'!O4 | I8: ='總表'!W4 | J8: ='總表'!AC4 | K8: ='總表'!AG4 | L8: ='總表'!AL4 | M8: ='總表'!AV4 | N8: ='總表'!AW4 | O8: ='總表'!AX4 | P8: ='總表'!BB4
A9: =COUNTIF($O$4:$O$18,">"&O9)+1 | B9: ='總表'!A5 | C9: ESTC | D9: ='總表'!C5 | E9: ='總表'!E5 | F9: ='總表'!H5 | G9: ='總表'!I5 | H9: ='總表'!O5 | I9: ='總表'!W5 | J9: ='總表'!AC5 | K9: ='總表'!AG5 | L9: ='總表'!AL5 | M9: ='總表'!AV5 | N9: ='總表'!AW5 | O9: ='總表'!AX5 | P9: ='總表'!BB5
A10: =COUNTIF($O$4:$O$18,">"&O10)+1 | B10: ='總表'!A6 | C10: NEO | D10: ='總表'!C6 | E10: ='總表'!E6 | F10: ='總表'!H6 | G10: ='總表'!I6 | H10: ='總表'!O6 | I10: ='總表'!W6 | J10: ='總表'!AC6 | K10: ='總表'!AG6 | L10: ='總表'!AL6 | M10: ='總表'!AV6 | N10: ='總表'!AW6 | O10: ='總表'!AX6 | P10: ='總表'!BB6
A11: =COUNTIF($O$4:$O$18,">"&O11)+1 | B11: ='總表'!A10 | C11: IRD | D11: ='總表'!C10 | E11: ='總表'!E10 | F11: ='總表'!H10 | G11: ='總表'!I10 | H11: ='總表'!O10 | I11: ='總表'!W10 | J11: ='總表'!AC10 | K11: ='總表'!AG10 | L11: ='總表'!AL10 | M11: ='總表'!AV10 | N11: ='總表'!AW10 | O11: ='總表'!AX10 | P11: ='總表'!BB10
A12: =COUNTIF($O$4:$O$18,">"&O12)+1 | B12: ='總表'!A11 | C12: AMWL | D12: ='總表'!C11 | E12: ='總表'!E11 | F12: ='總表'!H11 | G12: ='總表'!I11 | H12: ='總表'!O11 | I12: ='總表'!W11 | J12: ='總表'!AC11 | K12: ='總表'!AG11 | L12: ='總表'!AL11 | M12: ='總表'!AV11 | N12: ='總表'!AW11 | O12: ='總表'!AX11 | P12: ='總表'!BB11
A13: =COUNTIF($O$4:$O$18,">"&O13)+1 | B13: ='總表'!A8 | C13: HPQ | D13: ='總表'!C8 | E13: ='總表'!E8 | F13: ='總表'!H8 | G13: ='總表'!I8 | H13: ='總表'!O8 | I13: ='總表'!W8 | J13: ='總表'!AC8 | K13: ='總表'!AG8 | L13: ='總表'!AL8 | M13: ='總表'!AV8 | N13: ='總表'!AW8 | O13: ='總表'!AX8 | P13: ='總表'!BB8
A14: =COUNTIF($O$4:$O$18,">"&O14)+1 | B14: ='總表'!A16 | C14: DINO | D14: ='總表'!C16 | E14: ='總表'!E16 | F14: ='總表'!H16 | G14: ='總表'!I16 | H14: ='總表'!O16 | I14: ='總表'!W16 | J14: ='總表'!AC16 | K14: ='總表'!AG16 | L14: ='總表'!AL16 | M14: ='總表'!AV16 | N14: ='總表'!AW16 | O14: ='總表'!AX16 | P14: ='總表'!BB16
A15: =COUNTIF($O$4:$O$18,">"&O15)+1 | B15: ='總表'!A20 | C15: VIR | D15: ='總表'!C20 | E15: ='總表'!E20 | F15: ='總表'!H20 | G15: ='總表'!I20 | H15: ='總表'!O20 | I15: ='總表'!W20 | J15: ='總表'!AC20 | K15: ='總表'!AG20 | L15: ='總表'!AL20 | M15: ='總表'!AV20 | N15: ='總表'!AW20 | O15: ='總表'!AX20 | P15: ='總表'!BB20
A16: =COUNTIF($O$4:$O$18,">"&O16)+1 | B16: ='總表'!A18 | C16: VLO | D16: ='總表'!C18 | E16: ='總表'!E18 | F16: ='總表'!H18 | G16: ='總表'!I18 | H16: ='總表'!O18 | I16: ='總表'!W18 | J16: ='總表'!AC18 | K16: ='總表'!AG18 | L16: ='總表'!AL18 | M16: ='總表'!AV18 | N16: ='總表'!AW18 | O16: ='總表'!AX18 | P16: ='總表'!BB18
A17: =COUNTIF($O$4:$O$18,">"&O17)+1 | B17: ='總表'!A24 | C17: DJCO | D17: ='總表'!C24 | E17: ='總表'!E24 | F17: ='總表'!H24 | G17: ='總表'!I24 | H17: ='總表'!O24 | I17: ='總表'!W24 | J17: ='總表'!AC24 | K17: ='總表'!AG24 | L17: ='總表'!AL24 | M17: ='總表'!AV24 | N17: ='總表'!AW24 | O17: ='總表'!AX24 | P17: ='總表'!BB24
A18: =COUNTIF($O$4:$O$18,">"&O18)+1 | B18: ='總表'!A27 | C18: REPX | D18: ='總表'!C27 | E18: ='總表'!E27 | F18: ='總表'!H27 | G18: ='總表'!I27 | H18: ='總表'!O27 | I18: ='總表'!W27 | J18: ='總表'!AC27 | K18: ='總表'!AG27 | L18: ='總表'!AL27 | M18: ='總表'!AV27 | N18: ='總表'!AW27 | O18: ='總表'!AX27 | P18: ='總表'!BB27

Sheet 2個月動能
A1: 2個月動能（42 個交易日回報排全體合資格股票前 10%）＋ 回到上升中嘅 20MA · 以綜合分數排序 · 2026-09-23 收市
A3: 頁內排名 | B3: 總表排名 | C3: 代號 | D3: 公司 | E3: 板塊 | F3: 市值組 | G3: 收市價 | H3: 距MA20% | I3: 距高位% | J3: 2個月回報 | K3: 2個月百分位 | L3: 覆蓋度 | M3: 動能分數 | N3: 回調質素 | O3: 綜合分數 | P3: 審視標記
A4: =COUNTIF($O$4:$O$22,">"&O4)+1 | B4: ='總表'!A2 | C4: VEEV | D4: ='總表'!C2 | E4: ='總表'!E2 | F4: ='總表'!H2 | G4: ='總表'!I2 | H4: ='總表'!O2 | I4: ='總表'!W2 | J4: ='總表'!AD2 | K4: ='總表'!AH2 | L4: ='總表'!AL2 | M4: ='總表'!AV2 | N4: ='總表'!AW2 | O4: ='總表'!AX2 | P4: ='總表'!BB2
A5: =COUNTIF($O$4:$O$22,">"&O5)+1 | B5: ='總表'!A7 | C5: NOW | D5: ='總表'!C7 | E5: ='總表'!E7 | F5: ='總表'!H7 | G5: ='總表'!I7 | H5: ='總表'!O7 | I5: ='總表'!W7 | J5: ='總表'!AD7 | K5: ='總表'!AH7 | L5: ='總表'!AL7 | M5: ='總表'!AV7 | N5: ='總表'!AW7 | O5: ='總表'!AX7 | P5: ='總表'!BB7
A6: =COUNTIF($O$4:$O$22,">"&O6)+1 | B6: ='總表'!A9 | C6: PLSE | D6: ='總表'!C9 | E6: ='總表'!E9 | F6: ='總表'!H9 | G6: ='總表'!I9 | H6: ='總表'!O9 | I6: ='總表'!W9 | J6: ='總表'!AD9 | K6: ='總表'!AH9 | L6: ='總表'!AL9 | M6: ='總表'!AV9 | N6: ='總表'!AW9 | O6: ='總表'!AX9 | P6: ='總表'!BB9
A7: =COUNTIF($O$4:$O$22,">"&O7)+1 | B7: ='總表'!A3 | C7: NUTX | D7: ='總表'!C3 | E7: ='總表'!E3 | F7: ='總表'!H3 | G7: ='總表'!I3 | H7: ='總表'!O3 | I7: ='總表'!W3 | J7: ='總表'!AD3 | K7: ='總表'!AH3 | L7: ='總表'!AL3 | M7: ='總表'!AV3 | N7: ='總表'!AW3 | O7: ='總表'!AX3 | P7: ='總表'!BB3
A8: =COUNTIF($O$4:$O$22,">"&O8)+1 | B8: ='總表'!A4 | C8: CLMT | D8: ='總表'!C4 | E8: ='總表'!E4 | F8: ='總表'!H4 | G8: ='總表'!I4 | H8: ='總表'!O4 | I8: ='總表'!W4 | J8: ='總表'!AD4 | K8: ='總表'!AH4 | L8: ='總表'!AL4 | M8: ='總表'!AV4 | N8: ='總表'!AW4 | O8: ='總表'!AX4 | P8: ='總表'!BB4
A9: =COUNTIF($O$4:$O$22,">"&O9)+1 | B9: ='總表'!A5 | C9: ESTC | D9: ='總表'!C5 | E9: ='總表'!E5 | F9: ='總表'!H5 | G9: ='總表'!I5 | H9: ='總表'!O5 | I9: ='總表'!W5 | J9: ='總表'!AD5 | K9: ='總表'!AH5 | L9: ='總表'!AL5 | M9: ='總表'!AV5 | N9: ='總表'!AW5 | O9: ='總表'!AX5 | P9: ='總表'!BB5
A10: =COUNTIF($O$4:$O$22,">"&O10)+1 | B10: ='總表'!A6 | C10: NEO | D10: ='總表'!C6 | E10: ='總表'!E6 | F10: ='總表'!H6 | G10: ='總表'!I6 | H10: ='總表'!O6 | I10: ='總表'!W6 | J10: ='總表'!AD6 | K10: ='總表'!AH6 | L10: ='總表'!AL6 | M10: ='總表'!AV6 | N10: ='總表'!AW6 | O10: ='總表'!AX6 | P10: ='總表'!BB6
A11: =COUNTIF($O$4:$O$22,">"&O11)+1 | B11: ='總表'!A10 | C11: IRD | D11: ='總表'!C10 | E11: ='總表'!E10 | F11: ='總表'!H10 | G11: ='總表'!I10 | H11: ='總表'!O10 | I11: ='總表'!W10 | J11: ='總表'!AD10 | K11: ='總表'!AH10 | L11: ='總表'!AL10 | M11: ='總表'!AV10 | N11: ='總表'!AW10 | O11: ='總表'!AX10 | P11: ='總表'!BB10
A12: =COUNTIF($O$4:$O$22,">"&O12)+1 | B12: ='總表'!A12 | C12: SNOW | D12: ='總表'!C12 | E12: ='總表'!E12 | F12: ='總表'!H12 | G12: ='總表'!I12 | H12: ='總表'!O12 | I12: ='總表'!W12 | J12: ='總表'!AD12 | K12: ='總表'!AH12 | L12: ='總表'!AL12 | M12: ='總表'!AV12 | N12: ='總表'!AW12 | O12: ='總表'!AX12 | P12: ='總表'!BB12
A13: =COUNTIF($O$4:$O$22,">"&O13)+1 | B13: ='總表'!A13 | C13: AMPL | D13: ='總表'!C13 | E13: ='總表'!E13 | F13: ='總表'!H13 | G13: ='總表'!I13 | H13: ='總表'!O13 | I13: ='總表'!W13 | J13: ='總表'!AD13 | K13: ='總表'!AH13 | L13: ='總表'!AL13 | M13: ='總表'!AV13 | N13: ='總表'!AW13 | O13: ='總表'!AX13 | P13: ='總表'!BB13
A14: =COUNTIF($O$4:$O$22,">"&O14)+1 | B14: ='總表'!A19 | C14: SABR | D14: ='總表'!C19 | E14: ='總表'!E19 | F14: ='總表'!H19 | G14: ='總表'!I19 | H14: ='總表'!O19 | I14: ='總表'!W19 | J14: ='總表'!AD19 | K14: ='總表'!AH19 | L14: ='總表'!AL19 | M14: ='總表'!AV19 | N14: ='總表'!AW19 | O14: ='總表'!AX19 | P14: ='總表'!BB19
A15: =COUNTIF($O$4:$O$22,">"&O15)+1 | B15: ='總表'!A8 | C15: HPQ | D15: ='總表'!C8 | E15: ='總表'!E8 | F15: ='總表'!H8 | G15: ='總表'!I8 | H15: ='總表'!O8 | I15: ='總表'!W8 | J15: ='總表'!AD8 | K15: ='總表'!AH8 | L15: ='總表'!AL8 | M15: ='總表'!AV8 | N15: ='總表'!AW8 | O15: ='總表'!AX8 | P15: ='總表'!BB8
A16: =COUNTIF($O$4:$O$22,">"&O16)+1 | B16: ='總表'!A15 | C16: ZETA | D16: ='總表'!C15 | E16: ='總表'!E15 | F16: ='總表'!H15 | G16: ='總表'!I15 | H16: ='總表'!O15 | I16: ='總表'!W15 | J16: ='總表'!AD15 | K16: ='總表'!AH15 | L16: ='總表'!AL15 | M16: ='總表'!AV15 | N16: ='總表'!AW15 | O16: ='總表'!AX15 | P16: ='總表'!BB15
A17: =COUNTIF($O$4:$O$22,">"&O17)+1 | B17: ='總表'!A17 | C17: MGNI | D17: ='總表'!C17 | E17: ='總表'!E17 | F17: ='總表'!H17 | G17: ='總表'!I17 | H17: ='總表'!O17 | I17: ='總表'!W17 | J17: ='總表'!AD17 | K17: ='總表'!AH17 | L17: ='總表'!AL17 | M17: ='總表'!AV17 | N17: ='總表'!AW17 | O17: ='總表'!AX17 | P17: ='總表'!BB17
A18: =COUNTIF($O$4:$O$22,">"&O18)+1 | B18: ='總表'!A20 | C18: VIR | D18: ='總表'!C20 | E18: ='總表'!E20 | F18: ='總表'!H20 | G18: ='總表'!I20 | H18: ='總表'!O20 | I18: ='總表'!W20 | J18: ='總表'!AD20 | K18: ='總表'!AH20 | L18: ='總表'!AL20 | M18: ='總表'!AV20 | N18: ='總表'!AW20 | O18: ='總表'!AX20 | P18: ='總表'!BB20
A19: =COUNTIF($O$4:$O$22,">"&O19)+1 | B19: ='總表'!A18 | C19: VLO | D19: ='總表'!C18 | E19: ='總表'!E18 | F19: ='總表'!H18 | G19: ='總表'!I18 | H19: ='總表'!O18 | I19: ='總表'!W18 | J19: ='總表'!AD18 | K19: ='總表'!AH18 | L19: ='總表'!AL18 | M19: ='總表'!AV18 | N19: ='總表'!AW18 | O19: ='總表'!AX18 | P19: ='總表'!BB18
A20: =COUNTIF($O$4:$O$22,">"&O20)+1 | B20: ='總表'!A21 | C20: MPC | D20: ='總表'!C21 | E20: ='總表'!E21 | F20: ='總表'!H21 | G20: ='總表'!I21 | H20: ='總表'!O21 | I20: ='總表'!W21 | J20: ='總表'!AD21 | K20: ='總表'!AH21 | L20: ='總表'!AL21 | M20: ='總表'!AV21 | N20: ='總表'!AW21 | O20: ='總表'!AX21 | P20: ='總表'!BB21
A21: =COUNTIF($O$4:$O$22,">"&O21)+1 | B21: ='總表'!A22 | C21: SGP | D21: ='總表'!C22 | E21: ='總表'!E22 | F21: ='總表'!H22 | G21: ='總表'!I22 | H21: ='總表'!O22 | I21: ='總表'!W22 | J21: ='總表'!AD22 | K21: ='總表'!AH22 | L21: ='總表'!AL22 | M21: ='總表'!AV22 | N21: ='總表'!AW22 | O21: ='總表'!AX22 | P21: ='總表'!BB22
A22: =COUNTIF($O$4:$O$22,">"&O22)+1 | B22: ='總表'!A29 | C22: CBLL | D22: ='總表'!C29 | E22: ='總表'!E29 | F22: ='總表'!H29 | G22: ='總表'!I29 | H22: ='總表'!O29 | I22: ='總表'!W29 | J22: ='總表'!AD29 | K22: ='總表'!AH29 | L22: ='總表'!AL29 | M22: ='總表'!AV29 | N22: ='總表'!AW29 | O22: ='總表'!AX29 | P22: ='總表'!BB29

Sheet 3個月動能
A1: 3個月動能（63 個交易日回報排全體合資格股票前 10%）＋ 回到上升中嘅 20MA · 以綜合分數排序 · 2026-09-23 收市
A3: 頁內排名 | B3: 總表排名 | C3: 代號 | D3: 公司 | E3: 板塊 | F3: 市值組 | G3: 收市價 | H3: 距MA20% | I3: 距高位% | J3: 3個月回報 | K3: 3個月百分位 | L3: 覆蓋度 | M3: 動能分數 | N3: 回調質素 | O3: 綜合分數 | P3: 審視標記
A4: =COUNTIF($O$4:$O$25,">"&O4)+1 | B4: ='總表'!A2 | C4: VEEV | D4: ='總表'!C2 | E4: ='總表'!E2 | F4: ='總表'!H2 | G4: ='總表'!I2 | H4: ='總表'!O2 | I4: ='總表'!W2 | J4: ='總表'!AE2 | K4: ='總表'!AI2 | L4: ='總表'!AL2 | M4: ='總表'!AV2 | N4: ='總表'!AW2 | O4: ='總表'!AX2 | P4: ='總表'!BB2
A5: =COUNTIF($O$4:$O$25,">"&O5)+1 | B5: ='總表'!A7 | C5: NOW | D5: ='總表'!C7 | E5: ='總表'!E7 | F5: ='總表'!H7 | G5: ='總表'!I7 | H5: ='總表'!O7 | I5: ='總表'!W7 | J5: ='總表'!AE7 | K5: ='總表'!AI7 | L5: ='總表'!AL7 | M5: ='總表'!AV7 | N5: ='總表'!AW7 | O5: ='總表'!AX7 | P5: ='總表'!BB7
A6: =COUNTIF($O$4:$O$25,">"&O6)+1 | B6: ='總表'!A9 | C6: PLSE | D6: ='總表'!C9 | E6: ='總表'!E9 | F6: ='總表'!H9 | G6: ='總表'!I9 | H6: ='總表'!O9 | I6: ='總表'!W9 | J6: ='總表'!AE9 | K6: ='總表'!AI9 | L6: ='總表'!AL9 | M6: ='總表'!AV9 | N6: ='總表'!AW9 | O6: ='總表'!AX9 | P6: ='總表'!BB9
A7: =COUNTIF($O$4:$O$25,">"&O7)+1 | B7: ='總表'!A3 | C7: NUTX | D7: ='總表'!C3 | E7: ='總表'!E3 | F7: ='總表'!H3 | G7: ='總表'!I3 | H7: ='總表'!O3 | I7: ='總表'!W3 | J7: ='總表'!AE3 | K7: ='總表'!AI3 | L7: ='總表'!AL3 | M7: ='總表'!AV3 | N7: ='總表'!AW3 | O7: ='總表'!AX3 | P7: ='總表'!BB3
A8: =COUNTIF($O$4:$O$25,">"&O8)+1 | B8: ='總表'!A4 | C8: CLMT | D8: ='總表'!C4 | E8: ='總表'!E4 | F8: ='總表'!H4 | G8: ='總表'!I4 | H8: ='總表'!O4 | I8: ='總表'!W4 | J8: ='總表'!AE4 | K8: ='總表'!AI4 | L8: ='總表'!AL4 | M8: ='總表'!AV4 | N8: ='總表'!AW4 | O8: ='總表'!AX4 | P8: ='總表'!BB4
A9: =COUNTIF($O$4:$O$25,">"&O9)+1 | B9: ='總表'!A5 | C9: ESTC | D9: ='總表'!C5 | E9: ='總表'!E5 | F9: ='總表'!H5 | G9: ='總表'!I5 | H9: ='總表'!O5 | I9: ='總表'!W5 | J9: ='總表'!AE5 | K9: ='總表'!AI5 | L9: ='總表'!AL5 | M9: ='總表'!AV5 | N9: ='總表'!AW5 | O9: ='總表'!AX5 | P9: ='總表'!BB5
A10: =COUNTIF($O$4:$O$25,">"&O10)+1 | B10: ='總表'!A6 | C10: NEO | D10: ='總表'!C6 | E10: ='總表'!E6 | F10: ='總表'!H6 | G10: ='總表'!I6 | H10: ='總表'!O6 | I10: ='總表'!W6 | J10: ='總表'!AE6 | K10: ='總表'!AI6 | L10: ='總表'!AL6 | M10: ='總表'!AV6 | N10: ='總表'!AW6 | O10: ='總表'!AX6 | P10: ='總表'!BB6
A11: =COUNTIF($O$4:$O$25,">"&O11)+1 | B11: ='總表'!A10 | C11: IRD | D11: ='總表'!C10 | E11: ='總表'!E10 | F11: ='總表'!H10 | G11: ='總表'!I10 | H11: ='總表'!O10 | I11: ='總表'!W10 | J11: ='總表'!AE10 | K11: ='總表'!AI10 | L11: ='總表'!AL10 | M11: ='總表'!AV10 | N11: ='總表'!AW10 | O11: ='總表'!AX10 | P11: ='總表'!BB10
A12: =COUNTIF($O$4:$O$25,">"&O12)+1 | B12: ='總表'!A11 | C12: AMWL | D12: ='總表'!C11 | E12: ='總表'!E11 | F12: ='總表'!H11 | G12: ='總表'!I11 | H12: ='總表'!O11 | I12: ='總表'!W11 | J12: ='總表'!AE11 | K12: ='總表'!AI11 | L12: ='總表'!AL11 | M12: ='總表'!AV11 | N12: ='總表'!AW11 | O12: ='總表'!AX11 | P12: ='總表'!BB11
A13: =COUNTIF($O$4:$O$25,">"&O13)+1 | B13: ='總表'!A12 | C13: SNOW | D13: ='總表'!C12 | E13: ='總表'!E12 | F13: ='總表'!H12 | G13: ='總表'!I12 | H13: ='總表'!O12 | I13: ='總表'!W12 | J13: ='總表'!AE12 | K13: ='總表'!AI12 | L13: ='總表'!AL12 | M13: ='總表'!AV12 | N13: ='總表'!AW12 | O13: ='總表'!AX12 | P13: ='總表'!BB12
A14: =COUNTIF($O$4:$O$25,">"&O14)+1 | B14: ='總表'!A13 | C14: AMPL | D14: ='總表'!C13 | E14: ='總表'!E13 | F14: ='總表'!H13 | G14: ='總表'!I13 | H14: ='總表'!O13 | I14: ='總表'!W13 | J14: ='總表'!AE13 | K14: ='總表'!AI13 | L14: ='總表'!AL13 | M14: ='總表'!AV13 | N14: ='總表'!AW13 | O14: ='總表'!AX13 | P14: ='總表'!BB13
A15: =COUNTIF($O$4:$O$25,">"&O15)+1 | B15: ='總表'!A8 | C15: HPQ | D15: ='總表'!C8 | E15: ='總表'!E8 | F15: ='總表'!H8 | G15: ='總表'!I8 | H15: ='總表'!O8 | I15: ='總表'!W8 | J15: ='總表'!AE8 | K15: ='總表'!AI8 | L15: ='總表'!AL8 | M15: ='總表'!AV8 | N15: ='總表'!AW8 | O15: ='總表'!AX8 | P15: ='總表'!BB8
A16: =COUNTIF($O$4:$O$25,">"&O16)+1 | B16: ='總表'!A15 | C16: ZETA | D16: ='總表'!C15 | E16: ='總表'!E15 | F16: ='總表'!H15 | G16: ='總表'!I15 | H16: ='總表'!O15 | I16: ='總表'!W15 | J16: ='總表'!AE15 | K16: ='總表'!AI15 | L16: ='總表'!AL15 | M16: ='總表'!AV15 | N16: ='總表'!AW15 | O16: ='總表'!AX15 | P16: ='總表'!BB15
A17: =COUNTIF($O$4:$O$25,">"&O17)+1 | B17: ='總表'!A23 | C17: ANGX | D17: ='總表'!C23 | E17: ='總表'!E23 | F17: ='總表'!H23 | G17: ='總表'!I23 | H17: ='總表'!O23 | I17: ='總表'!W23 | J17: ='總表'!AE23 | K17: ='總表'!AI23 | L17: ='總表'!AL23 | M17: ='總表'!AV23 | N17: ='總表'!AW23 | O17: ='總表'!AX23 | P17: ='總表'!BB23
A18: =COUNTIF($O$4:$O$25,">"&O18)+1 | B18: ='總表'!A16 | C18: DINO | D18: ='總表'!C16 | E18: ='總表'!E16 | F18: ='總表'!H16 | G18: ='總表'!I16 | H18: ='總表'!O16 | I18: ='總表'!W16 | J18: ='總表'!AE16 | K18: ='總表'!AI16 | L18: ='總表'!AL16 | M18: ='總表'!AV16 | N18: ='總表'!AW16 | O18: ='總表'!AX16 | P18: ='總表'!BB16
A19: =COUNTIF($O$4:$O$25,">"&O19)+1 | B19: ='總表'!A17 | C19: MGNI | D19: ='總表'!C17 | E19: ='總表'!E17 | F19: ='總表'!H17 | G19: ='總表'!I17 | H19: ='總表'!O17 | I19: ='總表'!W17 | J19: ='總表'!AE17 | K19: ='總表'!AI17 | L19: ='總表'!AL17 | M19: ='總表'!AV17 | N19: ='總表'!AW17 | O19: ='總表'!AX17 | P19: ='總表'!BB17
A20: =COUNTIF($O$4:$O$25,">"&O20)+1 | B20: ='總表'!A18 | C20: VLO | D20: ='總表'!C18 | E20: ='總表'!E18 | F20: ='總表'!H18 | G20: ='總表'!I18 | H20: ='總表'!O18 | I20: ='總表'!W18 | J20: ='總表'!AE18 | K20: ='總表'!AI18 | L20: ='總表'!AL18 | M20: ='總表'!AV18 | N20: ='總表'!AW18 | O20: ='總表'!AX18 | P20: ='總表'!BB18
A21: =COUNTIF($O$4:$O$25,">"&O21)+1 | B21: ='總表'!A21 | C21: MPC | D21: ='總表'!C21 | E21: ='總表'!E21 | F21: ='總表'!H21 | G21: ='總表'!I21 | H21: ='總表'!O21 | I21: ='總表'!W21 | J21: ='總表'!AE21 | K21: ='總表'!AI21 | L21: ='總表'!AL21 | M21: ='總表'!AV21 | N21: ='總表'!AW21 | O21: ='總表'!AX21 | P21: ='總表'!BB21
A22: =COUNTIF($O$4:$O$25,">"&O22)+1 | B22: ='總表'!A25 | C22: PSX | D22: ='總表'!C25 | E22: ='總表'!E25 | F22: ='總表'!H25 | G22: ='總表'!I25 | H22: ='總表'!O25 | I22: ='總表'!W25 | J22: ='總表'!AE25 | K22: ='總表'!AI25 | L22: ='總表'!AL25 | M22: ='總表'!AV25 | N22: ='總表'!AW25 | O22: ='總表'!AX25 | P22: ='總表'!BB25
A23: =COUNTIF($O$4:$O$25,">"&O23)+1 | B23: ='總表'!A22 | C23: SGP | D23: ='總表'!C22 | E23: ='總表'!E22 | F23: ='總表'!H22 | G23: ='總表'!I22 | H23: ='總表'!O22 | I23: ='總表'!W22 | J23: ='總表'!AE22 | K23: ='總表'!AI22 | L23: ='總表'!AL22 | M23: ='總表'!AV22 | N23: ='總表'!AW22 | O23: ='總表'!AX22 | P23: ='總表'!BB22
A24: =COUNTIF($O$4:$O$25,">"&O24)+1 | B24: ='總表'!A26 | C24: LPG | D24: ='總表'!C26 | E24: ='總表'!E26 | F24: ='總表'!H26 | G24: ='總表'!I26 | H24: ='總表'!O26 | I24: ='總表'!W26 | J24: ='總表'!AE26 | K24: ='總表'!AI26 | L24: ='總表'!AL26 | M24: ='總表'!AV26 | N24: ='總表'!AW26 | O24: ='總表'!AX26 | P24: ='總表'!BB26
A25: =COUNTIF($O$4:$O$25,">"&O25)+1 | B25: ='總表'!A28 | C25: APA | D25: ='總表'!C28 | E25: ='總表'!E28 | F25: ='總表'!H28 | G25: ='總表'!I28 | H25: ='總表'!O28 | I25: ='總表'!W28 | J25: ='總表'!AE28 | K25: ='總表'!AI28 | L25: ='總表'!AL28 | M25: ='總表'!AV28 | N25: ='總表'!AW28 | O25: ='總表'!AX28 | P25: ='總表'!BB28

Sheet 6個月動能
A1: 6個月動能（126 個交易日回報排全體合資格股票前 10%）＋ 回到上升中嘅 20MA · 以綜合分數排序 · 2026-09-23 收市
A3: 頁內排名 | B3: 總表排名 | C3: 代號 | D3: 公司 | E3: 板塊 | F3: 市值組 | G3: 收市價 | H3: 距MA20% | I3: 距高位% | J3: 6個月回報 | K3: 6個月百分位 | L3: 覆蓋度 | M3: 動能分數 | N3: 回調質素 | O3: 綜合分數 | P3: 審視標記
A4: =COUNTIF($O$4:$O$16,">"&O4)+1 | B4: ='總表'!A9 | C4: PLSE | D4: ='總表'!C9 | E4: ='總表'!E9 | F4: ='總表'!H9 | G4: ='總表'!I9 | H4: ='總表'!O9 | I4: ='總表'!W9 | J4: ='總表'!AF9 | K4: ='總表'!AJ9 | L4: ='總表'!AL9 | M4: ='總表'!AV9 | N4: ='總表'!AW9 | O4: ='總表'!AX9 | P4: ='總表'!BB9
A5: =COUNTIF($O$4:$O$16,">"&O5)+1 | B5: ='總表'!A14 | C5: DHX | D5: ='總表'!C14 | E5: ='總表'!E14 | F5: ='總表'!H14 | G5: ='總表'!I14 | H5: ='總表'!O14 | I5: ='總表'!W14 | J5: ='總表'!AF14 | K5: ='總表'!AJ14 | L5: ='總表'!AL14 | M5: ='總表'!AV14 | N5: ='總表'!AW14 | O5: ='總表'!AX14 | P5: ='總表'!BB14
A6: =COUNTIF($O$4:$O$16,">"&O6)+1 | B6: ='總表'!A3 | C6: NUTX | D6: ='總表'!C3 | E6: ='總表'!E3 | F6: ='總表'!H3 | G6: ='總表'!I3 | H6: ='總表'!O3 | I6: ='總表'!W3 | J6: ='總表'!AF3 | K6: ='總表'!AJ3 | L6: ='總表'!AL3 | M6: ='總表'!AV3 | N6: ='總表'!AW3 | O6: ='總表'!AX3 | P6: ='總表'!BB3
A7: =COUNTIF($O$4:$O$16,">"&O7)+1 | B7: ='總表'!A4 | C7: CLMT | D7: ='總表'!C4 | E7: ='總表'!E4 | F7: ='總表'!H4 | G7: ='總表'!I4 | H7: ='總表'!O4 | I7: ='總表'!W4 | J7: ='總表'!AF4 | K7: ='總表'!AJ4 | L7: ='總表'!AL4 | M7: ='總表'!AV4 | N7: ='總表'!AW4 | O7: ='總表'!AX4 | P7: ='總表'!BB4
A8: =COUNTIF($O$4:$O$16,">"&O8)+1 | B8: ='總表'!A5 | C8: ESTC | D8: ='總表'!C5 | E8: ='總表'!E5 | F8: ='總表'!H5 | G8: ='總表'!I5 | H8: ='總表'!O5 | I8: ='總表'!W5 | J8: ='總表'!AF5 | K8: ='總表'!AJ5 | L8: ='總表'!AL5 | M8: ='總表'!AV5 | N8: ='總表'!AW5 | O8: ='總表'!AX5 | P8: ='總表'!BB5
A9: =COUNTIF($O$4:$O$16,">"&O9)+1 | B9: ='總表'!A6 | C9: NEO | D9: ='總表'!C6 | E9: ='總表'!E6 | F9: ='總表'!H6 | G9: ='總表'!I6 | H9: ='總表'!O6 | I9: ='總表'!W6 | J9: ='總表'!AF6 | K9: ='總表'!AJ6 | L9: ='總表'!AL6 | M9: ='總表'!AV6 | N9: ='總表'!AW6 | O9: ='總表'!AX6 | P9: ='總表'!BB6
A10: =COUNTIF($O$4:$O$16,">"&O10)+1 | B10: ='總表'!A11 | C10: AMWL | D10: ='總表'!C11 | E10: ='總表'!E11 | F10: ='總表'!H11 | G10: ='總表'!I11 | H10: ='總表'!O11 | I10: ='總表'!W11 | J10: ='總表'!AF11 | K10: ='總表'!AJ11 | L10: ='總表'!AL11 | M10: ='總表'!AV11 | N10: ='總表'!AW11 | O10: ='總表'!AX11 | P10: ='總表'!BB11
A11: =COUNTIF($O$4:$O$16,">"&O11)+1 | B11: ='總表'!A12 | C11: SNOW | D11: ='總表'!C12 | E11: ='總表'!E12 | F11: ='總表'!H12 | G11: ='總表'!I12 | H11: ='總表'!O12 | I11: ='總表'!W12 | J11: ='總表'!AF12 | K11: ='總表'!AJ12 | L11: ='總表'!AL12 | M11: ='總表'!AV12 | N11: ='總表'!AW12 | O11: ='總表'!AX12 | P11: ='總表'!BB12
A12: =COUNTIF($O$4:$O$16,">"&O12)+1 | B12: ='總表'!A13 | C12: AMPL | D12: ='總表'!C13 | E12: ='總表'!E13 | F12: ='總表'!H13 | G12: ='總表'!I13 | H12: ='總表'!O13 | I12: ='總表'!W13 | J12: ='總表'!AF13 | K12: ='總表'!AJ13 | L12: ='總表'!AL13 | M12: ='總表'!AV13 | N12: ='總表'!AW13 | O12: ='總表'!AX13 | P12: ='總表'!BB13
A13: =COUNTIF($O$4:$O$16,">"&O13)+1 | B13: ='總表'!A8 | C13: HPQ | D13: ='總表'!C8 | E13: ='總表'!E8 | F13: ='總表'!H8 | G13: ='總表'!I8 | H13: ='總表'!O8 | I13: ='總表'!W8 | J13: ='總表'!AF8 | K13: ='總表'!AJ8 | L13: ='總表'!AL8 | M13: ='總表'!AV8 | N13: ='總表'!AW8 | O13: ='總表'!AX8 | P13: ='總表'!BB8
A14: =COUNTIF($O$4:$O$16,">"&O14)+1 | B14: ='總表'!A15 | C14: ZETA | D14: ='總表'!C15 | E14: ='總表'!E15 | F14: ='總表'!H15 | G14: ='總表'!I15 | H14: ='總表'!O15 | I14: ='總表'!W15 | J14: ='總表'!AF15 | K14: ='總表'!AJ15 | L14: ='總表'!AL15 | M14: ='總表'!AV15 | N14: ='總表'!AW15 | O14: ='總表'!AX15 | P14: ='總表'!BB15
A15: =COUNTIF($O$4:$O$16,">"&O15)+1 | B15: ='總表'!A16 | C15: DINO | D15: ='總表'!C16 | E15: ='總表'!E16 | F15: ='總表'!H16 | G15: ='總表'!I16 | H15: ='總表'!O16 | I15: ='總表'!W16 | J15: ='總表'!AF16 | K15: ='總表'!AJ16 | L15: ='總表'!AL16 | M15: ='總表'!AV16 | N15: ='總表'!AW16 | O15: ='總表'!AX16 | P15: ='總表'!BB16
